Workbook

Sheet Cover
B1: Anthropic S-1
B2: Training versus inference, run-rate revenue, and revenue mix
B3: Preliminary Form S-1 filed October 26, 2026 · Accession 0001628280-26-067168 · Dollars in millions · Blue inputs, green formulas
A5: The filing’s answer, in one page
B6: Compute is not split between training and inference. It is one fungible pool — research, model development, serving customers, and internal use of Claude — and it is expensed in a single line when the capacity arrives.
B7: Note 8 is the workaround. Cost of revenue is the upper bound on compute that serves paying customers. In the first half of 2026 that line was $2.38 billion, against $8.95 billion of compute expense and $16.29 billion of revenue. Implied gross margin was 85%. At least $6.57 billion of compute sat outside cost of revenue.
B8: That outside bucket is not “training.” It also holds internal inference and the free tier. Research and development was $9.74 billion in the same half, larger than the outside-compute bound, because R&D includes people and overhead.
B9: The ratio the company itself cites moved from compute at 201% of revenue in the first half of 2025 to 55% in the first half of 2026. In Q2 2026, revenue grew 1,368% year over year and compute grew 300%. GAAP operating margin was 8%. Adjusted operating margin was 19%.
B10: There is no ARR and no new ARR. Run-Rate Revenue is defined — 28 days of consumption × 13, plus a month of subscriptions × 12 — and the October 31, 2026 amount is blank. The ARR sheet shows GAAP revenue by quarter and refuses to relabel it.
B11: Revenue is 80% consumption and 20% subscription in the first half of 2026 ($13.06 billion and $3.22 billion). There is one segment. No margin is disclosed by product, model, channel, or pricing model. Channel-partner fees rose $2.7 billion in that half, equal to about 17% of revenue before counting the prior-period base.
A13: First-half 2026, linked to the calculation sheets
B14: Figure | C14: H1 2026 | D14: Where it is calculated
B15: Revenue | C15: ='Training vs Inference'!G8 | D15: Training vs Inference
B16: Compute and infrastructure | C16: ='Training vs Inference'!G9 | D16: Training vs Inference
B17: Cost of revenue, inference upper bound | C17: ='Training vs Inference'!G14 | D17: Training vs Inference
B18: Other compute, lower bound | C18: ='Training vs Inference'!G15 | D18: Training vs Inference
B19: Implied gross margin | C19: ='Training vs Inference'!G22 | D19: Training vs Inference
B20: Compute as % of revenue | C20: ='Training vs Inference'!G18 | D20: Training vs Inference
B21: Consumption revenue | C21: ='Revenue Mix and Margins'!G7 | D21: Revenue Mix and Margins
B22: Subscription revenue | C22: ='Revenue Mix and Margins'!G8 | D22: Revenue Mix and Margins
B23: Consumption mix | C23: ='Revenue Mix and Margins'!G10 | D23: Revenue Mix and Margins
B24: Adjusted operating margin | C24: ='Revenue Mix and Margins'!G26 | D24: Revenue Mix and Margins
A26: How the workbook is organized
B27: Training vs Inference | C27: The bounds, the quarterly compute ratio, and what still sits inside “other compute.”
B28: ARR and New ARR | C28: The Run-Rate Revenue definition, the blank October 31 figure, and GAAP revenue by quarter with an annualization that is explicitly not ARR.
B29: Revenue Mix and Margins | C29: Consumption, subscriptions, geography, company-wide margins, and the product cuts that are absent.
B30: Quarterly PnL | C30: Q4 2024 revenue, then the full quarterly statement from Q1 2025 through Q2 2026, with adjusted margins.
B31: Annual PnL | C31: 2023, 2024, 2025, and both first halves, nature and function, with adjusted income.
B32: Customers and KPIs | C32: The $100k cohort, 900% net revenue retention, concentration, and productivity.
B33: Compute Commitments | C33: Note totals and the named contracts. They are not added together, and they are not split by workload.
B34: Inputs | C34: Every typed S-1 number. Edit here only.
B35: Checks | C35: Tie-outs. Each one should read OK.
B36: Sources | C36: Filing citation, methodology, and the press figures that were not used as facts.

Sheet Training vs Inference
B1: Training versus inference
B2: Anthropic does not report training spend and inference spend as separate lines. Compute is one fungible pool, expensed as it comes online, and presented as a single “Compute and infrastructure” operating expense. Note 8 is the only functional split. It supports bounds, not a clean training-versus-inference income statement.
A4: How to read the two numbers that matter
A5: Cost of revenue is the upper bound on compute used to serve paying customers (inference that generates revenue). The footnote says substantially all of cost of revenue is that compute, and that the line also includes some personnel and allocated overhead. Compute expense minus cost of revenue is the lower bound on everything else: pre-training, post-training, research, internal use of Claude, and free-tier inference. Internal use and the free tier are inference, not training, and they sit outside cost of revenue. Research and development is not a training line. It mixes that other compute with people, software, and overhead.
B7: Millions of USD, except ratios | C7: 2023 | D7: 2024 | E7: 2025 | F7: H1 2025 | G7: H1 2026 | I7: What the row is
B8: Revenue | C8: =Inputs!C6 | D8: =Inputs!D6 | E8: =Inputs!E6 | F8: =Inputs!F6 | G8: =Inputs!G6 | I8: Reported revenue.
B9: Compute and infrastructure expense | C9: =Inputs!C7 | D9: =Inputs!D7 | E9: =Inputs!E7 | F9: =Inputs!F7 | G9: =Inputs!G7 | I9: All workloads. The line the company manages.
B10: Cost of revenue (Note 8) | C10: =Inputs!C26 | D10: =Inputs!D26 | E10: =Inputs!E26 | F10: =Inputs!F26 | G10: =Inputs!G26 | I10: Upper bound on paying-customer inference compute.
B11: Research and development (Note 8) | C11: =Inputs!C27 | D11: =Inputs!D27 | E11: =Inputs!E27 | F11: =Inputs!F27 | G11: =Inputs!G27 | I11: Not equal to training. Includes internal inference and people.
A13: Bounds
B14: Upper bound: paying-customer inference compute | C14: =C10 | D14: =D10 | E14: =E10 | F14: =F10 | G14: =G10 | I14: Equals cost of revenue. Overstates inference compute by the personnel and overhead inside cost of revenue.
B15: Lower bound: all other compute | C15: =C9-C10 | D15: =D9-D10 | E15: =E9-E10 | F15: =F9-F10 | G15: =G9-G10 | I15: Training, research, internal Claude usage, and free-tier inference, combined. Understates that bucket by any non-compute cost inside cost of revenue.
B16: Inference bound as % of compute expense | C16: =IF(C9=0,NA(),C14/C9) | D16: =IF(D9=0,NA(),D14/D9) | E16: =IF(E9=0,NA(),E14/E9) | F16: =IF(F9=0,NA(),F14/F9) | G16: =IF(G9=0,NA(),G14/G9) | I16: Upper bound on the share of compute expense that serves paying customers.
B17: Other-compute bound as % of compute expense | C17: =IF(C9=0,NA(),C15/C9) | D17: =IF(D9=0,NA(),D15/D9) | E17: =IF(E9=0,NA(),E15/E9) | F17: =IF(F9=0,NA(),F15/F9) | G17: =IF(G9=0,NA(),G15/G9) | I17: Lower bound on the share that does not serve paying customers.
B18: Total compute expense as % of revenue | C18: =IF(C8=0,NA(),C9/C8) | D18: =IF(D8=0,NA(),D9/D8) | E18: =IF(E8=0,NA(),E9/E8) | F18: =IF(F8=0,NA(),F9/F8) | G18: =IF(G8=0,NA(),G9/G8) | I18: The ratio the company discusses. Fell from about 10x revenue in 2023 to 55% in the first half of 2026.
B19: Inference bound as % of revenue | C19: =IF(C8=0,NA(),C14/C8) | D19: =IF(D8=0,NA(),D14/D8) | E19: =IF(E8=0,NA(),E14/E8) | F19: =IF(F8=0,NA(),F14/F8) | G19: =IF(G8=0,NA(),G14/G8) | I19: Cost of revenue over revenue. This is the gross-margin complement.
B20: Other-compute bound as % of revenue | C20: =IF(C8=0,NA(),C15/C8) | D20: =IF(D8=0,NA(),D15/D8) | E20: =IF(E8=0,NA(),E15/E8) | F20: =IF(F8=0,NA(),F15/F8) | G20: =IF(G8=0,NA(),G15/G8) | I20: Still large in dollars in 2026, but no longer larger than revenue.
B21: Implied gross profit | C21: =C8-C10 | D21: =D8-D10 | E21: =E8-E10 | F21: =F8-F10 | G21: =G8-G10 | I21: Revenue minus Note 8 cost of revenue. Not a line the company presents. Training is excluded from this profit.
B22: Implied gross margin | C22: =IF(C8=0,NA(),C21/C8) | D22: =IF(D8=0,NA(),D21/D8) | E22: =IF(E8=0,NA(),E21/E8) | F22: =IF(F8=0,NA(),F21/F8) | G22: =IF(G8=0,NA(),G21/G8) | I22: About 40% in 2025 and about 85% in the first half of 2026. This margin does not carry training.
B23: Research and development as % of revenue | C23: =IF(C8=0,NA(),C11/C8) | D23: =IF(D8=0,NA(),D11/D8) | E23: =IF(E8=0,NA(),E11/E8) | F23: =IF(F8=0,NA(),F11/F8) | G23: =IF(G8=0,NA(),G11/G8) | I23: R&D fell from many times revenue to 60% of revenue in the first half of 2026, and is still mostly not a gross-margin item.
A25: Read the 2026 columns this way. In the first half of 2026, revenue was $16.3 billion and compute expense was $8.9 billion, or 55% of revenue. At most $2.4 billion of that compute-and-overhead bucket was cost of revenue. At least $6.6 billion of compute expense sat outside cost of revenue. Implied gross margin was 85%. Research and development was $9.7 billion, larger than the other-compute bound, because R&D also contains payroll, software, and overhead. A year earlier, compute expense was 201% of revenue and implied gross margin was 12%. The change is operating leverage on a compute base that was committed 12 to 18 months ahead of delivery, not a disclosure that training stopped.
A27: What still sits inside “other compute”
A28: The company lists four workloads that share the pool: research, model development, serving customers, and internal usage of Claude. Serving customers is the only one that maps cleanly toward cost of revenue. Model development includes pre-training and post-training. Internal usage is employees running Claude, which is inference. Sales and marketing also contains compute for free access, which is inference given away and is outside cost of revenue. The filing says demand has historically exceeded capacity, so the marginal unit is steered to whichever workload is most productive at the time, and the company plans and assesses compute in total rather than by workload. That is why a training-versus-inference percentage is not knowable from this prospectus.
A30: Quarterly path of total compute — no training / inference split is disclosed by quarter
B31: Quarterly, millions of USD | C31: Q1 2025 | D31: Q2 2025 | E31: Q3 2025 | F31: Q4 2025 | G31: Q1 2026 | H31: Q2 2026
B32: Revenue | C32: =Inputs!D73 | D32: =Inputs!E73 | E32: =Inputs!F73 | F32: =Inputs!G73 | G32: =Inputs!H73 | H32: =Inputs!I73 | I32: From the quarterly table.
B33: Compute and infrastructure | C33: =Inputs!D74 | D33: =Inputs!E74 | E33: =Inputs!F74 | F33: =Inputs!G74 | G33: =Inputs!H74 | H33: =Inputs!I74 | I33: Not split by workload in any quarter.
B34: Compute as % of revenue | C34: =IF(C32=0,NA(),C33/C32) | D34: =IF(D32=0,NA(),D33/D32) | E34: =IF(E32=0,NA(),E33/E32) | F34: =IF(F32=0,NA(),F33/F32) | G34: =IF(G32=0,NA(),G33/G32) | H34: =IF(H32=0,NA(),H33/H32) | I34: Filing prints 251%, 177%, 148%, 144%, 72%, and 48%.
B35: Year-over-year revenue growth | G35: =IF(C32=0,NA(),G32/C32-1) | H35: =IF(D32=0,NA(),H32/D32-1) | I35: Q2 2026 revenue growth of 1,368% is the figure cited in the prospectus.
B36: Year-over-year compute growth | G36: =IF(C33=0,NA(),G33/C33-1) | H36: =IF(D33=0,NA(),H33/D33-1) | I36: Q2 2026 compute growth of 300% is the companion figure.
A38: For the quarter ended June 30, 2026, revenue grew 1,368% year over year and compute expense grew 300%. Compute was 48% of that quarter’s revenue, and the company reported GAAP operating income of $974 million (8% operating margin; 19% adjusted operating margin). The company also says the next increments of compute, and a greater mix of short-term compute, can compress operating margin even if unit economics improve, because the expense is recognized when capacity arrives, ahead of the revenue it will support. Owned-compute cash capex is still small next to the expense line: $482 million in the first half of 2026, versus $8.9 billion of compute expense. See Compute Commitments for the contracted amounts that have not yet hit the income statement.
B80: Chart source
C81: =C7 | D81: =D7 | E81: =E7 | F81: =F7 | G81: =G7
B82: Revenue | C82: =C8 | D82: =D8 | E82: =E8 | F82: =F8 | G82: =G8
B83: Inference compute, upper bound | C83: =C14 | D83: =D14 | E83: =E14 | F83: =F14 | G83: =G14
B84: Other compute, lower bound | C84: =C15 | D84: =D15 | E84: =E15 | F84: =F15 | G84: =G15

Sheet ARR and New ARR
B1: ARR and new ARR by quarter
B2: Anthropic does not report ARR or new ARR. The operating metric is Run-Rate Revenue. The prospectus defines it and names one measurement date, October 31, 2026. The dollar amount on that date is blank in this preliminary S-1. No quarterly series, and no new-versus-expansion bridge, is disclosed. The table below is GAAP revenue. The annualized column is arithmetic, not the company’s metric.
A4: Definition printed in the S-1
A5: Run-Rate Revenue = (consumption-based fees during the trailing 28 days × 13) + (aggregate monthly subscription fees on the measurement date × 12). Both pieces come from customer usage and active subscriptions. It is not GAAP revenue and not a forecast. Because it annualizes 28 days, a holiday trough or a launch spike moves the number by a full year. The company says usage is lower around summer and winter holidays. For the two weeks ended January 2, 2026, customer spend was about 20% below the prior two weeks ended December 19, 2025. Run-Rate Revenue also includes customers later found to be outside the usage policy; that revenue is not expected to recur once access is cut off. The company expects the Run-Rate Revenue growth rate to decline.
A7: The one reported observation
B8: Item | C8: Date | D8: Amount | E8: Unit | F8: Status
B9: Run-Rate Revenue | C9: October 31, 2026 | D9: Blank in the filing | E9: USD | F9: Not disclosed | G9: The sentence reads “our Run-Rate Revenue was $ as of October 31, 2026.” The dollars are non-breaking spaces, not a failed extract.
A11: GAAP revenue by quarter — not ARR, and not new ARR
B12: Quarter | C12: GAAP revenue | D12: Sequential change | E12: Sequential growth | F12: Year-over-year growth | G12: Illustrative annualized GAAP (×4) | H12: Change in illustrative annualized | I12: Run-Rate Revenue | J12: New ARR
B13: Q4 2024 | C13: =Inputs!C73 | G13: =C13*4 | I13: Not disclosed | J13: Not disclosed
B14: Q1 2025 | C14: =Inputs!D73 | D14: =C14-C13 | E14: =IF(C13=0,NA(),C14/C13-1) | G14: =C14*4 | H14: =G14-G13 | I14: Not disclosed | J14: Not disclosed
B15: Q2 2025 | C15: =Inputs!E73 | D15: =C15-C14 | E15: =IF(C14=0,NA(),C15/C14-1) | G15: =C15*4 | H15: =G15-G14 | I15: Not disclosed | J15: Not disclosed
B16: Q3 2025 | C16: =Inputs!F73 | D16: =C16-C15 | E16: =IF(C15=0,NA(),C16/C15-1) | G16: =C16*4 | H16: =G16-G15 | I16: Not disclosed | J16: Not disclosed
B17: Q4 2025 | C17: =Inputs!G73 | D17: =C17-C16 | E17: =IF(C16=0,NA(),C17/C16-1) | F17: =IF(C13=0,NA(),C17/C13-1) | G17: =C17*4 | H17: =G17-G16 | I17: Not disclosed | J17: Not disclosed
B18: Q1 2026 | C18: =Inputs!H73 | D18: =C18-C17 | E18: =IF(C17=0,NA(),C18/C17-1) | F18: =IF(C14=0,NA(),C18/C14-1) | G18: =C18*4 | H18: =G18-G17 | I18: Not disclosed | J18: Not disclosed
B19: Q2 2026 | C19: =Inputs!I73 | D19: =C19-C18 | E19: =IF(C18=0,NA(),C19/C18-1) | F19: =IF(C15=0,NA(),C19/C15-1) | G19: =C19*4 | H19: =G19-G18 | I19: Not disclosed | J19: Not disclosed
A21: Column G multiplies the quarter by four. Column H is four times the sequential revenue change. Neither column is Run-Rate Revenue. Run-Rate Revenue annualizes the last 28 days of consumption and one month of subscriptions, not the quarter. With sequential growth of 132% in Q1 2026 and 144% in Q2 2026, an end-of-quarter run-rate would sit above the quarterly annualization, and a holiday measurement would sit below it. The filing does not give the 28-day or monthly-subscription inputs, so the company’s formula cannot be rebuilt by quarter. New ARR is not a concept in the filing. Consumption is recognized as tokens are used. It is not booked as annual contract value, and there is no disclosure of new-logo ARR versus expansion ARR.
A23: Why net revenue retention is not a new-ARR bridge
A24: Net revenue retention was approximately 900% as of September 30, 2026, and that is the only NRR figure in the prospectus. It equals qualified customers’ current-quarter revenue divided by those same customers’ revenue in the quarter one year earlier. A qualified customer had at least $1 of revenue in the base quarter. Claude Pro and Max subscribers are excluded, because a fixed subscription does not show expansion. 900% means the retained cohort’s revenue was about 9×, not that the company added a stated dollar amount of ARR. Company-wide revenue in Q2 2026 was 14.7× Q2 2025. That is a different ratio: it includes new customers and it includes Pro and Max. The two ratios cannot be subtracted to produce new-logo revenue. Doing so would invent a number the filing does not support.
A26: GAAP totals that are often mistaken for ARR
B27: Construct | C27: Amount ($ millions) | D27: What it is | E27: Is it ARR?
B28: Q2 2026 revenue × 4 | C28: =C19*4 | D28: Annualizes the June quarter only.
B29: H1 2026 revenue × 2 | C29: =Inputs!G6*2 | D29: Annualizes the first half.
B30: TTM revenue ended June 30, 2026 | C30: =C16+C17+C18+C19 | D30: Q3 2025 through Q2 2026. About $19.7 billion.
B31: TTM revenue ended September 30, 2025 | C31: =C13+C14+C15+C16 | D31: Q4 2024 through Q3 2025. The base under the “about 1,200%” TTM comment.
B32: Known quarters inside TTM ended September 30, 2026 | C32: =C17+C18+C19 | D32: Q4 2025 through Q2 2026. Q3 2026 revenue is blank, so this is not TTM.
A34: A cross-check that is not in the filing
A35: Two rounded operating metrics can be multiplied, and the product is easy to misread as ARR. TTM revenue per employee was over $6.6 million as of September 30, 2026, and headcount was about 5,300. The product is just over $35 billion of implied TTM revenue. Subtracting the $18.3 billion of known quarters inside that TTM window would imply a Q3 2026 revenue on the order of $17 billion. Both inputs are approximate (“over”, “approximately”), Q3 revenue is blank in the prospectus, and Run-Rate Revenue is a 28-day construct rather than TTM. The cells below show the arithmetic so it can be stress-tested. They are not S-1 figures and they are not a forecast.
B36: Cross-check input | C36: Value | D36: Source of the input
B37: TTM revenue per employee, $ millions | C37: 6.6 | D37: S-1 says “over $6.6 million”. Typed here as 6.6 so the floor can be recomputed.
B38: Employees | C38: 5300 | D38: S-1 says “approximately 5,300” as of September 30, 2026.
B39: Implied TTM revenue, $ millions | C39: =C37*C38 | D39: Floor only if both inputs are taken at the printed rounded values. Not reported TTM.
B40: Implied Q3 2026 revenue, $ millions | C40: =C39-C32 | D40: Implied TTM minus Q4 2025, Q1 2026, and Q2 2026. Not a disclosed quarter.

Sheet Revenue Mix and Margins
B1: Revenue by consumption and subscription, and margins
B2: Note 2 disaggregates revenue two ways: consumption versus subscription, and United States versus international. There is one operating segment. There is no gross margin, and no margin, by product, model class, or pricing model. The gross margin below is revenue minus Note 8 cost of revenue. It is calculated here. It is not a line in the statements of operations.
A4: Consumption and subscription
A5: Consumption (“pay-for-intelligence”) is metered in tokens and priced by model. It is the substantial majority of revenue, and the company expects that to continue. Subscriptions cover a stated level of usage, generally for 12 months or less, for enterprises and prosumers. Customers can be on both. When a subscriber exhausts included usage, they step up a tier or buy more tokens. Minimum-commit contracts are mostly consumption revenue, not subscription revenue. 2023 subscription revenue was $2 million. The MD&A describes 2023 as substantially all consumption; the note is the precise split.
B6: Millions of USD | C6: 2023 | D6: 2024 | E6: 2025 | F6: H1 2025 | G6: H1 2026 | H6: Note
B7: Consumption-based revenue | C7: =Inputs!C34 | D7: =Inputs!D34 | E7: =Inputs!E34 | F7: =Inputs!F34 | G7: =Inputs!G34 | H7: Note 2.
B8: Subscription-based revenue | C8: =Inputs!C35 | D8: =Inputs!D35 | E8: =Inputs!E35 | F8: =Inputs!F35 | G8: =Inputs!G35 | H8: Note 2.
B9: Total | C9: =C7+C8 | D9: =D7+D8 | E9: =E7+E8 | F9: =F7+F8 | G9: =G7+G8 | H9: Ties to reported revenue. See Checks.
B10: Consumption mix | C10: =IF(C9=0,NA(),C7/C9) | D10: =IF(D9=0,NA(),D7/D9) | E10: =IF(E9=0,NA(),E7/E9) | F10: =IF(F9=0,NA(),F7/F9) | G10: =IF(G9=0,NA(),G7/G9) | H10: 75% in 2024, 83% in 2025, 80% in H1 2026, as the MD&A rounds them.
B11: Subscription mix | C11: =IF(C9=0,NA(),C8/C9) | D11: =IF(D9=0,NA(),D8/D9) | E11: =IF(E9=0,NA(),E8/E9) | F11: =IF(F9=0,NA(),F8/F9) | G11: =IF(G9=0,NA(),G8/G9) | H11: 25%, 17%, and 20% on the same rounding.
B12: Consumption growth vs prior comparable period | D12: =IF(C7=0,NA(),D7/C7-1) | E12: =IF(D7=0,NA(),E7/D7-1) | G12: =IF(F7=0,NA(),G7/F7-1) | H12: H1 2026 vs H1 2025, not vs full-year 2025. Amber cells have no comparable base.
B13: Subscription growth vs prior comparable period | D13: =IF(C8=0,NA(),D8/C8-1) | E13: =IF(D8=0,NA(),E8/D8-1) | G13: =IF(F8=0,NA(),G8/F8-1) | H13: Same comparison windows.
A15: Geography, by billing address
B16: Millions of USD | C16: 2023 | D16: 2024 | E16: 2025 | F16: H1 2025 | G16: H1 2026 | H16: Note
B17: United States | C17: =Inputs!C37 | D17: =Inputs!D37 | E17: =Inputs!E37 | F17: =Inputs!F37 | G17: =Inputs!G37 | H17: Note 2. No country outside the U.S. is broken out.
B18: International | C18: =Inputs!C38 | D18: =Inputs!D38 | E18: =Inputs!E38 | F18: =Inputs!F38 | G18: =Inputs!G38 | H18: Note 2.
B19: United States mix | C19: =IF((C17+C18)=0,NA(),C17/(C17+C18)) | D19: =IF((D17+D18)=0,NA(),D17/(D17+D18)) | E19: =IF((E17+E18)=0,NA(),E17/(E17+E18)) | F19: =IF((F17+F18)=0,NA(),F17/(F17+F18)) | G19: =IF((G17+G18)=0,NA(),G17/(G17+G18)) | H19: About two-thirds to the low-70s since 2024. 83% in 2023.
B20: International mix | C20: =IF((C17+C18)=0,NA(),C18/(C17+C18)) | D20: =IF((D17+D18)=0,NA(),D18/(D17+D18)) | E20: =IF((E17+E18)=0,NA(),E18/(E17+E18)) | F20: =IF((F17+F18)=0,NA(),F18/(F17+F18)) | G20: =IF((G17+G18)=0,NA(),G18/(G17+G18)) | H20: No margin by region.
A22: Margins the filing supports, and the cuts it does not
B23: Margin | C23: 2023 | D23: 2024 | E23: 2025 | F23: H1 2025 | G23: H1 2026 | H23: Scope
B24: Implied gross margin (revenue − cost of revenue) | C24: =(Inputs!C6-Inputs!C26)/Inputs!C6 | D24: =(Inputs!D6-Inputs!D26)/Inputs!D6 | E24: =(Inputs!E6-Inputs!E26)/Inputs!E6 | F24: =(Inputs!F6-Inputs!F26)/Inputs!F6 | G24: =(Inputs!G6-Inputs!G26)/Inputs!G6 | H24: Company-wide. Training is in R&D, not in this margin. Not reported as gross margin.
B25: GAAP operating margin | C25: =Inputs!C13/Inputs!C6 | D25: =Inputs!D13/Inputs!D6 | E25: =Inputs!E13/Inputs!E6 | F25: =Inputs!F13/Inputs!F6 | G25: =Inputs!G13/Inputs!G6 | H25: Company-wide. One segment. Q2 2026 was the first quarterly operating profit in the series.
B26: Adjusted operating margin | C26: =(Inputs!C13+Inputs!C21+Inputs!C22+Inputs!C9)/Inputs!C6 | D26: =(Inputs!D13+Inputs!D21+Inputs!D22+Inputs!D9)/Inputs!D6 | E26: =(Inputs!E13+Inputs!E21+Inputs!E22+Inputs!E9)/Inputs!E6 | F26: =(Inputs!F13+Inputs!F21+Inputs!F22+Inputs!F9)/Inputs!F6 | G26: =(Inputs!G13+Inputs!G21+Inputs!G22+Inputs!G9)/Inputs!G6 | H26: Excludes stock-based compensation, non-cash donations, and the Bartz settlement.
B27: Compute expense as % of revenue | C27: =Inputs!C7/Inputs!C6 | D27: =Inputs!D7/Inputs!D6 | E27: =Inputs!E7/Inputs!E6 | F27: =Inputs!F7/Inputs!F6 | G27: =Inputs!G7/Inputs!G6 | H27: All workloads. The ratio management cites.
B28: Cost of revenue as % of revenue | C28: =Inputs!C26/Inputs!C6 | D28: =Inputs!D26/Inputs!D6 | E28: =Inputs!E26/Inputs!E6 | F28: =Inputs!F26/Inputs!F6 | G28: =Inputs!G26/Inputs!G6 | H28: Complement of the implied gross margin.
B29: Sales, marketing, and partnerships as % of revenue | C29: =Inputs!C10/Inputs!C6 | D29: =Inputs!D10/Inputs!D6 | E29: =Inputs!E10/Inputs!E6 | F29: =Inputs!F10/Inputs!F6 | G29: =Inputs!G10/Inputs!G6 | H29: Nature line: channel fees and advertising. 19% in H1 2026.
B30: Functional sales and marketing as % of revenue | C30: =Inputs!C28/Inputs!C6 | D30: =Inputs!D28/Inputs!D6 | E30: =Inputs!E28/Inputs!E6 | F30: =Inputs!F28/Inputs!F6 | G30: =Inputs!G28/Inputs!G6 | H30: Note 8. Higher than the nature line because it includes people, free-tier compute, and overhead.
B31: Channel-fee increase as % of revenue | C31: =IF(Inputs!C45="",NA(),Inputs!C45/Inputs!C6) | D31: =IF(Inputs!D45="",NA(),Inputs!D45/Inputs!D6) | E31: =IF(Inputs!E45="",NA(),Inputs!E45/Inputs!E6) | F31: =IF(Inputs!F45="",NA(),Inputs!F45/Inputs!F6) | G31: =IF(Inputs!G45="",NA(),Inputs!G45/Inputs!G6) | H31: Increase only. $341 million in 2025 and $2.7 billion in H1 2026. The fee level is not disclosed.
B32: Upper bound: margin after cost of revenue and the channel-fee increase | C32: =IF(Inputs!C45="",NA(),C24-C31) | D32: =IF(Inputs!D45="",NA(),D24-D31) | E32: =IF(Inputs!E45="",NA(),E24-E31) | F32: =IF(Inputs!F45="",NA(),F24-F31) | G32: =IF(Inputs!G45="",NA(),G24-G31) | H32: Upper bound. Subtracting the increase and not the base overstates the margin that remains. Not a product or channel margin.
A34: Channel-partner fees are the closest thing to a cost that differs by route to market, and even that is not allocated to consumption versus subscription. The filing discloses the increase, not the fee. Prior-period sales and marketing was $43 million in 2024 and $120 million in the first half of 2025, so the base fee inside the increase is small relative to the $2.7 billion step-up, but it is still omitted from the upper bound above. The company pays cloud providers a fee and keeps the customer contract, so a large share of this cost rides on consumption sold through AWS, Google Cloud, and Azure. The filing does not say how much.
A36: Cuts that were requested and are not in the S-1
B37: Cut | C37: Disclosed? | D37: What exists instead | E37: Margin?
B38: Consumption vs subscription | C38: Revenue only | D38: Note 2, annual and first half. Not quarterly.
B39: United States vs international | C39: Revenue only | D39: Note 2, billing address. Long-lived assets are 94–95% in the U.S.
B40: Operating segment | C40: One segment | D40: Note 14. CODM is the CEO and President. Segment profit is consolidated net loss. SBC inside personnel is the only extra item the CODM receives.
B41: Claude Platform vs first-party apps | C41: Not disclosed | D41: Qualitative. Over 50% of ≥$100k customers used both the platform and an app in Q3 2026, up from about 30% in Q4 2025.
B42: Claude Code, Cowork, Claude.ai | C42: Not disclosed | D42: Enterprise users who did not use Claude Code spent under $75 a month on average. The top 5% of Enterprise users who used Claude Code spent about 20× that. Not a revenue total.
B43: Model class (Mythos/Fable, Opus, Sonnet, Haiku) | C43: Not disclosed | D43: Pricing and cost-per-task comments only. Opus 5.5 cut customer cost per task about 40% versus Opus 5. Fable 5.1 cut typical-workload cost about 25% versus Fable 5.
B44: Direct vs cloud marketplace | C44: Not disclosed | D44: Channel-partner fee is in sales and marketing. The increase is disclosed. The level, and the split of revenue by channel, are not.
B45: Free tier | C45: Not disclosed | D45: Compute for free access is inside functional sales and marketing, not cost of revenue.
...

Sheet Quarterly PnL
B1: Quarterly results of operations
B2: Unaudited, from the MD&A quarterly table, except Q4 2024 revenue, which is the $197 million named in the risk factors. Amber cells are not in the filing. Margins and adjusted figures are formulas.
B4: Millions of USD | C4: Q4 2024 | D4: Q1 2025 | E4: Q2 2025 | F4: Q3 2025 | G4: Q4 2025 | H4: Q1 2026 | I4: Q2 2026
B5: Revenue | C5: =Inputs!C73 | D5: =Inputs!D73 | E5: =Inputs!E73 | F5: =Inputs!F73 | G5: =Inputs!G73 | H5: =Inputs!H73 | I5: =Inputs!I73
B6: Compute and infrastructure | D6: =Inputs!D74 | E6: =Inputs!E74 | F6: =Inputs!F74 | G6: =Inputs!G74 | H6: =Inputs!H74 | I6: =Inputs!I74
B7: Personnel | D7: =Inputs!D75 | E7: =Inputs!E75 | F7: =Inputs!F75 | G7: =Inputs!G75 | H7: =Inputs!H75 | I7: =Inputs!I75
B8: Bartz settlement | D8: =Inputs!D76 | E8: =Inputs!E76 | F8: =Inputs!F76 | G8: =Inputs!G76 | H8: =Inputs!H76 | I8: =Inputs!I76
B9: Sales, marketing, and partnerships | D9: =Inputs!D77 | E9: =Inputs!E77 | F9: =Inputs!F77 | G9: =Inputs!G77 | H9: =Inputs!H77 | I9: =Inputs!I77
B10: Other operating and administrative | D10: =Inputs!D78 | E10: =Inputs!E78 | F10: =Inputs!F78 | G10: =Inputs!G78 | H10: =Inputs!H78 | I10: =Inputs!I78
B11: Total operating expenses | D11: =Inputs!D79 | E11: =Inputs!E79 | F11: =Inputs!F79 | G11: =Inputs!G79 | H11: =Inputs!H79 | I11: =Inputs!I79
B12: Operating income (loss) | D12: =Inputs!D80 | E12: =Inputs!E80 | F12: =Inputs!F80 | G12: =Inputs!G80 | H12: =Inputs!H80 | I12: =Inputs!I80
B13: Interest income | D13: =Inputs!D81 | E13: =Inputs!E81 | F13: =Inputs!F81 | G13: =Inputs!G81 | H13: =Inputs!H81 | I13: =Inputs!I81
B14: Change in fair value of notes, derivatives, and SAFEs | D14: =Inputs!D82 | E14: =Inputs!E82 | F14: =Inputs!F82 | G14: =Inputs!G82 | H14: =Inputs!H82 | I14: =Inputs!I82
B15: Other income (expense), net | D15: =Inputs!D83 | E15: =Inputs!E83 | F15: =Inputs!F83 | G15: =Inputs!G83 | H15: =Inputs!H83 | I15: =Inputs!I83
B16: Loss before income taxes | D16: =Inputs!D84 | E16: =Inputs!E84 | F16: =Inputs!F84 | G16: =Inputs!G84 | H16: =Inputs!H84 | I16: =Inputs!I84
B17: Provision for income taxes | D17: =Inputs!D85 | E17: =Inputs!E85 | F17: =Inputs!F85 | G17: =Inputs!G85 | H17: =Inputs!H85 | I17: =Inputs!I85
B18: Net loss | D18: =Inputs!D86 | E18: =Inputs!E86 | F18: =Inputs!F86 | G18: =Inputs!G86 | H18: =Inputs!H86 | I18: =Inputs!I86
B20: Stock-based compensation | D20: =Inputs!D87 | E20: =Inputs!E87 | F20: =Inputs!F87 | G20: =Inputs!G87 | H20: =Inputs!H87 | I20: =Inputs!I87
B21: Non-cash charitable contributions | D21: =Inputs!D88 | E21: =Inputs!E88 | F21: =Inputs!F88 | G21: =Inputs!G88 | H21: =Inputs!H88 | I21: =Inputs!I88
B22: Mark-to-market add-back | D22: =Inputs!D89 | E22: =Inputs!E89 | F22: =Inputs!F89 | G22: =Inputs!G89 | H22: =Inputs!H89 | I22: =Inputs!I89
B24: Computed margins
B25: Compute as % of revenue | D25: =IF(D5=0,NA(),D6/D5) | E25: =IF(E5=0,NA(),E6/E5) | F25: =IF(F5=0,NA(),F6/F5) | G25: =IF(G5=0,NA(),G6/G5) | H25: =IF(H5=0,NA(),H6/H5) | I25: =IF(I5=0,NA(),I6/I5)
B26: GAAP operating margin | D26: =IF(D5=0,NA(),D12/D5) | E26: =IF(E5=0,NA(),E12/E5) | F26: =IF(F5=0,NA(),F12/F5) | G26: =IF(G5=0,NA(),G12/G5) | H26: =IF(H5=0,NA(),H12/H5) | I26: =IF(I5=0,NA(),I12/I5)
B27: Adjusted operating income | D27: =D12+D20+D21+D8 | E27: =E12+E20+E21+E8 | F27: =F12+F20+F21+F8 | G27: =G12+G20+G21+G8 | H27: =H12+H20+H21+H8 | I27: =I12+I20+I21+I8
B28: Adjusted operating margin | D28: =IF(D5=0,NA(),D27/D5) | E28: =IF(E5=0,NA(),E27/E5) | F28: =IF(F5=0,NA(),F27/F5) | G28: =IF(G5=0,NA(),G27/G5) | H28: =IF(H5=0,NA(),H27/H5) | I28: =IF(I5=0,NA(),I27/I5)
B29: Adjusted net income | D29: =D18+D20+D21+D8-D14+D22 | E29: =E18+E20+E21+E8-E14+E22 | F29: =F18+F20+F21+F8-F14+F22 | G29: =G18+G20+G21+G8-G14+G22 | H29: =H18+H20+H21+H8-H14+H22 | I29: =I18+I20+I21+I8-I14+I22
B30: Sequential revenue growth | D30: =IF(C5=0,NA(),D5/C5-1) | E30: =IF(D5=0,NA(),E5/D5-1) | F30: =IF(E5=0,NA(),F5/E5-1) | G30: =IF(F5=0,NA(),G5/F5-1) | H30: =IF(G5=0,NA(),H5/G5-1) | I30: =IF(H5=0,NA(),I5/H5-1)
A32: Adjusted operating income adds back stock-based compensation, non-cash charitable contributions, and the Bartz settlement. Adjusted net income also adds back the fair-value loss on convertible notes, derivatives, and SAFEs, and the mark-to-market instruments. Q2 2026 adjusted operating income of $2,235 million and adjusted net income of $2,981 million match the reconciliation in the filing. Q2 2026 stock-based compensation is $1,261 million in that reconciliation; the quarterly footnote rounds the same figure to $1.3 billion.

Sheet Annual PnL
B1: Annual and first-half results
B2: Audited years ended December 31, 2023, 2024, and 2025. Unaudited six months ended June 30, 2025 and 2026. First-half figures are not annualized. Dollars in millions.
B4: Millions of USD | C4: 2023 | D4: 2024 | E4: 2025 | F4: H1 2025 | G4: H1 2026
B5: Revenue | C5: =Inputs!C6 | D5: =Inputs!D6 | E5: =Inputs!E6 | F5: =Inputs!F6 | G5: =Inputs!G6
B6: Compute and infrastructure | C6: =Inputs!C7 | D6: =Inputs!D7 | E6: =Inputs!E7 | F6: =Inputs!F7 | G6: =Inputs!G7
B7: Personnel | C7: =Inputs!C8 | D7: =Inputs!D8 | E7: =Inputs!E8 | F7: =Inputs!F8 | G7: =Inputs!G8
B8: Bartz settlement | C8: =Inputs!C9 | D8: =Inputs!D9 | E8: =Inputs!E9 | F8: =Inputs!F9 | G8: =Inputs!G9
B9: Sales, marketing, and partnerships | C9: =Inputs!C10 | D9: =Inputs!D10 | E9: =Inputs!E10 | F9: =Inputs!F10 | G9: =Inputs!G10
B10: Other operating and administrative | C10: =Inputs!C11 | D10: =Inputs!D11 | E10: =Inputs!E11 | F10: =Inputs!F11 | G10: =Inputs!G11
B11: Total operating expenses | C11: =Inputs!C12 | D11: =Inputs!D12 | E11: =Inputs!E12 | F11: =Inputs!F12 | G11: =Inputs!G12
B12: Operating income (loss) | C12: =Inputs!C13 | D12: =Inputs!D13 | E12: =Inputs!E13 | F12: =Inputs!F13 | G12: =Inputs!G13
B13: Interest income | C13: =Inputs!C14 | D13: =Inputs!D14 | E13: =Inputs!E14 | F13: =Inputs!F14 | G13: =Inputs!G14
B14: Change in fair value of notes, derivatives, and SAFEs | C14: =Inputs!C15 | D14: =Inputs!D15 | E14: =Inputs!E15 | F14: =Inputs!F15 | G14: =Inputs!G15
B15: Other income (expense), net | C15: =Inputs!C16 | D15: =Inputs!D16 | E15: =Inputs!E16 | F15: =Inputs!F16 | G15: =Inputs!G16
B16: Loss before income taxes | C16: =Inputs!C17 | D16: =Inputs!D17 | E16: =Inputs!E17 | F16: =Inputs!F17 | G16: =Inputs!G17
... B22: Mark-to-market add-back | C22: =Inputs!C23 | D22: =Inputs!D23 | E22: =Inputs!E23 | F22: =Inputs!F23 | G22: =Inputs!G23
B24: Cost of revenue (Note 8) | C24: =Inputs!C26 | D24: =Inputs!D26 | E24: =Inputs!E26 | F24: =Inputs!F26 | G24: =Inputs!G26
B25: Research and development (Note 8) | C25: =Inputs!C27 | D25: =Inputs!D27 | E25: =Inputs!E27 | F25: =Inputs!F27 | G25: =Inputs!G27
B26: Sales and marketing, functional (Note 8) | C26: =Inputs!C28 | D26: =Inputs!D28 | E26: =Inputs!E28 | F26: =Inputs!F28 | G26: =Inputs!G28
B27: General and administrative (Note 8) | C27: =Inputs!C30 | D27: =Inputs!D30 | E27: =Inputs!E30 | F27: =Inputs!F30 | G27: =Inputs!G30
B29: Purchases of property and equipment | C29: =Inputs!C41 | D29: =Inputs!D41 | E29: =Inputs!E41 | F29: =Inputs!F41 | G29: =Inputs!G41
B30: Depreciation and amortization (cash flow) | C30: =Inputs!C42 | D30: =Inputs!D42 | E30: =Inputs!E42 | F30: =Inputs!F42 | G30: =Inputs!G42
B31: Depreciation of property and equipment | C31: =Inputs!C43 | D31: =Inputs!D43 | E31: =Inputs!E43 | F31: =Inputs!F43 | G31: =Inputs!G43
B33: Computed
B34: GAAP operating margin | C34: =IF(C5=0,NA(),C12/C5) | D34: =IF(D5=0,NA(),D12/D5) | E34: =IF(E5=0,NA(),E12/E5) | F34: =IF(F5=0,NA(),F12/F5) | G34: =IF(G5=0,NA(),G12/G5)
B35: Adjusted operating income | C35: =C12+C20+C21+C8 | D35: =D12+D20+D21+D8 | E35: =E12+E20+E21+E8 | F35: =F12+F20+F21+F8 | G35: =G12+G20+G21+G8
B36: Adjusted operating margin | C36: =IF(C5=0,NA(),C35/C5) | D36: =IF(D5=0,NA(),D35/D5) | E36: =IF(E5=0,NA(),E35/E5) | F36: =IF(F5=0,NA(),F35/F5) | G36: =IF(G5=0,NA(),G35/G5)
B37: Adjusted net income | C37: =C18+C20+C21+C8-C14+C22 | D37: =D18+D20+D21+D8-D14+D22 | E37: =E18+E20+E21+E8-E14+E22 | F37: =F18+F20+F21+F8-F14+F22 | G37: =G18+G20+G21+G8-G14+G22
B38: Implied gross profit | C38: =C5-C24 | D38: =D5-D24 | E38: =E5-E24 | F38: =F5-F24 | G38: =G5-G24
B39: Implied gross margin | C39: =IF(C5=0,NA(),C38/C5) | D39: =IF(D5=0,NA(),D38/D5) | E39: =IF(E5=0,NA(),E38/E5) | F39: =IF(F5=0,NA(),F38/F5) | G39: =IF(G5=0,NA(),G38/G5)
B40: Compute as % of revenue | C40: =IF(C5=0,NA(),C6/C5) | D40: =IF(D5=0,NA(),D6/D5) | E40: =IF(E5=0,NA(),E6/E5) | F40: =IF(F5=0,NA(),F6/F5) | G40: =IF(G5=0,NA(),G6/G5)
B41: Year-over-year revenue growth | D41: =IF(C5=0,NA(),D5/C5-1) | E41: =IF(D5=0,NA(),E5/D5-1) | G41: =IF(F5=0,NA(),G5/F5-1)
A43: Adjusted operating income is $(522), $(2,788), $(4,854), $(1,849), and $1,618 million across these columns, matching the filing. Adjusted operating margin is (1,273)%, (722)%, (106)%, (159)%, and 10%. Adjusted net income is $(457), $(2,683), $(4,448), $(1,741), and $2,671 million. The first-half 2026 operating loss of $693 million and adjusted operating income of $1,618 million can both be true because stock-based compensation was $2,185 million.

Sheet Customers and KPIs
B1: Customers and operating metrics
B2: Counts and cohort revenue are as printed. Several September 30, 2026 dollar amounts are blank in the preliminary prospectus and are left blank here.
A4: Customers with at least $100,000 of trailing-twelve-month revenue
B5: As of / for | C5: Customer count | D5: Cohort revenue ($ millions) | E5: Share of revenue | F5: Window of the revenue
B6: December 31, 2023 | C6: 20 | D6: 37 | E6: 0.9 | F6: Full year 2023. Count is approximately 20.
B7: December 31, 2024 | C7: 200 | D7: 220 | E7: 0.57 | F7: Full year 2024. Count is approximately 200. Cohort revenue approximately $220 million.
B8: March 31, 2025 | C8: 400 | F8: Count only. Approximately 400.
B9: June 30, 2025 | C9: 600 | D9: 870 | E9: 0.75 | F9: First half of 2025. More than 600 customers. Cohort revenue $870 million.
B10: September 30, 2025 | C10: 950 | F10: Count only. More than 950.
B11: December 31, 2025 | C11: 1500 | D11: 3500 | E11: 0.76 | F11: Full year 2025. Approximately 1,500. Revenue printed as $3.5 billion.
B12: June 30, 2026 | C12: 6000 | D12: 12000 | E12: 0.74 | F12: First half of 2026. More than 6,000. Revenue printed as $12.0 billion.
B13: September 30, 2026 | C13: 11900 | F13: More than 11,900. Cohort revenue and the mix percent are blank.
A14: Year-end counts for 2023, 2024, and 2025, and the March 31, 2025 count, are “approximately.” The June 30, 2025, September 30, 2025, June 30, 2026, and September 30, 2026 counts are “more than” the figure in the count column. A customer is an organization, with accounts aggregated by internal records. The company does not track an “enterprise” category. It uses the $100,000 threshold as its enterprise measure because that level of spend is generally organizational. The count can move when accounts are re-aggregated. The remaining share of trailing-twelve-month revenue at September 30, 2026 came from about 40 million customers each below $100,000. That dollar share is blank.
A16: Larger customers as of September 30, 2026
B17: Threshold, trailing twelve months | C17: Count | D17: Revenue of this tier
B18: At least $100,000 | C18: More than 11,900 | D18: Blank in the filing
B19: At least $1 million | C19: More than 1,900 | D19: Not disclosed
B20: At least $10 million | C20: Approximately 250 | D20: Not disclosed
A22: Retention, concentration, and productivity
B23: Metric | C23: Value | D23: As of | E23: Definition constraint
B24: Net revenue retention | C24: Approximately 900% | D24: September 30, 2026 | E24: Cohort ratio. Excludes Claude Pro and Max. Only date disclosed.
B25: TTM revenue per employee | C25: Over $6.6 million | D25: September 30, 2026 | E25: Was $1.4 million at September 30, 2025.
B26: TTM revenue growth vs prior year | C26: Approximately 1,200% | D26: September 30, 2025 to 2026 | E26: Headcount up about 170% over the same span.
B27: Employees | C27: Approximately 5,300 | D27: September 30, 2026 | E27: About 940 at December 31, 2024.
B28: No single customer | C28: Not more than 10% of revenue | D28: Nine months ended September 30, 2026 | E28: Top five were about 25% over that nine-month period.
B29: Revenue outside the top five | C29: About 79% | D29: Quarter ended September 30, 2026 | E29: Was about 64% in the quarter ended March 31, 2026.
B30: Top five customers | C30: Each at a record | D30: Quarter ended September 30, 2026 | E30: Dollar amounts not disclosed.
B31: Policy-violating usage | C31: About 5% to 7% of revenue | D31: Nine months ended September 30, 2026 | E31: Recognized before access is cut off. Expected to decline after tighter enforcement in August and September 2026.
B32: Fortune 500 with ≥$100k TTM | C32: Over 50% | D32: September 30, 2026 | E32: Every Fortune 10 company. Over 30% of the Global 2000.
B33: Revenue vs Fortune 500 expenses | C33: Under 0.1% on average | D33: Quarter ended September 30, 2026 | E33: Top 10 Fortune 500 customers: under 1% of their expenses, about 8× the broader Fortune 500 average.
B34: Models released in the prior six months | C34: Over 80% of revenue | D34: Quarter ended September 30, 2026 | E34: Share of that quarter’s revenue from model versions released in the six months ended September 30, 2026.
B35: Code written by Claude | C35: Over 90% of contributions | D35: September 2026 | E35: Internal codebase. Daily code per engineer in Q3 2026 was over 45× the 2024 daily average.

Sheet Compute Commitments
B1: Forward compute commitments
B2: These amounts buy a fungible pool. None of them is labeled training or inference. The financial-statement totals and the named contracts overlap. They are different snapshots. They are not additive.
A4: Totals in the financial-statement notes
B5: Item | C5: Dec 31, 2025 | D5: Jun 30, 2026 | E5: Unit
B6: Fixed or minimum purchase commitments | C6: =Inputs!D104 | D6: =Inputs!E104 | E6: Millions of USD
B7: Leases not yet commenced, undiscounted | C7: =Inputs!D105 | D7: =Inputs!E105 | E7: Millions of USD
A8: December 31, 2025 purchase commitments of $54.559 billion are the scheduled non-cancelable agreements with more than a year left, mostly cloud hosting (Note 13). By June 30, 2026 that population was about $265.6 billion, with terms of 1 to 20 years. Separately, leases signed but not yet commenced were $50.2 billion at year-end 2025 and $321.4 billion at June 30, 2026 (Note 7). Some of those leases are conditional. The company may pay a portion by issuing convertible notes. Agreements with no fixed dollar commitment are excluded from both numbers, and the company says those payments will be significant. The MD&A’s later aggregate, “as of and subsequent to September 30, 2026,” is blank in this preliminary filing, including the portion due before 2031 and the portion due in the next 12 months.
A10: December 31, 2025 purchase-commitment schedule
B11: Year of payment | C11: Amount ($ millions)
B12: 2026 | C12: 7059
B13: 2027 | C13: 11128
B14: 2028 | C14: 10832
B15: 2029 | C15: 8304
B16: 2030 | C16: 5428
B17: Thereafter | C17: 11808
B18: Total | C18: =SUM(C12:C17) | D18: Must equal 54,559.
A20: Named agreements in the MD&A — overlapping, later, and not a sum
B21: Counterparty | C21: Stated amount ($ millions) | D21: What the amount is | E21: Term / timing | F21: Cancelable?
B22: Microsoft | C22: 44900 | D22: At least this spend, regardless of usage | E22: November 2026 – May 2033 | F22: Non-cancelable except breach, or undelivered tranches
B23: Google, base commitment | C23: 114500 | D23: At least about this spend, with a true-up | E23: April 2026 – July 2033 | F23: Non-cancelable except breach
B24: Google, additional TPUs | C24: 125000 | D24: Low end of the company’s estimate. Not in the commitments table. | E24: Delivery 2028 – 2031 | F24: Depends on capacity, deployment, and price
B25: Google, additional TPUs, high end | C25: 150000 | D25: High end of the same estimate. Do not add to the low end. | E25: Delivery 2028 – 2031 | F25: Same agreement
B26: Amazon | C26: 110000 | D26: At least this spend, with a true-up | E26: May 2026 – April 2036 | F26: Non-cancelable except breach
B27: SpaceXAI | C27: 120500 | D27: Up to this spend. About $3.1 billion a month once full, expected December 2026. | E27: Into 2029 | F27: Either party may cancel on 90 days after January 2027 or March 2027, depending on the agreement
B28: AMD, initial tranche | C28: 20000 | D28: No fixed commitment. Expected to exceed this if the full initial tranche is taken. Not in the commitments table. | E28: Calendar 2027 | F28: Non-cancelable by Anthropic except for AMD’s breach
B29: Nscale | C29: 44600 | D29: Up to about this spend. Fees accrue as capacity is accepted. | E29: Into 2033 | F29: Subject to Nscale financing; otherwise limited termination rights
B30: Lambda | C30: 41300 | D30: About this spend, of which about $34.9 billion is the August 2026 agreement. | E30: Into 2034 | F30: August agreement can end if the facility lease is not secured
B31: Broadcom equipment leases | C31: 161200 | D31: Aggregate rent excluding interest. Finance leases. Do not add the $125.2 billion 2026 lease, which is a subset described in the risk factors. | E31: Five years, rent starts when equipment is ready | F31: Non-cancelable during the lease except default
A33: A naive sum of the rows above double-counts the Google range, double-counts the Broadcom subset, and mixes June-snapshot note totals with contracts signed or amended through October 2026. The workbook therefore has no total under this table. Financing is also not spend: the Broadcom note facility is up to $42 billion to fund rent on the 2026 lease, Google has up to $20 billion of remaining note capacity, Amazon has $15 billion, and AMD has agreed to buy up to $5 billion of stock as GPU milestones are met. On the balance sheet at June 30, 2026, property and equipment net was $1.2 billion, servers gross were $618 million, construction in progress was $536 million, and finance-lease liabilities were $443 million. Almost all of the committed compute was still off the balance sheet and not yet in the income statement. Expense hits as the compute becomes available, which the company says is often 12 to 18 months after it is procured.

Sheet Inputs
B1: Inputs — figures as printed in the S-1
B2: Units: millions of U.S. dollars, except percentages, counts, and ratios. Blue cells are taken from the filing. Other sheets reference these cells. H1 columns are six months ended June 30, not annualized.
B4: Consolidated statements of operations — by nature
B5: Line | C5: 2023 | D5: 2024 | E5: 2025 | F5: H1 2025 | G5: H1 2026 | J5: Where it appears
B6: Revenue | C6: 41 | D6: 386 | E6: 4585 | F6: 1163 | G6: 16286 | J6: Statements of operations; MD&A
B7: Compute and infrastructure | C7: 433 | D7: 2522 | E7: 7326 | F7: 2334 | G7: 8945 | J7: Same. Single line for all workloads.
B8: Personnel | C8: 95 | D8: 454 | E8: 1839 | F8: 538 | G8: 3152 | J8: Same
B9: Bartz settlement | C9: 0 | D9: 0 | E9: 1500 | F9: 0 | G9: 0 | J9: Same. 2025 charge. Zeros stored as 0, not em dash.
B10: Sales, marketing, and partnerships | C10: 2 | D10: 43 | E10: 568 | F10: 120 | G10: 3168 | J10: Nature presentation. Channel fees and marketing.
B11: Other operating and administrative | C11: 62 | D11: 347 | E11: 1412 | F11: 306 | G11: 1714 | J11: Same
B12: Total operating expenses | C12: 592 | D12: 3366 | E12: 12645 | F12: 3298 | G12: 16979 | J12: Reported total
B13: Operating income (loss) | C13: -551 | D13: -2980 | E13: -8060 | F13: -2135 | G13: -693 | J13: Reported
B14: Interest income | C14: 69 | D14: 106 | E14: 431 | F14: 115 | G14: 1111 | J14: Reported
B15: Change in fair value of convertible notes, derivatives, and SAFEs | C15: -1045 | D15: -5434 | E15: -34308 | F15: -10942 | G15: -72388 | J15: Expense shown as reported (negative).
B16: Other income (expense), net | C16: -2 | D16: 0 | E16: -8 | F16: 0 | G16: -8757 | J16: 2024 and H1 2025 printed as em dash; stored as 0.
B17: Loss before income taxes | C17: -1529 | D17: -8308 | E17: -41945 | F17: -12962 | G17: -80727 | J17: Reported
... B19: Net loss | C19: -1531 | D19: -8309 | E19: -41965 | F19: -12969 | G19: -80748 | J19: Reported
B20: Items used in non-GAAP reconciliation
B21: Stock-based compensation (non-GAAP reconciliation) | C21: 29 | D21: 192 | E21: 1165 | F21: 286 | G21: 2185 | J21: Non-GAAP reconciliation. Cash-flow statement shows 1,158 for 2025, a $7 million presentation difference.
B22: Non-cash charitable contributions | C22: 0 | D22: 0 | E22: 541 | F22: 0 | G22: 126 | J22: Donation-matching program. Added back in adjusted operating income.
B23: Change in fair value of certain mark-to-market instruments | C23: 0 | D23: 0 | E23: 3 | F23: 0 | G23: 8720 | J23: Added back in adjusted net income only.
B25: Operating expenses by function — Note 8 (the training / inference proxy)
B26: Cost of revenue | C26: 26 | D26: 752 | E26: 2773 | F26: 1019 | G26: 2380 | J26: Note 8. Substantially all is customer-serving compute, plus some personnel and overhead.
B27: Research and development | C27: 422 | D27: 2275 | E27: 6338 | F27: 1850 | G27: 9741 | J27: Note 8. Primarily compute for model development, research, and internal usage, plus personnel, software, and overhead.
B28: Sales and marketing (functional) | C28: 76 | D28: 163 | E28: 911 | F28: 239 | G28: 3808 | J28: Note 8. Includes channel costs, marketing, personnel, free-tier compute, and overhead.
B29: Bartz settlement (functional) | C29: 0 | D29: 0 | E29: 1500 | F29: 0 | G29: 0 | J29: Note 8
B30: General and administrative | C30: 68 | D30: 176 | E30: 1123 | F30: 190 | G30: 1050 | J30: Note 8. Donation match, personnel, facilities, legal, taxes.
B31: Total operating expenses (functional) | C31: 592 | D31: 3366 | E31: 12645 | F31: 3298 | G31: 16979 | J31: Note 8. Ties to the nature total.
B33: Revenue disaggregation — Note 2
B34: Consumption-based revenue | C34: 39 | D34: 288 | E34: 3796 | F34: 983 | G34: 13064 | J34: Note 2. Pay-for-intelligence, metered in tokens.
B35: Subscription-based revenue | C35: 2 | D35: 98 | E35: 789 | F35: 180 | G35: 3222 | J35: Note 2. Generally 12 months or less.
B37: United States revenue | C37: 34 | D37: 263 | E37: 3362 | F37: 820 | G37: 11763 | J37: Note 2. Billing address.
B38: International revenue | C38: 7 | D38: 123 | E38: 1223 | F38: 343 | G38: 4523 | J38: Note 2. Billing address.
B40: Cash investment in owned compute (not the expense line)
B41: Purchases of property and equipment (cash outflow) | C41: 2 | D41: 15 | E41: 131 | F41: 18 | G41: 482 | J41: Cash flow statement. Sign flipped to a positive outflow.
B42: Depreciation and amortization (cash-flow add-back) | C42: 3 | D42: 21 | E42: 40 | F42: 14 | G42: 97 | J42: Cash flow statement. Includes intangibles.
B43: Depreciation of property and equipment | C43: 1 | D43: 3 | E43: 10 | F43: 4 | G43: 35 | J43: Note 6.
B44: Channel-partner fee increase vs the comparable prior period (not the fee level)
B45: Increase in fees paid to channel partners | E45: 341 | G45: 2700 | J45: MD&A. 2025 vs 2024: +$341 million. H1 2026 vs H1 2025: +$2.7 billion. Level of the fee is not disclosed. Amber cells are not disclosed.
B70: Unaudited quarterly statements of operations
...

Sheet Checks
B1: Tie-out checks
B2: Each row should read OK. A CHECK means two S-1 figures that ought to tie do not.
B4: Check | C4: 2023 | D4: 2024 | E4: 2025 | F4: H1 2025 | G4: H1 2026 | H4: Result
B5: Nature lines sum to total operating expenses | C5: =IF(ABS((Inputs!C7+Inputs!C8+Inputs!C9+Inputs!C10+Inputs!C11)-Inputs!C12)<0.5,"OK","CHECK") | D5: =IF(ABS((Inputs!D7+Inputs!D8+Inputs!D9+Inputs!D10+Inputs!D11)-Inputs!D12)<0.5,"OK","CHECK") | E5: =IF(ABS((Inputs!E7+Inputs!E8+Inputs!E9+Inputs!E10+Inputs!E11)-Inputs!E12)<0.5,"OK","CHECK") | F5: =IF(ABS((Inputs!F7+Inputs!F8+Inputs!F9+Inputs!F10+Inputs!F11)-Inputs!F12)<0.5,"OK","CHECK") | G5: =IF(ABS((Inputs!G7+Inputs!G8+Inputs!G9+Inputs!G10+Inputs!G11)-Inputs!G12)<0.5,"OK","CHECK") | H5: =IF(COUNTIF(C5:G5,"CHECK")=0,"OK","CHECK")
B6: Functional lines sum to total operating expenses | C6: =IF(ABS((Inputs!C26+Inputs!C27+Inputs!C28+Inputs!C29+Inputs!C30)-Inputs!C31)<0.5,"OK","CHECK") | D6: =IF(ABS((Inputs!D26+Inputs!D27+Inputs!D28+Inputs!D29+Inputs!D30)-Inputs!D31)<0.5,"OK","CHECK") | E6: =IF(ABS((Inputs!E26+Inputs!E27+Inputs!E28+Inputs!E29+Inputs!E30)-Inputs!E31)<0.5,"OK","CHECK") | F6: =IF(ABS((Inputs!F26+Inputs!F27+Inputs!F28+Inputs!F29+Inputs!F30)-Inputs!F31)<0.5,"OK","CHECK") | G6: =IF(ABS((Inputs!G26+Inputs!G27+Inputs!G28+Inputs!G29+Inputs!G30)-Inputs!G31)<0.5,"OK","CHECK") | H6: =IF(COUNTIF(C6:G6,"CHECK")=0,"OK","CHECK")
B7: Nature total equals functional total | C7: =IF(ABS(Inputs!C12-Inputs!C31)<0.5,"OK","CHECK") | D7: =IF(ABS(Inputs!D12-Inputs!D31)<0.5,"OK","CHECK") | E7: =IF(ABS(Inputs!E12-Inputs!E31)<0.5,"OK","CHECK") | F7: =IF(ABS(Inputs!F12-Inputs!F31)<0.5,"OK","CHECK") | G7: =IF(ABS(Inputs!G12-Inputs!G31)<0.5,"OK","CHECK") | H7: =IF(COUNTIF(C7:G7,"CHECK")=0,"OK","CHECK")
B8: Consumption + subscription = revenue | C8: =IF(ABS((Inputs!C34+Inputs!C35)-Inputs!C6)<0.5,"OK","CHECK") | D8: =IF(ABS((Inputs!D34+Inputs!D35)-Inputs!D6)<0.5,"OK","CHECK") | E8: =IF(ABS((Inputs!E34+Inputs!E35)-Inputs!E6)<0.5,"OK","CHECK") | F8: =IF(ABS((Inputs!F34+Inputs!F35)-Inputs!F6)<0.5,"OK","CHECK") | G8: =IF(ABS((Inputs!G34+Inputs!G35)-Inputs!G6)<0.5,"OK","CHECK") | H8: =IF(COUNTIF(C8:G8,"CHECK")=0,"OK","CHECK")
B9: United States + international = revenue | C9: =IF(ABS((Inputs!C37+Inputs!C38)-Inputs!C6)<0.5,"OK","CHECK") | D9: =IF(ABS((Inputs!D37+Inputs!D38)-Inputs!D6)<0.5,"OK","CHECK") | E9: =IF(ABS((Inputs!E37+Inputs!E38)-Inputs!E6)<0.5,"OK","CHECK") | F9: =IF(ABS((Inputs!F37+Inputs!F38)-Inputs!F6)<0.5,"OK","CHECK") | G9: =IF(ABS((Inputs!G37+Inputs!G38)-Inputs!G6)<0.5,"OK","CHECK") | H9: =IF(COUNTIF(C9:G9,"CHECK")=0,"OK","CHECK")
B10: Operating income = revenue − operating expenses | C10: =IF(ABS((Inputs!C6-Inputs!C12)-Inputs!C13)<0.5,"OK","CHECK") | D10: =IF(ABS((Inputs!D6-Inputs!D12)-Inputs!D13)<0.5,"OK","CHECK") | E10: =IF(ABS((Inputs!E6-Inputs!E12)-Inputs!E13)<0.5,"OK","CHECK") | F10: =IF(ABS((Inputs!F6-Inputs!F12)-Inputs!F13)<0.5,"OK","CHECK") | G10: =IF(ABS((Inputs!G6-Inputs!G12)-Inputs!G13)<0.5,"OK","CHECK") | H10: =IF(COUNTIF(C10:G10,"CHECK")=0,"OK","CHECK")
B11: Quarterly check | C11: Q1 2025 | D11: Q2 2025 | E11: Q3 2025 | F11: Q4 2025 | G11: Q1 2026 | H11: Q2 2026 | I11: Result
B12: Quarterly component lines sum to total operating expenses | C12: =IF(ABS((Inputs!D74+Inputs!D75+Inputs!D76+Inputs!D77+Inputs!D78)-Inputs!D79)<0.5,"OK","CHECK") | D12: =IF(ABS((Inputs!E74+Inputs!E75+Inputs!E76+Inputs!E77+Inputs!E78)-Inputs!E79)<0.5,"OK","CHECK") | E12: =IF(ABS((Inputs!F74+Inputs!F75+Inputs!F76+Inputs!F77+Inputs!F78)-Inputs!F79)<0.5,"OK","CHECK") | F12: =IF(ABS((Inputs!G74+Inputs!G75+Inputs!G76+Inputs!G77+Inputs!G78)-Inputs!G79)<0.5,"OK","CHECK") | G12: =IF(ABS((Inputs!H74+Inputs!H75+Inputs!H76+Inputs!H77+Inputs!H78)-Inputs!H79)<0.5,"OK","CHECK") | H12: =IF(ABS((Inputs!I74+Inputs!I75+Inputs!I76+Inputs!I77+Inputs!I78)-Inputs!I79)<0.5,"OK","CHECK") | I12: =IF(COUNTIF(C12:H12,"CHECK")=0,"OK","CHECK")
B13: 2025 revenue equals the four 2025 quarters | C13: =IF(ABS((Inputs!D73+Inputs!E73+Inputs!F73+Inputs!G73)-Inputs!E6)<0.5,"OK","CHECK")
B14: H1 2026 revenue equals Q1 + Q2 2026 | C14: =IF(ABS((Inputs!H73+Inputs!I73)-Inputs!G6)<0.5,"OK","CHECK")
B15: 2025 compute equals the four 2025 quarters | C15: =IF(ABS((Inputs!D74+Inputs!E74+Inputs!F74+Inputs!G74)-Inputs!E7)<0.5,"OK","CHECK")
B16: H1 2026 compute equals Q1 + Q2 2026 | C16: =IF(ABS((Inputs!H74+Inputs!I74)-Inputs!G7)<0.5,"OK","CHECK")
B17: Dec 31, 2025 commitment schedule sums to 54,559 | C17: =IF(ABS('Compute Commitments'!C18-54559)<0.5,"OK","CHECK")

Sheet Sources
B1: Sources and methodology
B3: Filing | C3: Anthropic, PBC Form S-1, preliminary prospectus, subject to completion. Filed October 26, 2026. File number 333-299633. Accession 0001628280-26-067168. CIK 0002130357.
B4: URL | C4: https://www.sec.gov/Archives/edgar/data/2130357/000162828026067168/anthropicpbc-sx1.htm
B5: Statements | C5: Audited consolidated financial statements for the years ended December 31, 2023, 2024, and 2025. Unaudited interim statements for the six months ended June 30, 2025 and 2026. Unaudited quarterly statements of operations for Q1 2025 through Q2 2026.
B6: Units | C6: Every dollar figure in this workbook is millions of U.S. dollars unless a cell says otherwise. Counts, percentages, and ratios are labeled.
B7: Blue cells | C7: Typed from the filing. Amber cells are amounts the filing leaves blank or does not contain. Green cells are formulas.
B8: Training vs inference | C8: Not a reported split. The face of the income statement has one compute line. Note 8 regroups operating expenses by function. Cost of revenue is substantially all customer-serving compute, plus some personnel and overhead, so it is an upper bound on paying-customer inference compute. Compute expense minus cost of revenue is a lower bound on training, research, internal inference, and free-tier inference combined.
B9: Why the bound is one-sided | C9: If cost of revenue contains non-compute costs, true customer-serving compute is lower than cost of revenue, and true other compute is higher than compute minus cost of revenue. The labels “upper bound” and “lower bound” refer to that inequality.
B10: Internal use and free tier | C10: Internal usage of Claude is inference consumed by employees. The filing puts that workload’s compute in research and development, not cost of revenue. Compute for free access is in functional sales and marketing. Both are inside the “other compute” bound.
B11: Gross margin | C11: The company stopped presenting gross profit when it switched the income statement from a functional classification to a nature classification during 2025, and it recast prior periods. Implied gross margin in this workbook is revenue minus Note 8 cost of revenue, divided by revenue. It excludes training.
B12: Adjusted figures | C12: Adjusted operating income adds back stock-based compensation, non-cash charitable contributions, and the Bartz settlement. Adjusted net income also adds back the fair-value change on convertible notes, derivatives, and SAFEs, and specified mark-to-market instruments. Definitions are the company’s.
B13: Run-Rate Revenue | C13: Trailing 28-day consumption fees × 13, plus monthly subscription fees on the measurement date × 12. The only dated observation in the prospectus is October 31, 2026, and the amount is blank. This workbook does not fill that blank.
B14: ARR and new ARR | C14: Not reported, and not estimated. Quarterly GAAP revenue × 4 is labeled illustrative. Sequential change in that annualization is four times sequential revenue, and it is labeled as such. Net revenue retention of about 900% is a cohort ratio, not dollar new ARR.
... B22: Em dashes | C22: Where the filing prints an em dash for a nil amount, this workbook stores zero so that sums work. Where a number is omitted rather than nil, the cell is amber and empty.
