Workbook

Sheet Revenue Build
A1: Snap Inc. (SNAP) - Revenue Build by Segment & Driver
B3: 2019 | C3: 2020 | D3: 2021 | E3: 2022 | F3: 2023 | G3: 2024 | H3: 2025E | I3: 2026E | J3: 2027E | K3: 2028E
B4: Historical | C4: Historical | D4: Historical | E4: Historical | F4: Historical | G4: Historical | H4: Forecast | I4: Forecast | J4: Forecast | K4: Forecast
A6: DAU DRIVERS
A7: Daily Active Users (M) | B7: 218 | C7: 265 | D7: 319 | E7: 375 | F7: 414 | G7: 443 | H7: =ROUND(G7*(1+Assumptions!H7),0) | I7: =ROUND(H7*(1+Assumptions!I7),0) | J7: =ROUND(I7*(1+Assumptions!J7),0) | K7: =ROUND(J7*(1+Assumptions!K7),0)
A8: YoY Growth | C8: =C7/B7-1 | D8: =D7/C7-1 | E8: =E7/D7-1 | F8: =F7/E7-1 | G8: =G7/F7-1 | H8: =H7/G7-1 | I8: =I7/H7-1 | J8: =J7/I7-1 | K8: =K7/J7-1
A10: ARPU DRIVERS
A11: Avg Revenue Per User ($) | B11: =ROUND(B15/B7,2) | C11: =ROUND(C15/C7,2) | D11: =ROUND(D15/D7,2) | E11: =ROUND(E15/E7,2) | F11: =ROUND(F15/F7,2) | G11: =ROUND(G15/G7,2) | H11: =ROUND(G11*(1+Assumptions!H8),2) | I11: =ROUND(H11*(1+Assumptions!I8),2) | J11: =ROUND(I11*(1+Assumptions!J8),2) | K11: =ROUND(J11*(1+Assumptions!K8),2)
A12: YoY Growth | C12: =C11/B11-1 | D12: =D11/C11-1 | E12: =E11/D11-1 | F12: =F11/E11-1 | G12: =G11/F11-1 | H12: =H11/G11-1 | I12: =I11/H11-1 | J12: =J11/I11-1 | K12: =K11/J11-1
A14: REVENUE
A15: Total Revenue ($M) | B15: 1716 | C15: 2507 | D15: 4117 | E15: 4602 | F15: 4606 | G15: 5360 | H15: =ROUND(H7*H11,0) | I15: =ROUND(I7*I11,0) | J15: =ROUND(J7*J11,0) | K15: =ROUND(K7*K11,0)
A16: YoY Growth | C16: =C15/B15-1 | D16: =D15/C15-1 | E16: =E15/D15-1 | F16: =F15/E15-1 | G16: =G15/F15-1 | H16: =H15/G15-1 | I16: =I15/H15-1 | J16: =J15/I15-1 | K16: =K15/J15-1
A18: REVENUE BY GEOGRAPHY
A19: North America | B19: 1100 | C19: 1620 | D19: 2720 | E19: 2990 | F19: 2950 | G19: 3430 | H19: =ROUND(H15*Assumptions!H26,0) | I19: =ROUND(I15*Assumptions!I26,0) | J19: =ROUND(J15*Assumptions!J26,0) | K19: =ROUND(K15*Assumptions!K26,0)
A20: % of Total | B20: =B19/B15 | C20: =C19/C15 | D20: =D19/D15 | E20: =E19/E15 | F20: =F19/F15 | G20: =G19/G15 | H20: =H19/H15 | I20: =I19/I15 | ... K20: =K19/K15
A21: Europe | B21: 360 | C21: 500 | D21: 830 | E21: 920 | F21: 920 | G21: 1070 | H21: =ROUND(H15*Assumptions!H27,0) | I21: =ROUND(I15*Assumptions!I27,0) | J21: =ROUND(J15*Assumptions!J27,0) | K21: =ROUND(K15*Assumptions!K27,0)
A22: % of Total | B22: =B21/B15 | C22: =C21/C15 | D22: =D21/D15 | E22: =E21/E15 | F22: =F21/F15 | G22: =G21/G15 | H22: =H21/H15 | I22: =I21/I15 | ... K22: =K21/K15
A23: Rest of World | B23: 256 | C23: 387 | D23: 567 | E23: 692 | F23: 736 | G23: 860 | H23: =ROUND(H15*Assumptions!H28,0) | I23: =ROUND(I15*Assumptions!I28,0) | J23: =ROUND(J15*Assumptions!J28,0) | K23: =ROUND(K15*Assumptions!K28,0)
A24: % of Total | B24: =B23/B15 | C24: =C23/C15 | D24: =D23/D15 | E24: =E23/E15 | F24: =F23/F15 | G24: =G23/G15 | H24: =H23/H15 | I24: =I23/I15 | ... K24: =K23/K15
A26: IMPLIED AD METRICS
A27: Impressions/DAU/Day | B27: 25 | C27: 27 | D27: 30 | E27: 33 | F27: 36 | G27: 39 | H27: 42 | I27: 44 | J27: 46 | K27: 48
A28: Implied eCPM ($) | B28: =ROUND(B15/(B7*B27*365/1000000)*1000,2) | C28: =ROUND(C15/(C7*C27*365/1000000)*1000,2) | D28: =ROUND(D15/(D7*D27*365/1000000)*1000,2) | E28: =ROUND(E15/(E7*E27*365/1000000)*1000,2) | F28: =ROUND(F15/(F7*F27*365/1000000)*1000,2) | G28: =ROUND(G15/(G7*G27*365/1000000)*1000,2) | H28: =ROUND(H15/(H7*H27*365/1000000)*1000,2) | I28: =ROUND(I15/(I7*I27*365/1000000)*1000,2) | ... K28: =ROUND(K15/(K7*K27*365/1000000)*1000,2)

Sheet Non-GAAP P&L
A1: Snap Inc. (SNAP) - Non-GAAP Income Statement ($M)
B3: 2019 | C3: 2020 | D3: 2021 | E3: 2022 | F3: 2023 | G3: 2024 | H3: 2025E | I3: 2026E | J3: 2027E | K3: 2028E
B4: Historical | C4: Historical | D4: Historical | E4: Historical | F4: Historical | G4: Historical | H4: Forecast | I4: Forecast | J4: Forecast | K4: Forecast
A6: Revenue | B6: 1716 | C6: 2507 | D6: 4117 | E6: 4602 | F6: 4606 | G6: 5360 | H6: ='Revenue Build'!H15 | I6: ='Revenue Build'!I15 | J6: ='Revenue Build'!J15 | K6: ='Revenue Build'!K15
A7: YoY Growth | C7: =C6/B6-1 | D7: =D6/C6-1 | E7: =E6/D6-1 | F7: =F6/E6-1 | G7: =G6/F6-1 | H7: =H6/G6-1 | I7: =I6/H6-1 | J7: =J6/I6-1 | K7: =K6/J6-1
A9: Non-GAAP Cost of Revenue | B9: 838 | C9: 1077 | D9: 1686 | E9: 2053 | F9: 2095 | G9: 2374 | H9: =ROUND(H6*(1-Assumptions!H11),0) | I9: =ROUND(I6*(1-Assumptions!I11),0) | J9: =ROUND(J6*(1-Assumptions!J11),0) | K9: =ROUND(K6*(1-Assumptions!K11),0)
A10: Non-GAAP Gross Profit | B10: =B6-B9 | C10: =C6-C9 | D10: =D6-D9 | E10: =E6-E9 | F10: =F6-F9 | G10: =G6-G9 | H10: =H6-H9 | I10: =I6-I9 | ... K10: =K6-K9
A11: Non-GAAP Gross Margin | B11: =B10/B6 | C11: =C10/C6 | D11: =D10/D6 | E11: =E10/E6 | F11: =F10/F6 | G11: =G10/G6 | H11: =H10/H6 | I11: =I10/I6 | ... K11: =K10/K6
A13: Non-GAAP Operating Expenses
A14: Non-GAAP R&D | B14: 676 | C14: 837 | D14: 965 | E14: 1220 | F14: 1133 | G14: 1132 | H14: =ROUND(H6*Assumptions!H12,0) | I14: =ROUND(I6*Assumptions!I12,0) | J14: =ROUND(J6*Assumptions!J12,0) | K14: =ROUND(K6*Assumptions!K12,0)
A15: % of Revenue | B15: =B14/B6 | C15: =C14/C6 | D15: =D14/D6 | E15: =E14/E6 | F15: =F14/F6 | G15: =G14/G6 | H15: =H14/H6 | I15: =I14/I6 | ... K15: =K14/K6
A16: Non-GAAP S&M | B16: 501 | C16: 599 | D16: 888 | E16: 1033 | F16: 934 | G16: 951 | H16: =ROUND(H6*Assumptions!H13,0) | I16: =ROUND(I6*Assumptions!I13,0) | J16: =ROUND(J6*Assumptions!J13,0) | K16: =ROUND(K6*Assumptions!K13,0)
A17: % of Revenue | B17: =B16/B6 | C17: =C16/C6 | D17: =D16/D6 | E17: =E16/E6 | F17: =F16/F6 | G17: =G16/G6 | H17: =H16/H6 | I17: =I16/I6 | ... K17: =K16/K6
A18: Non-GAAP G&A | B18: 240 | C18: 264 | D18: 282 | E18: 171 | F18: 253 | G18: 282 | H18: =ROUND(H6*Assumptions!H14,0) | I18: =ROUND(I6*Assumptions!I14,0) | J18: =ROUND(J6*Assumptions!J14,0) | K18: =ROUND(K6*Assumptions!K14,0)
A19: % of Revenue | B19: =B18/B6 | C19: =C18/C6 | D19: =D18/D6 | E19: =E18/E6 | F19: =F18/F6 | G19: =G18/G6 | H19: =H18/H6 | I19: =I18/I6 | ... K19: =K18/K6
A20: Non-GAAP Total OpEx | B20: =B14+B16+B18 | C20: =C14+C16+C18 | D20: =D14+D16+D18 | E20: =E14+E16+E18 | F20: =F14+F16+F18 | G20: =G14+G16+G18 | H20: =H14+H16+H18 | I20: =I14+I16+I18 | ... K20: =K14+K16+K18
A21: % of Revenue | B21: =B20/B6 | C21: =C20/C6 | D21: =D20/D6 | E21: =E20/E6 | F21: =F20/F6 | G21: =G20/G6 | H21: =H20/H6 | I21: =I20/I6 | ... K21: =K20/K6
A23: Non-GAAP Operating Income | B23: =B10-B20 | C23: =C10-C20 | D23: =D10-D20 | E23: =E10-E20 | F23: =F10-F20 | G23: =G10-G20 | H23: =H10-H20 | I23: =I10-I20 | ... K23: =K10-K20
A24: Non-GAAP Operating Margin | B24: =B23/B6 | C24: =C23/C6 | D24: =D23/D6 | E24: =E23/E6 | F24: =F23/F6 | G24: =G23/G6 | H24: =H23/H6 | I24: =I23/I6 | ... K24: =K23/K6
A26: PP&E Depreciation | B26: 51 | C26: 75 | D26: 85 | E26: 115 | F26: 135 | G26: 160 | H26: =Assumptions!H21 | I26: =Assumptions!I21 | J26: =Assumptions!J21 | K26: =Assumptions!K21
A27: Adjusted EBITDA | B27: =B23+B26 | C27: =C23+C26 | D27: =D23+D26 | E27: =E23+E26 | F27: =F23+F26 | G27: =G23+G26 | H27: =H23+H26 | I27: =I23+I26 | ... K27: =K23+K26
A28: Adjusted EBITDA Margin | B28: =B27/B6 | C28: =C27/C6 | D28: =D27/D6 | E28: =E27/E6 | F28: =F27/F6 | G28: =G27/G6 | H28: =H27/H6 | I28: =I27/I6 | ... K28: =K27/K6
A30: Interest & Other | B30: -51 | C30: -88 | D30: -89 | E30: -87 | F30: -100 | G30: -95 | H30: =-Assumptions!H32 | I30: =-Assumptions!I32 | J30: =-Assumptions!J32 | K30: =-Assumptions!K32
A31: Non-GAAP Pre-Tax Income | B31: =B23+B30 | C31: =C23+C30 | D31: =D23+D30 | E31: =E23+E30 | F31: =F23+F30 | G31: =G23+G30 | H31: =H23+H30 | I31: =I23+I30 | ... K31: =K23+K30
A32: Non-GAAP Tax Provision | B32: 0 | C32: 0 | D32: 10 | E32: 2 | F32: 7 | G32: 53 | H32: =IF(H31>0,ROUND(H31*Assumptions!H22,0),0) | I32: =IF(I31>0,ROUND(I31*Assumptions!I22,0),0) | J32: =IF(J31>0,ROUND(J31*Assumptions!J22,0),0) | K32: =IF(K31>0,ROUND(K31*Assumptions!K22,0),0)
A33: Non-GAAP Tax Rate | B33: =IF(B31>0,B32/B31,0) | C33: =IF(C31>0,C32/C31,0) | D33: =IF(D31>0,D32/D31,0) | E33: =IF(E31>0,E32/E31,0) | F33: =IF(F31>0,F32/F31,0) | G33: =IF(G31>0,G32/G31,0) | H33: =IF(H31>0,H32/H31,0) | I33: =IF(I31>0,I32/I31,0) | ... K33: =IF(K31>0,K32/K31,0)
A35: Non-GAAP Net Income | B35: =B31-B32 | C35: =C31-C32 | D35: =D31-D32 | E35: =E31-E32 | F35: =F31-F32 | G35: =G31-G32 | H35: =H31-H32 | I35: =I31-I32 | ... K35: =K31-K32
A37: Diluted Shares (M) | B37: =Assumptions!B48 | C37: =Assumptions!C48 | D37: =Assumptions!D48 | E37: =Assumptions!E48 | F37: =Assumptions!F48 | G37: =Assumptions!G48 | H37: =Assumptions!H48 | I37: =Assumptions!I48 | ... K37: =Assumptions!K48
A38: Non-GAAP Diluted EPS | B38: =ROUND(B35/B37,2) | C38: =ROUND(C35/C37,2) | D38: =ROUND(D35/D37,2) | E38: =ROUND(E35/E37,2) | F38: =ROUND(F35/F37,2) | G38: =ROUND(G35/G37,2) | H38: =ROUND(H35/H37,2) | I38: =ROUND(I35/I37,2) | ... K38: =ROUND(K35/K37,2)
A40: Memo: GAAP Adjustment Items (add-backs)
A41: Stock-Based Compensation | B41: 600 | C41: 770 | D41: 1096 | E41: 1538 | F41: 1376 | G41: 1296 | H41: =ROUND(H6*Assumptions!H17,0) | I41: =ROUND(I6*Assumptions!I17,0) | J41: =ROUND(J6*Assumptions!J17,0) | K41: =ROUND(K6*Assumptions!K17,0)
A42: SBC % of Revenue | B42: =B41/B6 | C42: =C41/C6 | D42: =D41/D6 | E42: =E41/E6 | F42: =F41/F6 | G42: =G41/G6 | H42: =H41/H6 | I42: =I41/I6 | ... K42: =K41/K6
A43: Intangible Amortization | B43: 30 | C43: 32 | D43: 55 | E43: 70 | F43: 65 | G43: 55 | H43: =Assumptions!H19 | I43: =Assumptions!I19 | J43: =Assumptions!J19 | K43: =Assumptions!K19
A44: Restructuring Charges | B44: 0 | C44: 0 | D44: 0 | E44: 155 | F44: 80 | G44: 35 | H44: =Assumptions!H20 | I44: =Assumptions!I20 | J44: =Assumptions!J20 | K44: =Assumptions!K20

Sheet GAAP Reconciliation
A1: Snap Inc. (SNAP) - Non-GAAP to GAAP Reconciliation ($M)
B3: 2019 | C3: 2020 | D3: 2021 | E3: 2022 | F3: 2023 | G3: 2024 | H3: 2025E | I3: 2026E | J3: 2027E | K3: 2028E
B4: Historical | C4: Historical | D4: Historical | E4: Historical | F4: Historical | G4: Historical | H4: Forecast | I4: Forecast | J4: Forecast | K4: Forecast
A6: NON-GAAP OI -> GAAP OI BRIDGE
A7: Non-GAAP Operating Income | B7: ='Non-GAAP P&L'!B23 | C7: ='Non-GAAP P&L'!C23 | D7: ='Non-GAAP P&L'!D23 | E7: ='Non-GAAP P&L'!E23 | F7: ='Non-GAAP P&L'!F23 | G7: ='Non-GAAP P&L'!G23 | H7: ='Non-GAAP P&L'!H23 | I7: ='Non-GAAP P&L'!I23 | ... K7: ='Non-GAAP P&L'!K23
A8: (-) Stock-Based Compensation | B8: =-'Non-GAAP P&L'!B41 | C8: =-'Non-GAAP P&L'!C41 | D8: =-'Non-GAAP P&L'!D41 | E8: =-'Non-GAAP P&L'!E41 | F8: =-'Non-GAAP P&L'!F41 | G8: =-'Non-GAAP P&L'!G41 | H8: =-'Non-GAAP P&L'!H41 | I8: =-'Non-GAAP P&L'!I41 | ... K8: =-'Non-GAAP P&L'!K41
A9: (-) Intangible Amortization | B9: =-'Non-GAAP P&L'!B43 | C9: =-'Non-GAAP P&L'!C43 | D9: =-'Non-GAAP P&L'!D43 | E9: =-'Non-GAAP P&L'!E43 | F9: =-'Non-GAAP P&L'!F43 | G9: =-'Non-GAAP P&L'!G43 | H9: =-'Non-GAAP P&L'!H43 | I9: =-'Non-GAAP P&L'!I43 | ... K9: =-'Non-GAAP P&L'!K43
A10: (-) Restructuring Charges | B10: =-'Non-GAAP P&L'!B44 | C10: =-'Non-GAAP P&L'!C44 | D10: =-'Non-GAAP P&L'!D44 | E10: =-'Non-GAAP P&L'!E44 | F10: =-'Non-GAAP P&L'!F44 | G10: =-'Non-GAAP P&L'!G44 | H10: =-'Non-GAAP P&L'!H44 | I10: =-'Non-GAAP P&L'!I44 | ... K10: =-'Non-GAAP P&L'!K44
A11: GAAP Operating Income (Loss) | B11: =B7+B8+B9+B10 | C11: =C7+C8+C9+C10 | D11: =D7+D8+D9+D10 | E11: =E7+E8+E9+E10 | F11: =F7+F8+F9+F10 | G11: =G7+G8+G9+G10 | H11: =H7+H8+H9+H10 | I11: =I7+I8+I9+I10 | ... K11: =K7+K8+K9+K10
A12: GAAP Operating Margin | B12: =B11/'Non-GAAP P&L'!B6 | C12: =C11/'Non-GAAP P&L'!C6 | D12: =D11/'Non-GAAP P&L'!D6 | E12: =E11/'Non-GAAP P&L'!E6 | F12: =F11/'Non-GAAP P&L'!F6 | G12: =G11/'Non-GAAP P&L'!G6 | H12: =H11/'Non-GAAP P&L'!H6 | I12: =I11/'Non-GAAP P&L'!I6 | ... K12: =K11/'Non-GAAP P&L'!K6
A14: NON-GAAP NI -> GAAP NI BRIDGE
A15: Non-GAAP Net Income | B15: ='Non-GAAP P&L'!B35 | C15: ='Non-GAAP P&L'!C35 | D15: ='Non-GAAP P&L'!D35 | E15: ='Non-GAAP P&L'!E35 | F15: ='Non-GAAP P&L'!F35 | G15: ='Non-GAAP P&L'!G35 | H15: ='Non-GAAP P&L'!H35 | I15: ='Non-GAAP P&L'!I35 | ... K15: ='Non-GAAP P&L'!K35
A16: (-) Stock-Based Compensation | B16: =-'Non-GAAP P&L'!B41 | C16: =-'Non-GAAP P&L'!C41 | D16: =-'Non-GAAP P&L'!D41 | E16: =-'Non-GAAP P&L'!E41 | F16: =-'Non-GAAP P&L'!F41 | G16: =-'Non-GAAP P&L'!G41 | H16: =-'Non-GAAP P&L'!H41 | I16: =-'Non-GAAP P&L'!I41 | ... K16: =-'Non-GAAP P&L'!K41
A17: (-) Intangible Amortization | B17: =-'Non-GAAP P&L'!B43 | C17: =-'Non-GAAP P&L'!C43 | D17: =-'Non-GAAP P&L'!D43 | E17: =-'Non-GAAP P&L'!E43 | F17: =-'Non-GAAP P&L'!F43 | G17: =-'Non-GAAP P&L'!G43 | H17: =-'Non-GAAP P&L'!H43 | I17: =-'Non-GAAP P&L'!I43 | ... K17: =-'Non-GAAP P&L'!K43
A18: (-) Restructuring Charges | B18: =-'Non-GAAP P&L'!B44 | C18: =-'Non-GAAP P&L'!C44 | D18: =-'Non-GAAP P&L'!D44 | E18: =-'Non-GAAP P&L'!E44 | F18: =-'Non-GAAP P&L'!F44 | G18: =-'Non-GAAP P&L'!G44 | H18: =-'Non-GAAP P&L'!H44 | I18: =-'Non-GAAP P&L'!I44 | ... K18: =-'Non-GAAP P&L'!K44
A19: (+) Tax Effect of Adjustments | B19: ='Non-GAAP P&L'!B32-B43 | C19: ='Non-GAAP P&L'!C32-C43 | D19: ='Non-GAAP P&L'!D32-D43 | E19: ='Non-GAAP P&L'!E32-E43 | F19: ='Non-GAAP P&L'!F32-F43 | G19: ='Non-GAAP P&L'!G32-G43 | H19: ='Non-GAAP P&L'!H32-H43 | I19: ='Non-GAAP P&L'!I32-I43 | ... K19: ='Non-GAAP P&L'!K32-K43
A20: GAAP Net Income (Loss) | B20: =B15+B16+B17+B18+B19 | C20: =C15+C16+C17+C18+C19 | D20: =D15+D16+D17+D18+D19 | E20: =E15+E16+E17+E18+E19 | F20: =F15+F16+F17+F18+F19 | G20: =G15+G16+G17+G18+G19 | H20: =H15+H16+H17+H18+H19 | I20: =I15+I16+I17+I18+I19 | ... K20: =K15+K16+K17+K18+K19
A21: GAAP Diluted EPS | B21: =ROUND(B20/'Non-GAAP P&L'!B37,2) | C21: =ROUND(C20/'Non-GAAP P&L'!C37,2) | D21: =ROUND(D20/'Non-GAAP P&L'!D37,2) | E21: =ROUND(E20/'Non-GAAP P&L'!E37,2) | F21: =ROUND(F20/'Non-GAAP P&L'!F37,2) | G21: =ROUND(G20/'Non-GAAP P&L'!G37,2) | H21: =ROUND(H20/'Non-GAAP P&L'!H37,2) | I21: =ROUND(I20/'Non-GAAP P&L'!I37,2) | ... K21: =ROUND(K20/'Non-GAAP P&L'!K37,2)
A24: FULL GAAP INCOME STATEMENT
A25: Revenue | B25: ='Non-GAAP P&L'!B6 | C25: ='Non-GAAP P&L'!C6 | D25: ='Non-GAAP P&L'!D6 | E25: ='Non-GAAP P&L'!E6 | F25: ='Non-GAAP P&L'!F6 | G25: ='Non-GAAP P&L'!G6 | H25: ='Non-GAAP P&L'!H6 | I25: ='Non-GAAP P&L'!I6 | ... K25: ='Non-GAAP P&L'!K6
A26: GAAP Cost of Revenue | B26: 880 | C26: 1128 | D26: 1763 | E26: 2158 | F26: 2190 | G26: 2461 | H26: ='Non-GAAP P&L'!H9+ROUND('Non-GAAP P&L'!H41*Assumptions!H18,0)+ROUND('Non-GAAP P&L'!H43*0.4,0) | I26: ='Non-GAAP P&L'!I9+ROUND('Non-GAAP P&L'!I41*Assumptions!I18,0)+ROUND('Non-GAAP P&L'!I43*0.4,0) | J26: ='Non-GAAP P&L'!J9+ROUND('Non-GAAP P&L'!J41*Assumptions!J18,0)+ROUND('Non-GAAP P&L'!J43*0.4,0) | K26: ='Non-GAAP P&L'!K9+ROUND('Non-GAAP P&L'!K41*Assumptions!K18,0)+ROUND('Non-GAAP P&L'!K43*0.4,0)
A27: GAAP Gross Profit | B27: =B25-B26 | C27: =C25-C26 | D27: =D25-D26 | E27: =E25-E26 | F27: =F25-F26 | G27: =G25-G26 | H27: =H25-H26 | I27: =I25-I26 | ... K27: =K25-K26
A28: GAAP Gross Margin | B28: =B27/B25 | C28: =C27/C25 | D28: =D27/D25 | E28: =E27/E25 | F28: =F27/F25 | G28: =G27/G25 | H28: =H27/H25 | I28: =I27/I25 | ... K28: =K27/K25
A30: GAAP R&D | B30: 988 | C30: 1235 | D30: 1535 | E30: 2017 | F30: 1847 | G30: 1802 | H30: ='Non-GAAP P&L'!H14+ROUND('Non-GAAP P&L'!H41*0.50,0)+ROUND('Non-GAAP P&L'!H43*0.40,0) | I30: ='Non-GAAP P&L'!I14+ROUND('Non-GAAP P&L'!I41*0.50,0)+ROUND('Non-GAAP P&L'!I43*0.40,0) | J30: ='Non-GAAP P&L'!J14+ROUND('Non-GAAP P&L'!J41*0.50,0)+ROUND('Non-GAAP P&L'!J43*0.40,0) | K30: ='Non-GAAP P&L'!K14+ROUND('Non-GAAP P&L'!K41*0.50,0)+ROUND('Non-GAAP P&L'!K43*0.40,0)
A31: GAAP S&M | B31: 654 | C31: 794 | D31: 1168 | E31: 1424 | F31: 1284 | G31: 1281 | H31: ='Non-GAAP P&L'!H16+ROUND('Non-GAAP P&L'!H41*0.25,0)+ROUND('Non-GAAP P&L'!H43*0.10,0) | I31: ='Non-GAAP P&L'!I16+ROUND('Non-GAAP P&L'!I41*0.25,0)+ROUND('Non-GAAP P&L'!I43*0.10,0) | J31: ='Non-GAAP P&L'!J16+ROUND('Non-GAAP P&L'!J41*0.25,0)+ROUND('Non-GAAP P&L'!J43*0.10,0) | K31: ='Non-GAAP P&L'!K16+ROUND('Non-GAAP P&L'!K41*0.25,0)+ROUND('Non-GAAP P&L'!K43*0.10,0)
A32: GAAP G&A | B32: 363 | C32: 421 | D32: 507 | E32: 641 | F32: 614 | G32: 582 | H32: ='Non-GAAP P&L'!H18+ROUND('Non-GAAP P&L'!H41*0.20,0)+ROUND('Non-GAAP P&L'!H43*0.10,0)+'Non-GAAP P&L'!H44 | I32: ='Non-GAAP P&L'!I18+ROUND('Non-GAAP P&L'!I41*0.20,0)+ROUND('Non-GAAP P&L'!I43*0.10,0)+'Non-GAAP P&L'!I44 | J32: ='Non-GAAP P&L'!J18+ROUND('Non-GAAP P&L'!J41*0.20,0)+ROUND('Non-GAAP P&L'!J43*0.10,0)+'Non-GAAP P&L'!J44 | K32: ='Non-GAAP P&L'!K18+ROUND('Non-GAAP P&L'!K41*0.20,0)+ROUND('Non-GAAP P&L'!K43*0.10,0)+'Non-GAAP P&L'!K44
A33: GAAP Total OpEx | B33: =B30+B31+B32 | C33: =C30+C31+C32 | D33: =D30+D31+D32 | E33: =E30+E31+E32 | F33: =F30+F31+F32 | G33: =G30+G31+G32 | H33: =H30+H31+H32 | I33: =I30+I31+I32 | ... K33: =K30+K31+K32
A34: GAAP Operating Income (Loss) | B34: =B27-B33 | C34: =C27-C33 | D34: =D27-D33 | E34: =E27-E33 | F34: =F27-F33 | G34: =G27-G33 | H34: =H27-H33 | I34: =I27-I33 | ... K34: =K27-K33
A35: GAAP Operating Margin | B35: =B34/B25 | C35: =C34/C25 | D35: =D34/D25 | E35: =E34/E25 | F35: =F34/F25 | G35: =G34/G25 | H35: =H34/H25 | I35: =I34/I25 | ... K35: =K34/K25
A37: Total D&A (PP&E + Intangible) | B37: ='Non-GAAP P&L'!B26+'Non-GAAP P&L'!B43 | C37: ='Non-GAAP P&L'!C26+'Non-GAAP P&L'!C43 | D37: ='Non-GAAP P&L'!D26+'Non-GAAP P&L'!D43 | E37: ='Non-GAAP P&L'!E26+'Non-GAAP P&L'!E43 | F37: ='Non-GAAP P&L'!F26+'Non-GAAP P&L'!F43 | G37: ='Non-GAAP P&L'!G26+'Non-GAAP P&L'!G43 | H37: ='Non-GAAP P&L'!H26+'Non-GAAP P&L'!H43 | I37: ='Non-GAAP P&L'!I26+'Non-GAAP P&L'!I43 | ... K37: ='Non-GAAP P&L'!K26+'Non-GAAP P&L'!K43
A38: GAAP EBITDA | B38: =B34+B37 | C38: =C34+C37 | D38: =D34+D37 | E38: =E34+E37 | F38: =F34+F37 | G38: =G34+G37 | H38: =H34+H37 | I38: =I34+I37 | ... K38: =K34+K37
A39: GAAP EBITDA Margin | B39: =B38/B25 | C39: =C38/C25 | D39: =D38/D25 | E39: =E38/E25 | F39: =F38/F25 | G39: =G38/G25 | H39: =H38/H25 | I39: =I38/I25 | ... K39: =K38/K25
A41: Interest & Other | B41: ='Non-GAAP P&L'!B30 | C41: ='Non-GAAP P&L'!C30 | D41: ='Non-GAAP P&L'!D30 | E41: ='Non-GAAP P&L'!E30 | F41: ='Non-GAAP P&L'!F30 | G41: ='Non-GAAP P&L'!G30 | H41: ='Non-GAAP P&L'!H30 | I41: ='Non-GAAP P&L'!I30 | ... K41: ='Non-GAAP P&L'!K30
A42: GAAP Pre-Tax Income (Loss) | B42: =B34+B41 | C42: =C34+C41 | D42: =D34+D41 | E42: =E34+E41 | F42: =F34+F41 | G42: =G34+G41 | H42: =H34+H41 | I42: =I34+I41 | ... K42: =K34+K41
A43: GAAP Tax Provision | B43: 5 | C43: 7 | D43: 14 | E43: 20 | F43: 25 | G43: 28 | H43: =IF(H42>0,ROUND(H42*Assumptions!H23,0),0) | I43: =IF(I42>0,ROUND(I42*Assumptions!I23,0),0) | J43: =IF(J42>0,ROUND(J42*Assumptions!J23,0),0) | K43: =IF(K42>0,ROUND(K42*Assumptions!K23,0),0)
A45: GAAP Net Income (Loss) | B45: =B42-B43 | C45: =C42-C43 | D45: =D42-D43 | E45: =E42-E43 | F45: =F42-F43 | G45: =G42-G43 | H45: =H42-H43 | I45: =I42-I43 | ... K45: =K42-K43
A46: GAAP Diluted EPS | B46: =ROUND(B45/'Non-GAAP P&L'!B37,2) | C46: =ROUND(C45/'Non-GAAP P&L'!C37,2) | D46: =ROUND(D45/'Non-GAAP P&L'!D37,2) | E46: =ROUND(E45/'Non-GAAP P&L'!E37,2) | F46: =ROUND(F45/'Non-GAAP P&L'!F37,2) | G46: =ROUND(G45/'Non-GAAP P&L'!G37,2) | H46: =ROUND(H45/'Non-GAAP P&L'!H37,2) | I46: =ROUND(I45/'Non-GAAP P&L'!I37,2) | ... K46: =ROUND(K45/'Non-GAAP P&L'!K37,2)
A49: ADJUSTED EBITDA -> FREE CASH FLOW BRIDGE
A50: Adjusted EBITDA | B50: ='Non-GAAP P&L'!B27 | C50: ='Non-GAAP P&L'!C27 | D50: ='Non-GAAP P&L'!D27 | E50: ='Non-GAAP P&L'!E27 | F50: ='Non-GAAP P&L'!F27 | G50: ='Non-GAAP P&L'!G27 | H50: ='Non-GAAP P&L'!H27 | I50: ='Non-GAAP P&L'!I27 | ... K50: ='Non-GAAP P&L'!K27
A51: (-) PP&E Depreciation | B51: =-'Non-GAAP P&L'!B26 | C51: =-'Non-GAAP P&L'!C26 | D51: =-'Non-GAAP P&L'!D26 | E51: =-'Non-GAAP P&L'!E26 | F51: =-'Non-GAAP P&L'!F26 | G51: =-'Non-GAAP P&L'!G26 | H51: =-'Non-GAAP P&L'!H26 | I51: =-'Non-GAAP P&L'!I26 | ... K51: =-'Non-GAAP P&L'!K26
...

Sheet Balance Sheet
A1: Snap Inc. (SNAP) - Balance Sheet ($M, GAAP)
B3: 2019 | C3: 2020 | D3: 2021 | E3: 2022 | F3: 2023 | G3: 2024 | H3: 2025E | I3: 2026E | J3: 2027E | K3: 2028E
B4: Historical | C4: Historical | D4: Historical | E4: Historical | F4: Historical | G4: Historical | H4: Forecast | I4: Forecast | J4: Forecast | K4: Forecast
A6: ASSETS
A7: Cash & Equivalents | B7: 2024 | C7: 2768 | D7: 3506 | E7: 3938 | F7: 3374 | G7: 3205 | H7: ='Cash Flow & FCF Bridge'!H24 | I7: ='Cash Flow & FCF Bridge'!I24 | J7: ='Cash Flow & FCF Bridge'!J24 | K7: ='Cash Flow & FCF Bridge'!K24
A8: Accounts Receivable | B8: 548 | C8: 737 | D8: 1068 | E8: 995 | F8: 1109 | G8: 1230 | H8: =ROUND('Revenue Build'!H15*Assumptions!H43/365,0) | I8: =ROUND('Revenue Build'!I15*Assumptions!I43/365,0) | J8: =ROUND('Revenue Build'!J15*Assumptions!J43/365,0) | K8: =ROUND('Revenue Build'!K15*Assumptions!K43/365,0)
A9: Other Current Assets | B9: 174 | C9: 200 | D9: 201 | E9: 182 | F9: 217 | G9: 215 | H9: 200 | I9: 200 | J9: 200 | K9: 200
A10: Total Current Assets | B10: =B7+B8+B9 | C10: =C7+C8+C9 | D10: =D7+D8+D9 | E10: =E7+E8+E9 | F10: =F7+F8+F9 | G10: =G7+G8+G9 | H10: =H7+H8+H9 | I10: =I7+I8+I9 | ... K10: =K7+K8+K9
A12: PP&E | B12: 204 | C12: 258 | D12: 339 | E12: 452 | F12: 430 | G12: 400 | H12: =Assumptions!H36 | I12: =Assumptions!I36 | J12: =Assumptions!J36 | K12: =Assumptions!K36
A13: Intangibles | B13: 181 | C13: 182 | D13: 411 | E13: 440 | F13: 395 | G13: 360 | H13: =Assumptions!H37 | I13: =Assumptions!I37 | J13: =Assumptions!J37 | K13: =Assumptions!K37
A14: ROU Assets | B14: 250 | C14: 280 | D14: 310 | E14: 350 | F14: 360 | G14: 370 | H14: =Assumptions!H38 | I14: =Assumptions!I38 | J14: =Assumptions!J38 | K14: =Assumptions!K38
A15: Other LT Assets | B15: 150 | C15: 180 | D15: 250 | E15: 310 | F15: 330 | G15: 350 | H15: =Assumptions!H39 | I15: =Assumptions!I39 | J15: =Assumptions!J39 | K15: =Assumptions!K39
A16: Total Assets | B16: =B10+B12+B13+B14+B15 | C16: =C10+C12+C13+C14+C15 | D16: =D10+D12+D13+D14+D15 | E16: =E10+E12+E13+E14+E15 | F16: =F10+F12+F13+F14+F15 | G16: =G10+G12+G13+G14+G15 | H16: =H10+H12+H13+H14+H15 | I16: =I10+I12+I13+I14+I15 | ... K16: =K10+K12+K13+K14+K15
A18: LIABILITIES
A19: Accounts Payable | B19: 120 | C19: 155 | D19: 245 | E19: 265 | F19: 280 | G19: 295 | H19: =ROUND('GAAP Reconciliation'!H26*Assumptions!H44/365,0) | I19: =ROUND('GAAP Reconciliation'!I26*Assumptions!I44/365,0) | J19: =ROUND('GAAP Reconciliation'!J26*Assumptions!J44/365,0) | K19: =ROUND('GAAP Reconciliation'!K26*Assumptions!K44/365,0)
A20: Accrued Liabilities | B20: 350 | C20: 430 | D20: 620 | E20: 705 | F20: 680 | G20: 720 | H20: =ROUND('Revenue Build'!H15*Assumptions!H45,0) | I20: =ROUND('Revenue Build'!I15*Assumptions!I45,0) | J20: =ROUND('Revenue Build'!J15*Assumptions!J45,0) | K20: =ROUND('Revenue Build'!K15*Assumptions!K45,0)
A21: Deferred Revenue | B21: 25 | C21: 30 | D21: 35 | E21: 40 | F21: 42 | G21: 45 | H21: =ROUND('Revenue Build'!H15*0.007,0) | I21: =ROUND('Revenue Build'!I15*0.007,0) | J21: =ROUND('Revenue Build'!J15*0.007,0) | K21: =ROUND('Revenue Build'!K15*0.007,0)
A22: Other Current Liab | B22: 0 | C22: 0 | D22: 0 | E22: 0 | F22: 0 | G22: 0 | H22: 100 | I22: 100 | J22: 100 | K22: 100
A23: Total Current Liabilities | B23: =B19+B20+B21+B22 | C23: =C19+C20+C21+C22 | D23: =D19+D20+D21+D22 | E23: =E19+E20+E21+E22 | F23: =F19+F20+F21+F22 | G23: =G19+G20+G21+G22 | H23: =H19+H20+H21+H22 | I23: =I19+I20+I21+I22 | ... K23: =K19+K20+K21+K22
A25: Long-Term Debt | B25: 1485 | C25: 2190 | D25: 3745 | E25: 3745 | F25: 3745 | G25: 3745 | H25: =Assumptions!H40 | I25: =Assumptions!I40 | J25: =Assumptions!J40 | K25: =Assumptions!K40
A26: Lease Liab | B26: 220 | C26: 260 | D26: 300 | E26: 340 | F26: 350 | G26: 360 | H26: =Assumptions!H41 | I26: =Assumptions!I41 | J26: =Assumptions!J41 | K26: =Assumptions!K41
A27: Other LT Liab | B27: 80 | C27: 95 | D27: 120 | E27: 140 | F27: 150 | G27: 155 | H27: =Assumptions!H42 | I27: =Assumptions!I42 | J27: =Assumptions!J42 | K27: =Assumptions!K42
A28: Total Liabilities | B28: =B23+B25+B26+B27 | C28: =C23+C25+C26+C27 | D28: =D23+D25+D26+D27 | E28: =E23+E25+E26+E27 | F28: =F23+F25+F26+F27 | G28: =G23+G25+G26+G27 | H28: =H23+H25+H26+H27 | I28: =I23+I25+I26+I27 | ... K28: =K23+K25+K26+K27
A30: STOCKHOLDERS' EQUITY
A31: Total Equity | B31: =B16-B28 | C31: =C16-C28 | D31: =D16-D28 | E31: =E16-E28 | F31: =F16-F28 | G31: =G16-G28 | H31: =H16-H28 | I31: =I16-I28 | ... K31: =K16-K28
A32: Total L&E | B32: =B28+B31 | C32: =C28+C31 | D32: =D28+D31 | E32: =E28+E31 | F32: =F28+F31 | G32: =G28+G31 | H32: =H28+H31 | I32: =I28+I31 | ... K32: =K28+K31
A34: Balance Check (=0) | B34: =B16-B32 | C34: =C16-C32 | D34: =D16-D32 | E34: =E16-E32 | F34: =F16-F32 | G34: =G16-G32 | H34: =H16-H32 | I34: =I16-I32 | ... K34: =K16-K32

Sheet Cash Flow & FCF Bridge
A1: Snap Inc. (SNAP) - Cash Flow Statement ($M)
B3: 2019 | C3: 2020 | D3: 2021 | E3: 2022 | F3: 2023 | G3: 2024 | H3: 2025E | I3: 2026E | J3: 2027E | K3: 2028E
B4: Historical | C4: Historical | D4: Historical | E4: Historical | F4: Historical | G4: Historical | H4: Forecast | I4: Forecast | J4: Forecast | K4: Forecast
A6: CASH FROM OPERATIONS
A7: GAAP Net Income (Loss) | B7: ='GAAP Reconciliation'!B45 | C7: ='GAAP Reconciliation'!C45 | D7: ='GAAP Reconciliation'!D45 | E7: ='GAAP Reconciliation'!E45 | F7: ='GAAP Reconciliation'!F45 | G7: ='GAAP Reconciliation'!G45 | H7: ='GAAP Reconciliation'!H45 | I7: ='GAAP Reconciliation'!I45 | ... K7: ='GAAP Reconciliation'!K45
A8: (+) Total D&A | B8: ='Non-GAAP P&L'!B26+'Non-GAAP P&L'!B43 | C8: ='Non-GAAP P&L'!C26+'Non-GAAP P&L'!C43 | D8: ='Non-GAAP P&L'!D26+'Non-GAAP P&L'!D43 | E8: ='Non-GAAP P&L'!E26+'Non-GAAP P&L'!E43 | F8: ='Non-GAAP P&L'!F26+'Non-GAAP P&L'!F43 | G8: ='Non-GAAP P&L'!G26+'Non-GAAP P&L'!G43 | H8: ='Non-GAAP P&L'!H26+'Non-GAAP P&L'!H43 | I8: ='Non-GAAP P&L'!I26+'Non-GAAP P&L'!I43 | ... K8: ='Non-GAAP P&L'!K26+'Non-GAAP P&L'!K43
A9: (+) Stock-Based Compensation | B9: ='Non-GAAP P&L'!B41 | C9: ='Non-GAAP P&L'!C41 | D9: ='Non-GAAP P&L'!D41 | E9: ='Non-GAAP P&L'!E41 | F9: ='Non-GAAP P&L'!F41 | G9: ='Non-GAAP P&L'!G41 | H9: ='Non-GAAP P&L'!H41 | I9: ='Non-GAAP P&L'!I41 | ... K9: ='Non-GAAP P&L'!K41
A10: (+/-) Working Capital Changes | B10: -80 | C10: -45 | D10: -120 | E10: 50 | F10: 30 | G10: 15 | H10: =Assumptions!H33 | I10: =Assumptions!I33 | J10: =Assumptions!J33 | K10: =Assumptions!K33
A11: (+/-) Other Non-Cash Adj. | B11: 583 | C11: 500 | D11: 474 | E11: 206 | F11: -77 | G11: -377 | H11: 0 | I11: 0 | J11: 0 | K11: 0
A12: Cash from Operations (CFO) | B12: =SUM(B7:B11) | C12: =SUM(C7:C11) | D12: =SUM(D7:D11) | E12: =SUM(E7:E11) | F12: =SUM(F7:F11) | G12: =SUM(G7:G11) | H12: =SUM(H7:H11) | I12: =SUM(I7:I11) | ... K12: =SUM(K7:K11)
A14: CASH FROM INVESTING
A15: Capital Expenditures | B15: -51 | C15: -59 | D15: -85 | E15: -115 | F15: -93 | G15: -90 | H15: =-Assumptions!H31 | I15: =-Assumptions!I31 | J15: =-Assumptions!J31 | K15: =-Assumptions!K31
A16: Other Investing | B16: -149 | C16: -441 | D16: -1115 | E16: -235 | F16: -27 | G16: -10 | H16: 0 | I16: 0 | J16: 0 | K16: 0
A17: Cash from Investing (CFI) | B17: =B15+B16 | C17: =C15+C16 | D17: =D15+D16 | E17: =E15+E16 | F17: =F15+F16 | G17: =G15+G16 | H17: =H15+H16 | I17: =I15+I16 | ... K17: =K15+K16
A19: CASH FROM FINANCING
A20: Cash from Financing (CFF) | B20: =Assumptions!B52 | C20: =Assumptions!C52 | D20: =Assumptions!D52 | E20: =Assumptions!E52 | F20: =Assumptions!F52 | G20: =Assumptions!G52 | H20: =Assumptions!H52 | I20: =Assumptions!I52 | ... K20: =Assumptions!K52
A22: Net Change in Cash | B22: =B12+B17+B20 | C22: =C12+C17+C20 | D22: =D12+D17+D20 | E22: =E12+E17+E20 | F22: =F12+F17+F20 | G22: =G12+G17+G20 | H22: =H12+H17+H20 | I22: =I12+I17+I20 | ... K22: =K12+K17+K20
A23: Beginning Cash | B23: 1365 | C23: 2024 | D23: 2768 | E23: 3506 | F23: 3938 | G23: 3374 | H23: =G24 | I23: =H24 | J23: =I24 | K23: =J24
A24: Ending Cash | B24: =B23+B22 | C24: =C23+C22 | D24: =D23+D22 | E24: =E23+E22 | F24: =F23+F22 | G24: =G23+G22 | H24: =H23+H22 | I24: =I23+I22 | ... K24: =K23+K22
A26: Free Cash Flow (CFO + CapEx) | B26: =B12+B15 | C26: =C12+C15 | D26: =D12+D15 | E26: =E12+E15 | F26: =F12+F15 | G26: =G12+G15 | H26: =H12+H15 | I26: =I12+I15 | ... K26: =K12+K15
A27: FCF Margin | B27: =B26/'Revenue Build'!B15 | C27: =C26/'Revenue Build'!C15 | D27: =D26/'Revenue Build'!D15 | E27: =E26/'Revenue Build'!E15 | F27: =F26/'Revenue Build'!F15 | G27: =G26/'Revenue Build'!G15 | H27: =H26/'Revenue Build'!H15 | I27: =I26/'Revenue Build'!I15 | ... K27: =K26/'Revenue Build'!K15

Sheet Quarterly Detail
A1: Snap Inc. (SNAP) - Non-GAAP Quarterly P&L ($M)
B3: Q1-23 | C3: Q2-23 | D3: Q3-23 | E3: Q4-23 | F3: Q1-24 | G3: Q2-24 | H3: Q3-24 | I3: Q4-24 | J3: Q1-25E | K3: Q2-25E | L3: Q3-25E | M3: Q4-25E | N3: Q1-26E | O3: Q2-26E | P3: Q3-26E | Q3: Q4-26E
B4: Historical | C4: Historical | D4: Historical | E4: Historical | F4: Historical | G4: Historical | H4: Historical | I4: Historical | J4: Forecast | K4: Forecast | L4: Forecast | M4: Forecast | N4: Forecast | O4: Forecast | P4: Forecast | Q4: Forecast
A6: DAU (M) | B6: 383 | C6: 397 | D6: 406 | E6: 414 | F6: 422 | G6: 432 | H6: 437 | I6: 443 | J6: =ROUND('Revenue Build'!G7+('Revenue Build'!H7-'Revenue Build'!G7)*1/4,0) | K6: =ROUND('Revenue Build'!G7+('Revenue Build'!H7-'Revenue Build'!G7)*2/4,0) | L6: =ROUND('Revenue Build'!G7+('Revenue Build'!H7-'Revenue Build'!G7)*3/4,0) | M6: =ROUND('Revenue Build'!G7+('Revenue Build'!H7-'Revenue Build'!G7)*4/4,0) | N6: =ROUND('Revenue Build'!H7+('Revenue Build'!I7-'Revenue Build'!H7)*1/4,0) | O6: =ROUND('Revenue Build'!H7+('Revenue Build'!I7-'Revenue Build'!H7)*2/4,0) | P6: =ROUND('Revenue Build'!H7+('Revenue Build'!I7-'Revenue Build'!H7)*3/4,0) | Q6: =ROUND('Revenue Build'!H7+('Revenue Build'!I7-'Revenue Build'!H7)*4/4,0)
A7: Revenue | B7: 989 | C7: 1068 | D7: 1189 | E7: 1361 | F7: 1195 | G7: 1237 | H7: 1373 | I7: 1556 | J7: =ROUND('Revenue Build'!H15*Assumptions!B56,0) | K7: =ROUND('Revenue Build'!H15*Assumptions!C56,0) | L7: =ROUND('Revenue Build'!H15*Assumptions!D56,0) | M7: =ROUND('Revenue Build'!H15*Assumptions!E56,0) | N7: =ROUND('Revenue Build'!I15*Assumptions!B56,0) | O7: =ROUND('Revenue Build'!I15*Assumptions!C56,0) | P7: =ROUND('Revenue Build'!I15*Assumptions!D56,0) | Q7: =ROUND('Revenue Build'!I15*Assumptions!E56,0)
A8: ARPU ($) | B8: =ROUND(B7/B6,2) | C8: =ROUND(C7/C6,2) | D8: =ROUND(D7/D6,2) | E8: =ROUND(E7/E6,2) | F8: =ROUND(F7/F6,2) | G8: =ROUND(G7/G6,2) | H8: =ROUND(H7/H6,2) | I8: =ROUND(I7/I6,2) | ... Q8: =ROUND(Q7/Q6,2)
A10: Non-GAAP COGS | B10: 460 | C10: 480 | D10: 515 | E10: 610 | F10: 515 | G10: 535 | H10: 588 | I10: 697 | J10: =ROUND(J7*(1-Assumptions!H11),0) | K10: =ROUND(K7*(1-Assumptions!H11),0) | L10: =ROUND(L7*(1-Assumptions!H11),0) | M10: =ROUND(M7*(1-Assumptions!H11),0) | N10: =ROUND(N7*(1-Assumptions!I11),0) | O10: =ROUND(O7*(1-Assumptions!I11),0) | P10: =ROUND(P7*(1-Assumptions!I11),0) | Q10: =ROUND(Q7*(1-Assumptions!I11),0)
A11: Non-GAAP Gross Profit | B11: =B7-B10 | C11: =C7-C10 | D11: =D7-D10 | E11: =E7-E10 | F11: =F7-F10 | G11: =G7-G10 | H11: =H7-H10 | I11: =I7-I10 | ... Q11: =Q7-Q10
A12: Non-GAAP GM | B12: =B11/B7 | C12: =C11/C7 | D12: =D11/D7 | E12: =E11/E7 | F12: =F11/F7 | G12: =G11/G7 | H12: =H11/H7 | I12: =I11/I7 | ... Q12: =Q11/Q7
A14: Non-GAAP R&D | B14: 260 | C14: 252 | D14: 248 | E14: 246 | F14: 248 | G14: 244 | H14: 244 | I14: 245 | J14: =ROUND(J7*Assumptions!H12,0) | K14: =ROUND(K7*Assumptions!H12,0) | L14: =ROUND(L7*Assumptions!H12,0) | M14: =ROUND(M7*Assumptions!H12,0) | N14: =ROUND(N7*Assumptions!I12,0) | O14: =ROUND(O7*Assumptions!I12,0) | P14: =ROUND(P7*Assumptions!I12,0) | Q14: =ROUND(Q7*Assumptions!I12,0)
A15: Non-GAAP S&M | B15: 240 | C15: 232 | D15: 234 | E15: 231 | F15: 235 | G15: 232 | H15: 234 | I15: 234 | J15: =ROUND(J7*Assumptions!H13,0) | K15: =ROUND(K7*Assumptions!H13,0) | L15: =ROUND(L7*Assumptions!H13,0) | M15: =ROUND(M7*Assumptions!H13,0) | N15: =ROUND(N7*Assumptions!I13,0) | O15: =ROUND(O7*Assumptions!I13,0) | P15: =ROUND(P7*Assumptions!I13,0) | Q15: =ROUND(Q7*Assumptions!I13,0)
A16: Non-GAAP G&A | B16: 58 | C16: 57 | D16: 55 | E16: 55 | F16: 53 | G16: 52 | H16: 52 | I16: 52 | J16: =ROUND(J7*Assumptions!H14,0) | K16: =ROUND(K7*Assumptions!H14,0) | L16: =ROUND(L7*Assumptions!H14,0) | M16: =ROUND(M7*Assumptions!H14,0) | N16: =ROUND(N7*Assumptions!I14,0) | O16: =ROUND(O7*Assumptions!I14,0) | P16: =ROUND(P7*Assumptions!I14,0) | Q16: =ROUND(Q7*Assumptions!I14,0)
A17: Non-GAAP Operating Income | B17: =B11-B14-B15-B16 | C17: =C11-C14-C15-C16 | D17: =D11-D14-D15-D16 | E17: =E11-E14-E15-E16 | F17: =F11-F14-F15-F16 | G17: =G11-G14-G15-G16 | H17: =H11-H14-H15-H16 | I17: =I11-I14-I15-I16 | ... Q17: =Q11-Q14-Q15-Q16
A18: Non-GAAP OI Margin | B18: =B17/B7 | C18: =C17/C7 | D18: =D17/D7 | E18: =E17/E7 | F18: =F17/F7 | G18: =G17/G7 | H18: =H17/H7 | I18: =I17/I7 | ... Q18: =Q17/Q7
A20: PP&E Depreciation | B20: 34 | C20: 34 | D20: 34 | E20: 33 | F20: 40 | G20: 40 | H20: 40 | I20: 40 | J20: =ROUND(Assumptions!H21/4,0) | K20: =ROUND(Assumptions!H21/4,0) | L20: =ROUND(Assumptions!H21/4,0) | M20: =ROUND(Assumptions!H21/4,0) | N20: =ROUND(Assumptions!I21/4,0) | O20: =ROUND(Assumptions!I21/4,0) | P20: =ROUND(Assumptions!I21/4,0) | Q20: =ROUND(Assumptions!I21/4,0)
A21: Adjusted EBITDA | B21: =B17+B20 | C21: =C17+C20 | D21: =D17+D20 | E21: =E17+E20 | F21: =F17+F20 | G21: =G17+G20 | H21: =H17+H20 | I21: =I17+I20 | ... Q21: =Q17+Q20
A23: SBC | B23: 355 | C23: 345 | D23: 340 | E23: 336 | F23: 330 | G23: 325 | H23: 322 | I23: 319 | J23: =ROUND(J7*Assumptions!H17,0) | K23: =ROUND(K7*Assumptions!H17,0) | L23: =ROUND(L7*Assumptions!H17,0) | M23: =ROUND(M7*Assumptions!H17,0) | N23: =ROUND(N7*Assumptions!I17,0) | O23: =ROUND(O7*Assumptions!I17,0) | P23: =ROUND(P7*Assumptions!I17,0) | Q23: =ROUND(Q7*Assumptions!I17,0)
A24: Intangible Amort | B24: 16 | C24: 16 | D24: 17 | E24: 16 | F24: 14 | G24: 14 | H24: 14 | I24: 13 | J24: =ROUND(Assumptions!H19/4,0) | K24: =ROUND(Assumptions!H19/4,0) | L24: =ROUND(Assumptions!H19/4,0) | M24: =ROUND(Assumptions!H19/4,0) | N24: =ROUND(Assumptions!I19/4,0) | O24: =ROUND(Assumptions!I19/4,0) | P24: =ROUND(Assumptions!I19/4,0) | Q24: =ROUND(Assumptions!I19/4,0)
A25: Restructuring | B25: 22 | C25: 20 | D25: 20 | E25: 18 | F25: 10 | G25: 9 | H25: 8 | I25: 8 | J25: =ROUND(Assumptions!H20/4,0) | K25: =ROUND(Assumptions!H20/4,0) | L25: =ROUND(Assumptions!H20/4,0) | M25: =ROUND(Assumptions!H20/4,0) | N25: =ROUND(Assumptions!I20/4,0) | O25: =ROUND(Assumptions!I20/4,0) | P25: =ROUND(Assumptions!I20/4,0) | Q25: =ROUND(Assumptions!I20/4,0)
A26: GAAP Operating Income | B26: =B17-B23-B24-B25 | C26: =C17-C23-C24-C25 | D26: =D17-D23-D24-D25 | E26: =E17-E23-E24-E25 | F26: =F17-F23-F24-F25 | G26: =G17-G23-G24-G25 | H26: =H17-H23-H24-H25 | I26: =I17-I23-I24-I25 | ... Q26: =Q17-Q23-Q24-Q25
A28: Interest & Other | B28: -25 | C28: -25 | D28: -25 | E28: -25 | F28: -24 | G28: -24 | H28: -24 | I28: -23 | J28: =ROUND(-Assumptions!H32/4,0) | K28: =ROUND(-Assumptions!H32/4,0) | L28: =ROUND(-Assumptions!H32/4,0) | M28: =ROUND(-Assumptions!H32/4,0) | N28: =ROUND(-Assumptions!I32/4,0) | O28: =ROUND(-Assumptions!I32/4,0) | P28: =ROUND(-Assumptions!I32/4,0) | Q28: =ROUND(-Assumptions!I32/4,0)
A29: Non-GAAP Pre-Tax | B29: =B17+B28 | C29: =C17+C28 | D29: =D17+D28 | E29: =E17+E28 | F29: =F17+F28 | G29: =G17+G28 | H29: =H17+H28 | I29: =I17+I28 | ... Q29: =Q17+Q28
A30: Non-GAAP Tax | B30: =IF(B29>0,ROUND(B29*0.08,0),0) | C30: =IF(C29>0,ROUND(C29*0.08,0),0) | D30: =IF(D29>0,ROUND(D29*0.08,0),0) | E30: =IF(E29>0,ROUND(E29*0.08,0),0) | F30: =IF(F29>0,ROUND(F29*0.08,0),0) | G30: =IF(G29>0,ROUND(G29*0.08,0),0) | H30: =IF(H29>0,ROUND(H29*0.08,0),0) | I30: =IF(I29>0,ROUND(I29*0.08,0),0) | J30: =IF(J29>0,ROUND(J29*Assumptions!H22,0),0) | K30: =IF(K29>0,ROUND(K29*Assumptions!H22,0),0) | L30: =IF(L29>0,ROUND(L29*Assumptions!H22,0),0) | M30: =IF(M29>0,ROUND(M29*Assumptions!H22,0),0) | N30: =IF(N29>0,ROUND(N29*Assumptions!I22,0),0) | O30: =IF(O29>0,ROUND(O29*Assumptions!I22,0),0) | P30: =IF(P29>0,ROUND(P29*Assumptions!I22,0),0) | Q30: =IF(Q29>0,ROUND(Q29*Assumptions!I22,0),0)
A31: Non-GAAP Net Income | B31: =B29-B30 | C31: =C29-C30 | D31: =D29-D30 | E31: =E29-E30 | F31: =F29-F30 | G31: =G29-G30 | H31: =H29-H30 | I31: =I29-I30 | ... Q31: =Q29-Q30
A33: CapEx | B33: -22 | C33: -24 | D33: -23 | E33: -24 | F33: -22 | G33: -23 | H33: -22 | I33: -23 | J33: =ROUND(-Assumptions!H31/4,0) | K33: =ROUND(-Assumptions!H31/4,0) | L33: =ROUND(-Assumptions!H31/4,0) | M33: =ROUND(-Assumptions!H31/4,0) | N33: =ROUND(-Assumptions!I31/4,0) | O33: =ROUND(-Assumptions!I31/4,0) | P33: =ROUND(-Assumptions!I31/4,0) | Q33: =ROUND(-Assumptions!I31/4,0)

Sheet Share Count & Dilution
A1: Snap Inc. (SNAP) - Share Count & Dilution
B3: 2019 | C3: 2020 | D3: 2021 | E3: 2022 | F3: 2023 | G3: 2024 | H3: 2025E | I3: 2026E | J3: 2027E | K3: 2028E
B4: Historical | C4: Historical | D4: Historical | E4: Historical | F4: Historical | G4: Historical | H4: Forecast | I4: Forecast | J4: Forecast | K4: Forecast
A5: Diluted Shares (M) | B5: =Assumptions!B48 | C5: =Assumptions!C48 | D5: =Assumptions!D48 | E5: =Assumptions!E48 | F5: =Assumptions!F48 | G5: =Assumptions!G48 | H5: =Assumptions!H48 | I5: =Assumptions!I48 | ... K5: =Assumptions!K48
A6: YoY Dilution | C6: =C5/B5-1 | D6: =D5/C5-1 | E6: =E5/D5-1 | F6: =F5/E5-1 | G6: =G5/F5-1 | H6: =H5/G5-1 | I6: =I5/H5-1 | J6: =J5/I5-1 | K6: =K5/J5-1
A7: SBC ($M) | B7: ='Non-GAAP P&L'!B41 | C7: ='Non-GAAP P&L'!C41 | D7: ='Non-GAAP P&L'!D41 | E7: ='Non-GAAP P&L'!E41 | F7: ='Non-GAAP P&L'!F41 | G7: ='Non-GAAP P&L'!G41 | H7: ='Non-GAAP P&L'!H41 | I7: ='Non-GAAP P&L'!I41 | ... K7: ='Non-GAAP P&L'!K41
A8: Non-GAAP EPS | B8: ='Non-GAAP P&L'!B38 | C8: ='Non-GAAP P&L'!C38 | D8: ='Non-GAAP P&L'!D38 | E8: ='Non-GAAP P&L'!E38 | F8: ='Non-GAAP P&L'!F38 | G8: ='Non-GAAP P&L'!G38 | H8: ='Non-GAAP P&L'!H38 | I8: ='Non-GAAP P&L'!I38 | ... K8: ='Non-GAAP P&L'!K38
A9: GAAP EPS | B9: ='GAAP Reconciliation'!B46 | C9: ='GAAP Reconciliation'!C46 | D9: ='GAAP Reconciliation'!D46 | E9: ='GAAP Reconciliation'!E46 | F9: ='GAAP Reconciliation'!F46 | G9: ='GAAP Reconciliation'!G46 | H9: ='GAAP Reconciliation'!H46 | I9: ='GAAP Reconciliation'!I46 | ... K9: ='GAAP Reconciliation'!K46
A12: Quarterly Dilution Schedule (Next 8 Quarters)
B14: Q1-25E | C14: Q2-25E | D14: Q3-25E | E14: Q4-25E | F14: Q1-26E | G14: Q2-26E | H14: Q3-26E | I14: Q4-26E
A15: Beginning Shares (M) | B15: =Assumptions!G48 | C15: =B19 | D15: =C19 | E15: =D19 | F15: =E19 | G15: =F19 | H15: =G19 | I15: =H19
A16: (+) RSU Vesting | B16: 12 | C16: 11 | D16: 13 | E16: 12 | F16: 11 | G16: 10 | H16: 12 | I16: 11
A17: (-) Buybacks | B17: 5 | C17: 5 | D17: 5 | E17: 5 | F17: 5 | G17: 5 | H17: 5 | I17: 5
A18: (+/-) Other | B18: 3 | C18: 4 | D18: 2 | E18: 3 | F18: 3 | G18: 3 | H18: 1 | I18: 3
A19: Ending Shares (M) | B19: =B15+B16-B17+B18 | C19: =C15+C16-C17+C18 | D19: =D15+D16-D17+D18 | E19: =E15+E16-E17+E18 | F19: =F15+F16-F17+F18 | G19: =G15+G16-G17+G18 | H19: =H15+H16-H17+H18 | I19: =I15+I16-I17+I18
A21: Memo: New RSU Grants | B21: 8 | C21: 8 | D21: 8 | E21: 8 | F21: 7 | G21: 7 | H21: 7 | I21: 7
A22: Memo: Quarterly SBC ($M) | B22: ='Quarterly Detail'!J23 | C22: ='Quarterly Detail'!K23 | D22: ='Quarterly Detail'!L23 | E22: ='Quarterly Detail'!M23 | F22: ='Quarterly Detail'!N23 | G22: ='Quarterly Detail'!O23 | H22: ='Quarterly Detail'!P23 | I22: ='Quarterly Detail'!Q23
A23: Memo: SBC / Share ($) | B23: =ROUND(B22/B19,2) | C23: =ROUND(C22/C19,2) | D23: =ROUND(D22/D19,2) | E23: =ROUND(E22/E19,2) | F23: =ROUND(F22/F19,2) | G23: =ROUND(G22/G19,2) | H23: =ROUND(H22/H19,2) | I23: =ROUND(I22/I19,2)
A25: Outstanding Equity Awards (est.)
A26: Unvested RSUs (M) | B26: 120 | C26: 117 | D26: 112 | E26: 108 | F26: 104 | G26: 101 | H26: 96 | I26: 92
A27: Vested Options (M) | B27: 15 | C27: 14 | D27: 13 | E27: 12 | F27: 11 | G27: 10 | H27: 9 | I27: 8

Sheet Sensitivity Analysis
A1: Snap Inc. (SNAP) - Sensitivity Analysis
A4: TABLE 1: FY2026E Revenue ($M)
A6: DAU Growth / ARPU Growth -> | B6: 0.04 | C6: 0.06 | D6: 0.09 | E6: 0.12 | F6: 0.15
A7: 0.02 | B7: =ROUND(('Revenue Build'!H7*(1+$A7))*('Revenue Build'!H11*(1+B$6)),0) | C7: =ROUND(('Revenue Build'!H7*(1+$A7))*('Revenue Build'!H11*(1+C$6)),0) | D7: =ROUND(('Revenue Build'!H7*(1+$A7))*('Revenue Build'!H11*(1+D$6)),0) | E7: =ROUND(('Revenue Build'!H7*(1+$A7))*('Revenue Build'!H11*(1+E$6)),0) | F7: =ROUND(('Revenue Build'!H7*(1+$A7))*('Revenue Build'!H11*(1+F$6)),0)
A8: 0.035 | B8: =ROUND(('Revenue Build'!H7*(1+$A8))*('Revenue Build'!H11*(1+B$6)),0) | C8: =ROUND(('Revenue Build'!H7*(1+$A8))*('Revenue Build'!H11*(1+C$6)),0) | D8: =ROUND(('Revenue Build'!H7*(1+$A8))*('Revenue Build'!H11*(1+D$6)),0) | E8: =ROUND(('Revenue Build'!H7*(1+$A8))*('Revenue Build'!H11*(1+E$6)),0) | F8: =ROUND(('Revenue Build'!H7*(1+$A8))*('Revenue Build'!H11*(1+F$6)),0)
A9: 0.055 | B9: =ROUND(('Revenue Build'!H7*(1+$A9))*('Revenue Build'!H11*(1+B$6)),0) | C9: =ROUND(('Revenue Build'!H7*(1+$A9))*('Revenue Build'!H11*(1+C$6)),0) | D9: =ROUND(('Revenue Build'!H7*(1+$A9))*('Revenue Build'!H11*(1+D$6)),0) | E9: =ROUND(('Revenue Build'!H7*(1+$A9))*('Revenue Build'!H11*(1+E$6)),0) | F9: =ROUND(('Revenue Build'!H7*(1+$A9))*('Revenue Build'!H11*(1+F$6)),0)
A10: 0.07 | B10: =ROUND(('Revenue Build'!H7*(1+$A10))*('Revenue Build'!H11*(1+B$6)),0) | C10: =ROUND(('Revenue Build'!H7*(1+$A10))*('Revenue Build'!H11*(1+C$6)),0) | D10: =ROUND(('Revenue Build'!H7*(1+$A10))*('Revenue Build'!H11*(1+D$6)),0) | E10: =ROUND(('Revenue Build'!H7*(1+$A10))*('Revenue Build'!H11*(1+E$6)),0) | F10: =ROUND(('Revenue Build'!H7*(1+$A10))*('Revenue Build'!H11*(1+F$6)),0)
A11: 0.085 | B11: =ROUND(('Revenue Build'!H7*(1+$A11))*('Revenue Build'!H11*(1+B$6)),0) | C11: =ROUND(('Revenue Build'!H7*(1+$A11))*('Revenue Build'!H11*(1+C$6)),0) | D11: =ROUND(('Revenue Build'!H7*(1+$A11))*('Revenue Build'!H11*(1+D$6)),0) | E11: =ROUND(('Revenue Build'!H7*(1+$A11))*('Revenue Build'!H11*(1+E$6)),0) | F11: =ROUND(('Revenue Build'!H7*(1+$A11))*('Revenue Build'!H11*(1+F$6)),0)
A15: TABLE 2: FY2026E Adj EBITDA ($M)
A17: Rev Growth / Adj EBITDA Margin -> | B17: 0.1 | C17: 0.14 | D17: 0.18 | E17: 0.22 | F17: 0.26
A18: 0.1 | B18: =ROUND('Revenue Build'!H15*(1+$A18)*B$17,0) | C18: =ROUND('Revenue Build'!H15*(1+$A18)*C$17,0) | D18: =ROUND('Revenue Build'!H15*(1+$A18)*D$17,0) | E18: =ROUND('Revenue Build'!H15*(1+$A18)*E$17,0) | F18: =ROUND('Revenue Build'!H15*(1+$A18)*F$17,0)
A19: 0.14 | B19: =ROUND('Revenue Build'!H15*(1+$A19)*B$17,0) | C19: =ROUND('Revenue Build'!H15*(1+$A19)*C$17,0) | D19: =ROUND('Revenue Build'!H15*(1+$A19)*D$17,0) | E19: =ROUND('Revenue Build'!H15*(1+$A19)*E$17,0) | F19: =ROUND('Revenue Build'!H15*(1+$A19)*F$17,0)
A20: 0.17 | B20: =ROUND('Revenue Build'!H15*(1+$A20)*B$17,0) | C20: =ROUND('Revenue Build'!H15*(1+$A20)*C$17,0) | D20: =ROUND('Revenue Build'!H15*(1+$A20)*D$17,0) | E20: =ROUND('Revenue Build'!H15*(1+$A20)*E$17,0) | F20: =ROUND('Revenue Build'!H15*(1+$A20)*F$17,0)
A21: 0.2 | B21: =ROUND('Revenue Build'!H15*(1+$A21)*B$17,0) | C21: =ROUND('Revenue Build'!H15*(1+$A21)*C$17,0) | D21: =ROUND('Revenue Build'!H15*(1+$A21)*D$17,0) | E21: =ROUND('Revenue Build'!H15*(1+$A21)*E$17,0) | F21: =ROUND('Revenue Build'!H15*(1+$A21)*F$17,0)
A22: 0.24 | B22: =ROUND('Revenue Build'!H15*(1+$A22)*B$17,0) | C22: =ROUND('Revenue Build'!H15*(1+$A22)*C$17,0) | D22: =ROUND('Revenue Build'!H15*(1+$A22)*D$17,0) | E22: =ROUND('Revenue Build'!H15*(1+$A22)*E$17,0) | F22: =ROUND('Revenue Build'!H15*(1+$A22)*F$17,0)
A26: TABLE 3: DCF Implied Share Price ($)
A28: DCF Helper Data:
A29: FCF 25E | B29: ='Cash Flow & FCF Bridge'!H26
A30: FCF 26E | B30: ='Cash Flow & FCF Bridge'!I26
A31: FCF 27E | B31: ='Cash Flow & FCF Bridge'!J26
A32: FCF 28E | B32: ='Cash Flow & FCF Bridge'!K26
A33: Net Debt | B33: =Assumptions!H40-'Cash Flow & FCF Bridge'!H24
A34: Shares | B34: =Assumptions!I48
A36: WACC / Terminal Growth -> | B36: 0.02 | C36: 0.025 | D36: 0.03 | E36: 0.035 | F36: 0.04
A37: 0.09 | B37: =ROUND(($B$29/(1+$A37)^1+$B$30/(1+$A37)^2+$B$31/(1+$A37)^3+$B$32/(1+$A37)^4+$B$32*(1+B$36)/($A37-B$36)/(1+$A37)^4-$B$33)/$B$34,1) | C37: =ROUND(($B$29/(1+$A37)^1+$B$30/(1+$A37)^2+$B$31/(1+$A37)^3+$B$32/(1+$A37)^4+$B$32*(1+C$36)/($A37-C$36)/(1+$A37)^4-$B$33)/$B$34,1) | D37: =ROUND(($B$29/(1+$A37)^1+$B$30/(1+$A37)^2+$B$31/(1+$A37)^3+$B$32/(1+$A37)^4+$B$32*(1+D$36)/($A37-D$36)/(1+$A37)^4-$B$33)/$B$34,1) | E37: =ROUND(($B$29/(1+$A37)^1+$B$30/(1+$A37)^2+$B$31/(1+$A37)^3+$B$32/(1+$A37)^4+$B$32*(1+E$36)/($A37-E$36)/(1+$A37)^4-$B$33)/$B$34,1) | F37: =ROUND(($B$29/(1+$A37)^1+$B$30/(1+$A37)^2+$B$31/(1+$A37)^3+$B$32/(1+$A37)^4+$B$32*(1+F$36)/($A37-F$36)/(1+$A37)^4-$B$33)/$B$34,1)
A38: 0.1 | B38: =ROUND(($B$29/(1+$A38)^1+$B$30/(1+$A38)^2+$B$31/(1+$A38)^3+$B$32/(1+$A38)^4+$B$32*(1+B$36)/($A38-B$36)/(1+$A38)^4-$B$33)/$B$34,1) | C38: =ROUND(($B$29/(1+$A38)^1+$B$30/(1+$A38)^2+$B$31/(1+$A38)^3+$B$32/(1+$A38)^4+$B$32*(1+C$36)/($A38-C$36)/(1+$A38)^4-$B$33)/$B$34,1) | D38: =ROUND(($B$29/(1+$A38)^1+$B$30/(1+$A38)^2+$B$31/(1+$A38)^3+$B$32/(1+$A38)^4+$B$32*(1+D$36)/($A38-D$36)/(1+$A38)^4-$B$33)/$B$34,1) | E38: =ROUND(($B$29/(1+$A38)^1+$B$30/(1+$A38)^2+$B$31/(1+$A38)^3+$B$32/(1+$A38)^4+$B$32*(1+E$36)/($A38-E$36)/(1+$A38)^4-$B$33)/$B$34,1) | F38: =ROUND(($B$29/(1+$A38)^1+$B$30/(1+$A38)^2+$B$31/(1+$A38)^3+$B$32/(1+$A38)^4+$B$32*(1+F$36)/($A38-F$36)/(1+$A38)^4-$B$33)/$B$34,1)
A39: 0.11 | B39: =ROUND(($B$29/(1+$A39)^1+$B$30/(1+$A39)^2+$B$31/(1+$A39)^3+$B$32/(1+$A39)^4+$B$32*(1+B$36)/($A39-B$36)/(1+$A39)^4-$B$33)/$B$34,1) | C39: =ROUND(($B$29/(1+$A39)^1+$B$30/(1+$A39)^2+$B$31/(1+$A39)^3+$B$32/(1+$A39)^4+$B$32*(1+C$36)/($A39-C$36)/(1+$A39)^4-$B$33)/$B$34,1) | D39: =ROUND(($B$29/(1+$A39)^1+$B$30/(1+$A39)^2+$B$31/(1+$A39)^3+$B$32/(1+$A39)^4+$B$32*(1+D$36)/($A39-D$36)/(1+$A39)^4-$B$33)/$B$34,1) | E39: =ROUND(($B$29/(1+$A39)^1+$B$30/(1+$A39)^2+$B$31/(1+$A39)^3+$B$32/(1+$A39)^4+$B$32*(1+E$36)/($A39-E$36)/(1+$A39)^4-$B$33)/$B$34,1) | F39: =ROUND(($B$29/(1+$A39)^1+$B$30/(1+$A39)^2+$B$31/(1+$A39)^3+$B$32/(1+$A39)^4+$B$32*(1+F$36)/($A39-F$36)/(1+$A39)^4-$B$33)/$B$34,1)
A40: 0.12 | B40: =ROUND(($B$29/(1+$A40)^1+$B$30/(1+$A40)^2+$B$31/(1+$A40)^3+$B$32/(1+$A40)^4+$B$32*(1+B$36)/($A40-B$36)/(1+$A40)^4-$B$33)/$B$34,1) | C40: =ROUND(($B$29/(1+$A40)^1+$B$30/(1+$A40)^2+$B$31/(1+$A40)^3+$B$32/(1+$A40)^4+$B$32*(1+C$36)/($A40-C$36)/(1+$A40)^4-$B$33)/$B$34,1) | D40: =ROUND(($B$29/(1+$A40)^1+$B$30/(1+$A40)^2+$B$31/(1+$A40)^3+$B$32/(1+$A40)^4+$B$32*(1+D$36)/($A40-D$36)/(1+$A40)^4-$B$33)/$B$34,1) | E40: =ROUND(($B$29/(1+$A40)^1+$B$30/(1+$A40)^2+$B$31/(1+$A40)^3+$B$32/(1+$A40)^4+$B$32*(1+E$36)/($A40-E$36)/(1+$A40)^4-$B$33)/$B$34,1) | F40: =ROUND(($B$29/(1+$A40)^1+$B$30/(1+$A40)^2+$B$31/(1+$A40)^3+$B$32/(1+$A40)^4+$B$32*(1+F$36)/($A40-F$36)/(1+$A40)^4-$B$33)/$B$34,1)
A41: 0.13 | B41: =ROUND(($B$29/(1+$A41)^1+$B$30/(1+$A41)^2+$B$31/(1+$A41)^3+$B$32/(1+$A41)^4+$B$32*(1+B$36)/($A41-B$36)/(1+$A41)^4-$B$33)/$B$34,1) | C41: =ROUND(($B$29/(1+$A41)^1+$B$30/(1+$A41)^2+$B$31/(1+$A41)^3+$B$32/(1+$A41)^4+$B$32*(1+C$36)/($A41-C$36)/(1+$A41)^4-$B$33)/$B$34,1) | D41: =ROUND(($B$29/(1+$A41)^1+$B$30/(1+$A41)^2+$B$31/(1+$A41)^3+$B$32/(1+$A41)^4+$B$32*(1+D$36)/($A41-D$36)/(1+$A41)^4-$B$33)/$B$34,1) | E41: =ROUND(($B$29/(1+$A41)^1+$B$30/(1+$A41)^2+$B$31/(1+$A41)^3+$B$32/(1+$A41)^4+$B$32*(1+E$36)/($A41-E$36)/(1+$A41)^4-$B$33)/$B$34,1) | F41: =ROUND(($B$29/(1+$A41)^1+$B$30/(1+$A41)^2+$B$31/(1+$A41)^3+$B$32/(1+$A41)^4+$B$32*(1+F$36)/($A41-F$36)/(1+$A41)^4-$B$33)/$B$34,1)

Sheet Valuation Cross-Checks
A1: Snap Inc. (SNAP) - Valuation Cross-Checks
A3: 1. DCF Valuation
A5: WACC | B5: 0.11
A6: Terminal Growth | B6: 0.03
A7: Net Debt ($M) | B7: =Assumptions!H40-'Cash Flow & FCF Bridge'!H24
A8: Shares (M) | B8: =Assumptions!I48
B10: FY2025E | C10: FY2026E | D10: FY2027E | E10: FY2028E
A11: FCF ($M) | B11: ='Cash Flow & FCF Bridge'!H26 | C11: ='Cash Flow & FCF Bridge'!I26 | D11: ='Cash Flow & FCF Bridge'!J26 | E11: ='Cash Flow & FCF Bridge'!K26
A12: Discount Factor | B12: =1/(1+$B$5)^1 | C12: =1/(1+$B$5)^2 | D12: =1/(1+$B$5)^3 | E12: =1/(1+$B$5)^4
A13: PV of FCF | B13: =ROUND(B11*B12,0) | C13: =ROUND(C11*C12,0) | D13: =ROUND(D11*D12,0) | E13: =ROUND(E11*E12,0)
A15: Sum PV FCFs | B15: =SUM(B13:E13)
A16: Terminal Value | B16: =ROUND(E11*(1+$B$6)/($B$5-$B$6),0)
A17: PV of TV | B17: =ROUND(B16*E12,0)
A18: EV ($M) | B18: =B15+B17
A19: Equity ($M) | B19: =B18-B7
A20: Implied Price ($) | B20: =ROUND(B19/B8,2)
A23: 2. Unit Economics / EV Sanity Check
A25: Market Cap ($M, est.) | B25: 18000
A26: EV ($M, est.) | B26: =B25+B7
A28: Metric | B28: Value | C28: Commentary
A29: EV/DAU ($) | B29: =ROUND(B26/'Revenue Build'!H7,1) | C29: vs META ~$310, PINS ~$75
A30: EV/FY25E Rev | B30: =ROUND(B26/'Revenue Build'!H15,1) | C30: vs peers 4-8x
A31: EV/FY26E Adj EBITDA | B31: =IF('Non-GAAP P&L'!I27>0,ROUND(B26/'Non-GAAP P&L'!I27,1),"N/M") | C31: vs peers 15-25x
A32: FY26E FCF Yield | B32: =IF('Cash Flow & FCF Bridge'!I26>0,'Cash Flow & FCF Bridge'!I26/B25,0) | C32: FCF inflection
A35: Valuation Summary
A36: Current Price (est.) | B36: 10.5
A38: Method | B38: Price ($) | C38: Upside/Downside
A39: DCF | B39: =B20 | C39: =B39/B36-1
A40: EV/Rev Comp (4x FY26E) | B40: =ROUND(('Revenue Build'!I15*4-B7)/B8,2) | C40: =B40/B36-1

Sheet Assumptions
A1: Snap Inc. (SNAP) - Model Assumptions (Non-GAAP Primary)
B3: 2019 | C3: 2020 | D3: 2021 | E3: 2022 | F3: 2023 | G3: 2024 | H3: 2025E | I3: 2026E | J3: 2027E | K3: 2028E
B4: Historical | C4: Historical | D4: Historical | E4: Historical | F4: Historical | G4: Historical | H4: Forecast | I4: Forecast | J4: Forecast | K4: Forecast
A6: GROWTH DRIVERS
A7: DAU YoY Growth | C7: ='Revenue Build'!C7/'Revenue Build'!B7-1 | D7: ='Revenue Build'!D7/'Revenue Build'!C7-1 | E7: ='Revenue Build'!E7/'Revenue Build'!D7-1 | F7: ='Revenue Build'!F7/'Revenue Build'!E7-1 | G7: ='Revenue Build'!G7/'Revenue Build'!F7-1 | H7: 0.065 | I7: 0.055 | J7: 0.045 | K7: 0.04
A8: ARPU YoY Growth | C8: ='Revenue Build'!C11/'Revenue Build'!B11-1 | D8: ='Revenue Build'!D11/'Revenue Build'!C11-1 | E8: ='Revenue Build'!E11/'Revenue Build'!D11-1 | F8: ='Revenue Build'!F11/'Revenue Build'!E11-1 | G8: ='Revenue Build'!G11/'Revenue Build'!F11-1 | H8: 0.1 | I8: 0.09 | J8: 0.08 | K8: 0.07
A10: NON-GAAP MARGIN ASSUMPTIONS
A11: Non-GAAP Gross Margin | B11: ='Non-GAAP P&L'!B10/'Non-GAAP P&L'!B6 | C11: ='Non-GAAP P&L'!C10/'Non-GAAP P&L'!C6 | D11: ='Non-GAAP P&L'!D10/'Non-GAAP P&L'!D6 | E11: ='Non-GAAP P&L'!E10/'Non-GAAP P&L'!E6 | F11: ='Non-GAAP P&L'!F10/'Non-GAAP P&L'!F6 | G11: ='Non-GAAP P&L'!G10/'Non-GAAP P&L'!G6 | H11: 0.575 | I11: 0.59 | J11: 0.605 | K11: 0.62
A12: Non-GAAP R&D % of Rev | B12: ='Non-GAAP P&L'!B14/'Non-GAAP P&L'!B6 | C12: ='Non-GAAP P&L'!C14/'Non-GAAP P&L'!C6 | D12: ='Non-GAAP P&L'!D14/'Non-GAAP P&L'!D6 | E12: ='Non-GAAP P&L'!E14/'Non-GAAP P&L'!E6 | F12: ='Non-GAAP P&L'!F14/'Non-GAAP P&L'!F6 | G12: ='Non-GAAP P&L'!G14/'Non-GAAP P&L'!G6 | H12: 0.19 | I12: 0.17 | J12: 0.16 | K12: 0.15
A13: Non-GAAP S&M % of Rev | B13: ='Non-GAAP P&L'!B16/'Non-GAAP P&L'!B6 | C13: ='Non-GAAP P&L'!C16/'Non-GAAP P&L'!C6 | D13: ='Non-GAAP P&L'!D16/'Non-GAAP P&L'!D6 | E13: ='Non-GAAP P&L'!E16/'Non-GAAP P&L'!E6 | F13: ='Non-GAAP P&L'!F16/'Non-GAAP P&L'!F6 | G13: ='Non-GAAP P&L'!G16/'Non-GAAP P&L'!G6 | H13: 0.16 | I13: 0.15 | J13: 0.14 | K13: 0.13
A14: Non-GAAP G&A % of Rev | B14: ='Non-GAAP P&L'!B18/'Non-GAAP P&L'!B6 | C14: ='Non-GAAP P&L'!C18/'Non-GAAP P&L'!C6 | D14: ='Non-GAAP P&L'!D18/'Non-GAAP P&L'!D6 | E14: ='Non-GAAP P&L'!E18/'Non-GAAP P&L'!E6 | F14: ='Non-GAAP P&L'!F18/'Non-GAAP P&L'!F6 | G14: ='Non-GAAP P&L'!G18/'Non-GAAP P&L'!G6 | H14: 0.05 | I14: 0.047 | J14: 0.044 | K14: 0.042
A16: GAAP ADJUSTMENT ITEMS
A17: SBC % of Revenue | B17: ='Non-GAAP P&L'!B41/'Non-GAAP P&L'!B6 | C17: ='Non-GAAP P&L'!C41/'Non-GAAP P&L'!C6 | D17: ='Non-GAAP P&L'!D41/'Non-GAAP P&L'!D6 | E17: ='Non-GAAP P&L'!E41/'Non-GAAP P&L'!E6 | F17: ='Non-GAAP P&L'!F41/'Non-GAAP P&L'!F6 | G17: ='Non-GAAP P&L'!G41/'Non-GAAP P&L'!G6 | H17: 0.2 | I17: 0.17 | J17: 0.15 | K17: 0.13
A18: SBC % Allocated to COGS | B18: 0.05 | C18: 0.05 | D18: 0.05 | E18: 0.05 | F18: 0.05 | G18: 0.05 | H18: 0.05 | I18: 0.05 | J18: 0.05 | K18: 0.05
A19: Intangible Amortization ($M) | B19: 30 | C19: 32 | D19: 55 | E19: 70 | F19: 65 | G19: 55 | H19: 45 | I19: 40 | J19: 35 | K19: 30
A20: Restructuring Charges ($M) | B20: 0 | C20: 0 | D20: 0 | E20: 155 | F20: 80 | G20: 35 | H20: 15 | I20: 10 | J20: 5 | K20: 0
A21: PP&E Depreciation ($M) | B21: 51 | C21: 75 | D21: 85 | E21: 115 | F21: 135 | G21: 160 | H21: 170 | I21: 180 | J21: 190 | K21: 200
A22: Non-GAAP Tax Rate | B22: 0.02 | C22: 0.02 | D22: 0.05 | E22: 0.05 | F22: 0.08 | G22: 0.1 | H22: 0.1 | I22: 0.12 | J22: 0.15 | K22: 0.18
A23: GAAP Tax Rate | B23: 0 | C23: 0 | D23: 0 | E23: 0 | F23: 0 | G23: 0 | H23: 0.05 | I23: 0.07 | J23: 0.1 | K23: 0.12
A25: GEOGRAPHIC MIX
A26: NA % of Revenue | B26: ='Revenue Build'!B19/'Revenue Build'!B15 | C26: ='Revenue Build'!C19/'Revenue Build'!C15 | D26: ='Revenue Build'!D19/'Revenue Build'!D15 | E26: ='Revenue Build'!E19/'Revenue Build'!E15 | F26: ='Revenue Build'!F19/'Revenue Build'!F15 | G26: ='Revenue Build'!G19/'Revenue Build'!G15 | H26: 0.63 | I26: 0.62 | J26: 0.61 | K26: 0.6
A27: EU % of Revenue | B27: ='Revenue Build'!B21/'Revenue Build'!B15 | C27: ='Revenue Build'!C21/'Revenue Build'!C15 | D27: ='Revenue Build'!D21/'Revenue Build'!D15 | E27: ='Revenue Build'!E21/'Revenue Build'!E15 | F27: ='Revenue Build'!F21/'Revenue Build'!F15 | G27: ='Revenue Build'!G21/'Revenue Build'!G15 | H27: 0.2 | I27: 0.2 | J27: 0.2 | K27: 0.21
A28: ROW % of Revenue | B28: ='Revenue Build'!B23/'Revenue Build'!B15 | C28: ='Revenue Build'!C23/'Revenue Build'!C15 | D28: ='Revenue Build'!D23/'Revenue Build'!D15 | E28: ='Revenue Build'!E23/'Revenue Build'!E15 | F28: ='Revenue Build'!F23/'Revenue Build'!F15 | G28: ='Revenue Build'!G23/'Revenue Build'!G15 | H28: 0.17 | I28: 0.18 | J28: 0.19 | K28: 0.19
A30: OTHER P&L ITEMS
A31: CapEx ($M, positive) | B31: 51 | C31: 59 | D31: 85 | E31: 115 | F31: 93 | G31: 90 | H31: 95 | I31: 100 | J31: 105 | K31: 110
A32: Interest Expense ($M, positive) | B32: 51 | C32: 88 | D32: 89 | E32: 87 | F32: 100 | G32: 95 | H32: 90 | I32: 85 | J32: 80 | K32: 75
A33: WC Change ($M) | B33: -80 | C33: -45 | D33: -120 | E33: 50 | F33: 30 | G33: 15 | H33: -20 | I33: -15 | J33: -10 | K33: -5
A35: BALANCE SHEET DRIVERS
A36: PP&E ($M) | B36: 204 | C36: 258 | D36: 339 | E36: 452 | F36: 430 | G36: 400 | H36: 390 | I36: 385 | J36: 380 | K36: 375
A37: Intangibles BS ($M) | B37: 181 | C37: 182 | D37: 411 | E37: 440 | F37: 395 | G37: 360 | H37: 340 | I37: 320 | J37: 300 | K37: 280
A38: ROU Assets ($M) | B38: 250 | C38: 280 | D38: 310 | E38: 350 | F38: 360 | G38: 370 | H38: 375 | I38: 380 | J38: 385 | K38: 390
A39: Other LT Assets ($M) | B39: 150 | C39: 180 | D39: 250 | E39: 310 | F39: 330 | G39: 350 | H39: 360 | I39: 370 | J39: 380 | K39: 390
A40: Long-Term Debt ($M) | B40: 1485 | C40: 2190 | D40: 3745 | E40: 3745 | F40: 3745 | G40: 3745 | H40: 3745 | I40: 3745 | J40: 3745 | K40: 3745
A41: Lease Liabilities ($M) | B41: 220 | C41: 260 | D41: 300 | E41: 340 | F41: 350 | G41: 360 | H41: 365 | I41: 370 | J41: 375 | K41: 380
A42: Other LT Liab ($M) | B42: 80 | C42: 95 | D42: 120 | E42: 140 | F42: 150 | G42: 155 | H42: 160 | I42: 165 | J42: 170 | K42: 175
A43: DSO (days) | H43: 80 | I43: 80 | J43: 80 | K43: 80
A44: DPO (days) | H44: 42 | I44: 42 | J44: 42 | K44: 42
A45: Accrued Liab % of Rev | H45: 0.12 | I45: 0.12 | J45: 0.12 | K45: 0.12
A47: SHARE COUNT
A48: Diluted Shares (M) | B48: 1500 | C48: 1548 | D48: 1620 | E48: 1660 | F48: 1676 | G48: 1690 | H48: =ROUND(G48*(1+H49),0) | I48: =ROUND(H48*(1+I49),0) | J48: =ROUND(I48*(1+J49),0) | K48: =ROUND(J48*(1+K49),0)
...
