Workbook

Sheet Summary
A1: Revenue Exposure to Teens Under 16 — Meta · Google · Snap · Pinterest
A2: Estimation model · FY2025 financials · base case unless ranged · figures in US$ millions
A4: Cohort definition: users UNDER AGE 16 — primarily 13–15 year-olds, plus under-13s present despite platforms' 13+ minimum-age rules (Ofcom: 51% of UK under-13s use social media).
A6: Company | B6: FY2025 revenue base ($M) | C6: Under-16 share (blended) | D6: Under-16 rev BASE ($M) | E6: Low ($M) | F6: High ($M) | G6: Primary youth surface
A7: Meta Platforms | B7: ='Model - Meta'!B12 | C7: ='Model - Meta'!C12 | D7: ='Model - Meta'!D12 | E7: ='Model - Meta'!E12 | F7: ='Model - Meta'!F12 | G7: Instagram
A8: Google / Alphabet | B8: ='Model - Google'!B30 | C8: ='Model - Google'!C30 | D8: ='Model - Google'!D30 | E8: ='Model - Google'!E30 | F8: ='Model - Google'!F30 | G8: YouTube
A9: Snap | B9: ='Model - Snap'!B11 | C9: ='Model - Snap'!C11 | D9: ='Model - Snap'!D11 | E9: ='Model - Snap'!E11 | F9: ='Model - Snap'!F11 | G9: Snapchat
A10: Pinterest | B10: ='Model - Pinterest'!B11 | C10: ='Model - Pinterest'!C11 | D10: ='Model - Pinterest'!D11 | E10: ='Model - Pinterest'!E11 | F10: ='Model - Pinterest'!F11 | G10: Pinterest
A11: TOTAL (4 companies) | B11: =SUM(B7:B10) | C11: =D11/B11 | D11: =SUM(D7:D10) | E11: =SUM(E7:E10) | F11: =SUM(F7:F10)
A13: BASE-CASE ESTIMATE: combined under-16 advertising-revenue exposure of roughly US$ (see D11) million per year across the four platforms.
A15: How to read this workbook
A16: • 'Under-16 revenue' = the slice of each platform's advertising revenue attributable to users aged under 16.
A17: • It is an ESTIMATE. No platform discloses age-specific revenue; this is a transparent, source-anchored model.
A18: • The driver is each platform's US under-16 ad-revenue SHARE (anchored to the Harvard 2023 study), scaled by
A19: region (multipliers) and applied to disclosed FY2025 regional revenue. See 'Assumptions' to flex any input.
A20: • Low / Base / High apply scenario scalars (0.65 / 1.00 / 1.35) reflecting Harvard's uncertainty intervals and
A21: the well-documented under-reporting of age by younger users (Meta 10-K; Ofcom: 40% of 8–17s give a fake age).
A22: • Snap shows the highest exposure (teen-core app); Pinterest the lowest (older, female-skewed, <18 ad limits).
A23: • Tabs: Methodology · Financials · Youth Usage Evidence · Assumptions · Model-<Company> · Aggregate · Regulatory Headwind · Sources.
A25: Key caveats
A26: 1. Platforms do not report revenue by age; all age-specific figures are modelled, not disclosed.
... A34: Australia's under-16 ban (in force Dec 2025) covers Facebook, Instagram, Snapchat and YouTube; Pinterest, Messenger and WhatsApp are EXCLUDED.
A35: Estimated at-risk revenue — Scenario A (Australia, in force today): | G35: ='Regulatory Headwind'!F54 | H35: $M / yr
A36: Estimated at-risk revenue — Scenario B (+ UK & EU pipeline, ~2026–27): | G36: ='Regulatory Headwind'!F55 | H36: $M / yr
A37: Estimated at-risk revenue — Scenario C (+ US states, broad adoption): | G37: ='Regulatory Headwind'!F56 | H37: $M / yr
A38: Most exposed: Snap (teen-core). Least: Pinterest (excluded in AU, older audience). FY2025 growth for context: Meta +22%, Google +15%, Snap +11%, Pinterest +16%.

Sheet Methodology
A1: METHODOLOGY
B3: Objective
B4: Estimate the annual advertising-revenue exposure of Meta, Google (Alphabet), Snap and Pinterest to users under age 16, at the most granular level the public data allows (company × surface × region × age band).
B5: Core formula (per company, per region)
B6: Under-16 revenue = Regional revenue × Under-16 revenue share(region) × Scenario scalar
B7: Under-16 revenue share(region) = US/anchor under-16 share × Regional multiplier
B8: US/anchor under-16 share = US under-18 share × Under-16 fraction of under-18
B9: Under-16 fraction of under-18 = (0–12 share of under-18 $) + (1 − that share) × (13–15 split of 13–17)
B10: Step 1 — Anchor: US under-18 ad-revenue shares (Harvard 2023)
B11: Raffoul et al. (PLOS ONE, 2023) simulated US 2022 youth ad revenue using Census, Common Sense Media, Pew, eMarketer and Qustodio data. Disclosed US under-18 SHARE of each platform's ad revenue: Instagram 16%, Snapchat 41.4%, YouTube 27%, Facebook 1.9%. These are the model's anchors (Pinterest, Search and Network are not in the study and are estimated).
B12: Step 2 — Split under-18 into under-16
B13: 'Under 16' = ages 0–15. We take all under-13 (0–12) revenue plus the 13–15 portion of the 13–17 band. The 13–15 portion is set at 57% of the 13–17 band (3 of 5 single-year ages, with a mild skew to higher engagement among 16–17s). The 0–12 share of each platform's under-18 dollars comes from the Harvard dollar figures where available (Instagram, YouTube) and is modelled otherwise.
B14: Step 3 — Regionalise
... B21: No platform discloses revenue by user age, and they caution that age data is unreliable because under-age users mis-state their age (Meta 10-K: 'a disproportionate number of our younger users register with an inaccurate age'). The workbook is therefore a transparent, fully-sourced model; every input is editable on the Assumptions tab and the results recalculate.

Sheet Financials
A1: HARD FINANCIAL DATA — FY2024 vs FY2025 (as reported) $M unless noted
A3: Meta Platforms
A4: Item | B4: FY2024 | C4: FY2025 | D4: YoY %
A5: Total revenue | B5: 164501 | C5: 200966 | D5: =C5/B5-1
A6: Family of Apps revenue | B6: 162355 | C6: 198759 | D6: =C6/B6-1
A7: Advertising revenue | B7: 160633 | C7: 196175 | D7: =C7/B7-1
A8: US & Canada ad rev (est. user-geography) | B8: 70679 | C8: 84355 | D8: =C8/B8-1
A9: Europe ad rev (est.) | B9: 36946 | C9: 45120 | D9: =C9/B9-1
A10: Asia-Pacific ad rev (est.) | B10: 35339 | C10: 45120 | D10: =C10/B10-1
A11: Rest of World ad rev (est.) | B11: 17670 | C11: 21579 | D11: =C11/B11-1
A12: Source: Meta FY2024 & FY2025 10-Ks. Regional ad-revenue split is estimated (user geography).
A14: Google / Alphabet
A15: Item | B15: FY2024 | C15: FY2025 | D15: YoY %
A16: Alphabet total revenue | B16: 350018 | C16: 402836 | D16: =C16/B16-1
A17: Google advertising | B17: 264590 | C17: 294691 | D17: =C17/B17-1
A18: Google Search & other | B18: 198084 | C18: 224532 | D18: =C18/B18-1
A19: YouTube ads | B19: 36147 | C19: 40367 | D19: =C19/B19-1
A20: Google Network | B20: 30359 | C20: 29792 | D20: =C20/B20-1
A21: Geo: United States | B21: 170459 | C21: 194167 | D21: =C21/B21-1
A22: Geo: EMEA | B22: 102205 | C22: 117225 | D22: =C22/B22-1
A23: Geo: APAC | B23: 56703 | C23: 67676 | D23: =C23/B23-1
A24: Geo: Other Americas | B24: 20301 | C24: 23767 | D24: =C24/B24-1
A25: Source: Alphabet FY2024 & FY2025 10-Ks. YouTube regional split estimated; Search/Network use Alphabet geo mix.
A27: Snap Inc.
A28: Item | B28: FY2024 | C28: FY2025 | D28: YoY %
A29: Total revenue | B29: 5361 | C29: 5931 | D29: =C29/B29-1
A30: North America revenue | B30: 3337.3 | C30: 3575.6 | D30: =C30/B30-1
A31: Europe revenue | B31: 961.6 | C31: 1128.4 | D31: =C31/B31-1
A32: Rest of World revenue | B32: 1062.5 | C32: 1227.4 | D32: =C32/B32-1
A33: Global DAU Q4 (m) | B33: 453 | C33: 474 | D33: =C33/B33-1
A34: NA / EU / RoW DAU Q4 (m) | B34: 100 / 99 / 254 | C34: 94 / 98 / 282
A35: Source: Snap FY2024 & FY2025 press releases. Regional figures are total revenue by user region.
A37: Pinterest, Inc.
A38: Item | B38: FY2024 | C38: FY2025 | D38: YoY %
A39: Total revenue | B39: 3646 | C39: 4222 | D39: =C39/B39-1
A40: US & Canada revenue | B40: 2884 | C40: 3173 | D40: =C40/B40-1
A41: Europe revenue | B41: 593 | C41: 775 | D41: =C41/B41-1
A42: Rest of World revenue | B42: 169 | C42: 274 | D42: =C42/B42-1
A43: Global MAU Q4 (m) | B43: 553 | C43: 619 | D43: =C43/B43-1
A44: UCAN / EU / RoW MAU Q4 (m) | B44: 101 / 145 / 307 | C44: 105 / 158 / 356
...

Sheet Youth Usage Evidence
A1: YOUTH-USAGE EVIDENCE BASE (data underpinning the assumptions)
A3: A. Harvard 2023 — estimated US youth USERS by platform, 2022 (millions)
A4: Platform | B4: Ages 0–12 | C4: Ages 13–17 | D4: Ages 0–17 | F4: Note
A5: Facebook | B5: 2.757 | C5: 7.047 | D5: 9.904 | F5: Raffoul et al., PLOS ONE 2023, Table 1
A6: Instagram | B6: 3.982 | C6: 12.726 | D6: 16.708 | F6: Raffoul et al., PLOS ONE 2023, Table 1
A7: Snapchat | B7: 2.869 | C7: 15.131 | D7: 18 | F7: Raffoul et al., PLOS ONE 2023, Table 1
A8: YouTube | B8: 31.448 | C8: 18.341 | D8: 49.789 | F8: Raffoul et al., PLOS ONE 2023, Table 1
A9: TikTok (ref.) | B9: 3.041 | C9: 15.932 | D9: 18.972 | F9: Raffoul et al., PLOS ONE 2023, Table 1
A10: X/Twitter (ref.) | B10: 2.071 | C10: 4.929 | D10: 7.001 | F10: Raffoul et al., PLOS ONE 2023, Table 1
A12: B. Harvard 2023 — US under-18 advertising revenue & share, 2022
A13: Platform | B13: 0–12 rev ($M) | C13: 13–17 rev ($M) | D13: Under-18 % of platform US ad rev | F13: Note
A14: Instagram | B14: 801.1 | C14: 4000 | D14: 0.16 | F14: PLOS ONE 2023, Figs 1–2
A15: YouTube | B15: 959.1 | C15: 1200 | D15: 0.27 | F15: PLOS ONE 2023, Figs 1–2
A16: Snapchat | B16: n/d | C16: n/d | D16: 0.414 | F16: PLOS ONE 2023, Figs 1–2
A17: Facebook | B17: 137.2 | C17: n/d | D17: 0.019 | F17: PLOS ONE 2023, Figs 1–2
A18: TikTok (ref.) | B18: n/d | C18: 2000 | D18: 0.35 | F18: PLOS ONE 2023, Figs 1–2
A19: Aggregate: 6 platforms earned ~$11.0bn US ad revenue from under-18s in 2022 ($2.1bn from ≤12, $8.6bn from 13–17).
A21: C. Ofcom 2024 (UK) — children's platform usage by age
A22: • Social-media use rises with age: 34% of 3–7s, 63% of 8–11s, 92% of 12–15s, 95% of 16–17s.
A23: • 51% of UK under-13s use social media despite the common 13+ minimum age.
A24: • 40% of 8–17s admit giving a fake age to access a site/app (key reason age data is unreliable).
A25: • Instagram and Snapchat usage each rise to ~80% among 16–17s (17% even among 3–4s).
A26: • YouTube is near-universal across all child age bands (>80% of 3–17s).
A27: • 5–7s with own profiles: YouTube/YT Kids 48%, Instagram 9%, WhatsApp 11%.
A29: D. Pinterest age profile
A30: • 13–17 year-olds ≈ 4% of Pinterest's audience; bulk of users are 25–34 (the largest cohort).
A31: • Gen Z is >40% of global MAU and fastest-growing, but that cohort is predominantly 18+.
A32: • Audience skews ~79% female; personalised ads are restricted for users under 18.

Sheet Assumptions
A1: MODELLING ASSUMPTIONS (edit blue-shaded inputs — the model recalculates)
A3: 1. Age-band split parameter
A4: 13–15 share of the 13–17 revenue band | B4: 0.57 | F4: 3 of the 5 single-year ages in 13–17 are <16; mild skew to older teens (slightly higher engagement). Low/Base/High = 50% / 57% / 62%.
A6: 2. Platform US under-16 ad-revenue share (anchored to Harvard 2023 US 2022 study)
A7: Platform / surface | B7: US under-18 rev share | C7: 0–12 share of under-18 $ | D7: Under-16 frac. of under-18 | E7: US under-16 rev share | F7: Basis / source
A8: Instagram | B8: 0.16 | C8: 0.1669 | D8: =C8+(1-C8)*$B4 | E8: =B8*D8 | F8: Harvard: U18 share 16%; 0–12 $801.1M of $4,801M
A9: Facebook | B9: 0.019 | C9: 0.22 | D9: =C9+(1-C9)*$B4 | E9: =B9*D9 | F9: Harvard: U18 share 1.9% (low youth base)
A10: Messenger / other (Meta) | B10: 0.03 | C10: 0.3 | D10: =C10+(1-C10)*$B4 | E10: =B10*D10 | F10: Estimate (messaging; limited youth ads)
A11: YouTube ads | B11: 0.27 | C11: 0.4442 | D11: =C11+(1-C11)*$B4 | E11: =B11*D11 | F11: Harvard: U18 share 27%; 0–12 $959.1M of $2,159M
A12: Google Search & other | B12: 0.025 | C12: 0.25 | D12: =C12+(1-C12)*$B4 | E12: =B12*D12 | F12: Estimate: teens search but low commercial intent/ad value
A13: Google Network | B13: 0.03 | C13: 0.25 | D13: =C13+(1-C13)*$B4 | E13: =B13*D13 | F13: Estimate: programmatic, broad adult base
A14: Snapchat | B14: 0.414 | C14: 0.1 | D14: =C14+(1-C14)*$B4 | E14: =B14*D14 | F14: Harvard: U18 share 41.4%; 0–12 $ modelled at 10%
A15: Pinterest | B15: 0.04 | C15: 0.15 | D15: =C15+(1-C15)*$B4 | E15: =B15*D15 | F15: Estimate: 13–17 ≈4% of users; <18 ad limits
A17: 3. Meta surface mix (weights of US ad revenue) — used to blend Meta's under-16 share
A18: Surface | B18: Weight | E18: US under-16 share | F18: Note
A19: Instagram | B19: 0.5 | E19: ='Assumptions'!$E$8 | F19: Instagram is the youth driver; Facebook skews older
A20: Facebook | B20: 0.4 | E20: ='Assumptions'!$E$9 | F20: Instagram is the youth driver; Facebook skews older
A21: Messenger / other (Meta) | B21: 0.1 | E21: ='Assumptions'!$E$10 | F21: Instagram is the youth driver; Facebook skews older
A22: Meta blended US under-16 share | B22: =SUMPRODUCT(B19:B21,E19:E21)
A24: 4. Regional multipliers (applied to the US/North-America under-16 share)
A25: Region | B25: Multiplier | F25: Rationale
A26: US & Canada / North America | B26: 1 | F26: Anchor region (Harvard study basis)
A27: Europe / EMEA | B27: 0.95 | F27: High youth usage (Ofcom) offset by GDPR-K / DSA enforcement
A28: Asia-Pacific | B28: 1.05 | F28: Younger populations; higher youth share of users
A29: Rest of World | B29: 1.15 | F29: Youngest populations; youth-heavy adoption, light regulation
A31: 5. Scenario scalars (capture model uncertainty: Harvard intervals, age mis-reporting)
A32: Scenario | B32: Scalar | F32: Note
A33: Low | B33: 0.65 | F33: Applied multiplicatively to base under-16 revenue
A34: Base | B34: 1 | F34: Applied multiplicatively to base under-16 revenue
A35: High | B35: 1.35 | F35: Applied multiplicatively to base under-16 revenue

Sheet Model - Meta
A1: UNDER-16 AD-REVENUE EXPOSURE MODEL — Meta Platforms (Facebook + Instagram + Messenger)
A3: FY2025 total revenue ($M) | B3: 200966
A4: FY2025 advertising revenue ($M) | B4: 196175
A5: Meta blended US under-16 ad-revenue share | B5: ='Assumptions'!$B$22
A7: Region | B7: Regional revenue ($M) | C7: Under-16 share (base) | D7: Under-16 rev BASE ($M) | E7: Low ($M) | F7: High ($M) | G7: Notes
A8: US & Canada | B8: 84355.2 | C8: ='Assumptions'!$B$22*'Assumptions'!$B$26 | D8: =B8*C8*'Assumptions'!$B$34 | E8: =B8*C8*'Assumptions'!$B$33 | F8: =B8*C8*'Assumptions'!$B$35 | G8: Anchor; Instagram youth-heavy, Facebook older
A9: Europe | B9: 45120.2 | C9: ='Assumptions'!$B$22*'Assumptions'!$B$27 | D9: =B9*C9*'Assumptions'!$B$34 | E9: =B9*C9*'Assumptions'!$B$33 | F9: =B9*C9*'Assumptions'!$B$35 | G9: Ofcom: ~80% of 16-17s on IG/Snap; DSA minor-risk probe ongoing
A10: Asia-Pacific | B10: 45120.2 | C10: ='Assumptions'!$B$22*'Assumptions'!$B$28 | D10: =B10*C10*'Assumptions'!$B$34 | E10: =B10*C10*'Assumptions'!$B$33 | F10: =B10*C10*'Assumptions'!$B$35 | G10: Lower ARPU but younger, youth-heavy user base
A11: Rest of World | B11: 21579.2 | C11: ='Assumptions'!$B$22*'Assumptions'!$B$29 | D11: =B11*C11*'Assumptions'!$B$34 | E11: =B11*C11*'Assumptions'!$B$33 | F11: =B11*C11*'Assumptions'!$B$35 | G11: Youngest demographics; lightest regulation
A12: TOTAL — Meta | B12: =SUM(B8:B11) | C12: =D12/B12 | D12: =SUM(D8:D11) | E12: =SUM(E8:E11) | F12: =SUM(F8:F11) | G12: Regional ad-revenue split is an estimate (user-geography)

Sheet Model - Google
A1: UNDER-16 AD-REVENUE EXPOSURE MODEL — Google / Alphabet (YouTube + Search + Network)
A3: FY2025 Alphabet total revenue ($M) | B3: 402836
A4: FY2025 Google advertising revenue ($M) | B4: 294691
A5: of which YouTube ads ($M) | B5: 40367
A6: of which Google Search & other ($M) | B6: 224532
A7: of which Google Network ($M) | B7: 29792
A8: YouTube US under-16 ad-revenue share | B8: ='Assumptions'!$E$11
A10: YouTube ads — the principal under-16 surface
A11: Region | B11: Regional revenue ($M) | C11: Under-16 share (base) | D11: Under-16 rev BASE ($M) | E11: Low ($M) | F11: High ($M) | G11: Notes
A12: US & Canada | B12: 14128.4 | C12: ='Assumptions'!$E$11*'Assumptions'!$B$26 | D12: =B12*C12*'Assumptions'!$B$34 | E12: =B12*C12*'Assumptions'!$B$33 | F12: =B12*C12*'Assumptions'!$B$35 | G12: YouTube regional split estimated (intl-heavy monetisation)
A13: Europe | B13: 12110.1 | C13: ='Assumptions'!$E$11*'Assumptions'!$B$27 | D13: =B13*C13*'Assumptions'!$B$34 | E13: =B13*C13*'Assumptions'!$B$33 | F13: =B13*C13*'Assumptions'!$B$35 | G13: YouTube regional split estimated (intl-heavy monetisation)
A14: Asia-Pacific | B14: 9284.4 | C14: ='Assumptions'!$E$11*'Assumptions'!$B$28 | D14: =B14*C14*'Assumptions'!$B$34 | E14: =B14*C14*'Assumptions'!$B$33 | F14: =B14*C14*'Assumptions'!$B$35 | G14: YouTube regional split estimated (intl-heavy monetisation)
A15: Rest of World | B15: 4844 | C15: ='Assumptions'!$E$11*'Assumptions'!$B$29 | D15: =B15*C15*'Assumptions'!$B$34 | E15: =B15*C15*'Assumptions'!$B$33 | F15: =B15*C15*'Assumptions'!$B$35 | G15: YouTube regional split estimated (intl-heavy monetisation)
A16: Subtotal — YouTube ads | B16: =SUM(B12:B15) | C16: =D16/B16 | D16: =SUM(D12:D15) | E16: =SUM(E12:E15) | F16: =SUM(F12:F15)
A18: Google Search & other (lower under-16 exposure)
A19: Region | B19: Regional revenue ($M) | C19: Under-16 share (base) | D19: Under-16 rev BASE ($M) | E19: Low ($M) | F19: High ($M) | G19: Notes
A20: US & Canada | B20: 108224.4 | C20: ='Assumptions'!$E$12*'Assumptions'!$B$26 | D20: =B20*C20*'Assumptions'!$B$34 | E20: =B20*C20*'Assumptions'!$B$33 | F20: =B20*C20*'Assumptions'!$B$35 | G20: Search regional split = Alphabet geographic mix
A21: Europe | B21: 65338.8 | C21: ='Assumptions'!$E$12*'Assumptions'!$B$27 | D21: =B21*C21*'Assumptions'!$B$34 | E21: =B21*C21*'Assumptions'!$B$33 | F21: =B21*C21*'Assumptions'!$B$35 | G21: Search regional split = Alphabet geographic mix
A22: Asia-Pacific | B22: 37721.4 | C22: ='Assumptions'!$E$12*'Assumptions'!$B$28 | D22: =B22*C22*'Assumptions'!$B$34 | E22: =B22*C22*'Assumptions'!$B$33 | F22: =B22*C22*'Assumptions'!$B$35 | G22: Search regional split = Alphabet geographic mix
A23: Rest of World | B23: 13247.4 | C23: ='Assumptions'!$E$12*'Assumptions'!$B$29 | D23: =B23*C23*'Assumptions'!$B$34 | E23: =B23*C23*'Assumptions'!$B$33 | F23: =B23*C23*'Assumptions'!$B$35 | G23: Search regional split = Alphabet geographic mix
A24: Subtotal — Search & other | B24: =SUM(B20:B23) | C24: =D24/B24 | D24: =SUM(D20:D23) | E24: =SUM(E20:E23) | F24: =SUM(F20:F23)
A26: Google Network (worldwide, minimal youth exposure)
A27: Region | B27: Regional revenue ($M) | C27: Under-16 share (base) | D27: Under-16 rev BASE ($M) | E27: Low ($M) | F27: High ($M) | G27: Notes
A28: Worldwide | B28: 29792 | C28: ='Assumptions'!$E$13 | D28: =B28*C28*'Assumptions'!$B$34 | E28: =B28*C28*'Assumptions'!$B$33 | F28: =B28*C28*'Assumptions'!$B$35 | G28: Programmatic third-party inventory; broad adult base
A30: TOTAL — Google (YouTube + Search + Network) | B30: =B16+B24+B28 | C30: =D30/B30 | D30: =D16+D24+D28 | E30: =E16+E24+E28 | F30: =F16+F24+F28 | G30: YouTube is ~90%+ of Google's under-16 exposure

Sheet Model - Snap
A1: UNDER-16 AD-REVENUE EXPOSURE MODEL — Snap Inc. (Snapchat)
A3: FY2025 total revenue ($M) | B3: 5931
A4: Q4-2025 global DAU (millions) | B4: 474
A5: Snapchat US under-16 ad-revenue share | B5: ='Assumptions'!$E$14
D6: Highest under-16 exposure of the four (Harvard: 41% of Snap US ad rev from <18)
A7: Region | B7: Regional revenue ($M) [total revenue] | C7: Under-16 share (base) | D7: Under-16 rev BASE ($M) | E7: Low ($M) | F7: High ($M) | G7: Notes
A8: North America | B8: 3575.6 | C8: ='Assumptions'!$E$14*'Assumptions'!$B$26 | D8: =B8*C8*'Assumptions'!$B$34 | E8: =B8*C8*'Assumptions'!$B$33 | F8: =B8*C8*'Assumptions'!$B$35 | G8: Anchor; Snapchat skews very young (teens core)
A9: Europe | B9: 1128.4 | C9: ='Assumptions'!$E$14*'Assumptions'!$B$27 | D9: =B9*C9*'Assumptions'!$B$34 | E9: =B9*C9*'Assumptions'!$B$33 | F9: =B9*C9*'Assumptions'!$B$35 | G9: High teen penetration; ~99M DAU
A10: Rest of World | B10: 1227.4 | C10: ='Assumptions'!$E$14*'Assumptions'!$B$29 | D10: =B10*C10*'Assumptions'!$B$34 | E10: =B10*C10*'Assumptions'!$B$33 | F10: =B10*C10*'Assumptions'!$B$35 | G10: Includes Asia-Pacific; fast-growing, youngest base (254M DAU)
A11: TOTAL — Snap | B11: =SUM(B8:B10) | C11: =D11/B11 | D11: =SUM(D8:D10) | E11: =SUM(E8:E10) | F11: =SUM(F8:F10) | G11: Applied to total revenue (incl. ~$0.4B Snapchat+ subs)

Sheet Model - Pinterest
A1: UNDER-16 AD-REVENUE EXPOSURE MODEL — Pinterest, Inc.
A3: FY2025 total revenue ($M) | B3: 4222
A4: Q4-2025 global MAU (millions) | B4: 619
A5: Pinterest US under-16 ad-revenue share | B5: ='Assumptions'!$E$15
D6: Lowest exposure: 13–17 ≈ 4% of users; personalised ads restricted for under-18s
A7: Region | B7: Regional revenue ($M) [estimated] | C7: Under-16 share (base) | D7: Under-16 rev BASE ($M) | E7: Low ($M) | F7: High ($M) | G7: Notes
A8: US & Canada | B8: 3173 | C8: ='Assumptions'!$E$15*'Assumptions'!$B$26 | D8: =B8*C8*'Assumptions'!$B$34 | E8: =B8*C8*'Assumptions'!$B$33 | F8: =B8*C8*'Assumptions'!$B$35 | G8: Anchor; 79% female skew, Gen Z fastest-growing cohort
A9: Europe | B9: 775 | C9: ='Assumptions'!$E$15*'Assumptions'!$B$27 | D9: =B9*C9*'Assumptions'!$B$34 | E9: =B9*C9*'Assumptions'!$B$33 | F9: =B9*C9*'Assumptions'!$B$35 | G9: Larger MAU (145M) but lower ARPU
A10: Rest of World | B10: 274 | C10: ='Assumptions'!$E$15*'Assumptions'!$B$29 | D10: =B10*C10*'Assumptions'!$B$34 | E10: =B10*C10*'Assumptions'!$B$33 | F10: =B10*C10*'Assumptions'!$B$35 | G10: Includes Asia-Pacific; very low ARPU ($0.19 Q4)
A11: TOTAL — Pinterest | B11: =SUM(B8:B10) | C11: =D11/B11 | D11: =SUM(D8:D10) | E11: =SUM(E8:E10) | F11: =SUM(F8:F10) | G11: Regional split estimated from disclosed Q4 mix

Sheet Aggregate by Region
A1: AGGREGATE UNDER-16 AD-REVENUE EXPOSURE BY REGION (BASE case, $M)
A2: Cross-company view. Snap & Pinterest do not split Asia-Pacific, so their APAC users sit inside 'Rest of World'.
A4: Region | B4: Meta | C4: Google | D4: Snap | E4: Pinterest | F4: TOTAL ($M)
A5: North America | B5: ='Model - Meta'!D8 | C5: ='Model - Google'!D12+'Model - Google'!D20+'Model - Google'!D28*0.487 | D5: ='Model - Snap'!D8 | E5: ='Model - Pinterest'!D8 | F5: =SUM(B5:E5)
A6: Europe | B6: ='Model - Meta'!D9 | C6: ='Model - Google'!D13+'Model - Google'!D21+'Model - Google'!D28*0.292 | D6: ='Model - Snap'!D9 | E6: ='Model - Pinterest'!D9 | F6: =SUM(B6:E6)
A7: Asia-Pacific | B7: ='Model - Meta'!D10 | C7: ='Model - Google'!D14+'Model - Google'!D22+'Model - Google'!D28*0.162 | D7: 0 | E7: 0 | F7: =SUM(B7:E7)
A8: Rest of World | B8: ='Model - Meta'!D11 | C8: ='Model - Google'!D15+'Model - Google'!D23+'Model - Google'!D28*0.058 | D8: ='Model - Snap'!D10 | E8: ='Model - Pinterest'!D10 | F8: =SUM(B8:E8)
A9: TOTAL — all regions | B9: =SUM(B5:B8) | C9: =SUM(C5:C8) | D9: =SUM(D5:D8) | E9: =SUM(E5:E8) | F9: =SUM(F5:F8)
A11: Region as % of total under-16 exposure
A12: North America | B12: =F5/F9
A13: Europe | B13: =F6/F9
A14: Asia-Pacific | B14: =F7/F9
A15: Rest of World | B15: =F8/F9

Sheet Regulatory Headwind
A1: REGULATORY HEADWIND — UNDER-16 SOCIAL-MEDIA AGE BANS
A2: Quantifies the revenue / growth headwind from under-16 bans. 'At-risk' revenue = the slice of under-16 revenue a ban is estimated to remove. All inputs (blue) are editable.
A4: 1. Australia — Social Media Minimum Age Act (in force 10 Dec 2025; minimum age 16; fines up to A$49.5m)
A5: Issuer | B5: In scope? | C5: Covered surface(s) | D5: Excluded / note
A6: Meta | B6: YES | C6: Facebook, Instagram, Threads | D6: Messenger & WhatsApp are excluded (messaging)
A7: Google | B7: YES | C7: YouTube | D7: YouTube Kids, Search and Network are out of scope
A8: Snap | B8: YES | C8: Snapchat | D8: Entire app in scope — most exposed
A9: Pinterest | B9: NO | C9: — (excluded) | D9: eSafety: not an 'age-restricted social media platform'
A11: 2. Headwind model inputs (editable)
A12: Developed-market under-16 multiplier (vs US anchor) | C12: 0.97 | D12: Ban markets (AU/UK/EU/US) skew developed
A13: Cohort factor — under-16 regime (AU, UK, ES, PT) | C13: 1 | D13: Full under-16 cohort
A14: Cohort factor — under-15 regime (DK, FR, GR, NL...) | C14: 0.82 | D14: Removes only 0–14 (keeps 15s)
A15: Cohort factor — US (under-14 / parental-consent) | C15: 0.55 | D15: Narrower cohort, consent not a full ban
A16: Enforcement effectiveness — Australia (in force) | C16: 0.6 | D16: Age assurance imperfect; VPN/evasion leakage
A17: Enforcement effectiveness — EU/UK pipeline | C17: 0.55 | D17: Similar assurance regime once enacted
A18: Enforcement effectiveness — US (incl. litigation discount) | C18: 0.25 | D18: Many state laws enjoined on 1st-Amendment grounds
A20: 3. Meta — exposure base = ad revenue (FB+IG+Messenger); FY2025 total revenue $200,966m
A21: Jurisdiction basket | B21: Status | C21: Rev share | D21: Cohort | E21: Enforce | F21: Covered | G21: At-risk ($M) | H21: bps of rev
A22: Australia | B22: In force (10 Dec 2025) | C22: 0.018 | D22: =$C$13 | E22: =$C$16 | F22: 1 | G22: ='Model - Meta'!B12*C22*'Assumptions'!$B$22*$C$12*D22*E22*F22 | H22: =G22/200966.0*10000
A23: United Kingdom | B23: Consulting; target ~2027 | C23: 0.055 | D23: =$C$13 | E23: =$C$17 | F23: 1 | G23: ='Model - Meta'!B12*C23*'Assumptions'!$B$22*$C$12*D23*E23*F23 | H23: =G23/200966.0*10000
A24: EU pipeline | B24: DK/FR/GR/PT passed; ES/NO/NL/IT advancing | C24: 0.06 | D24: =$C$14 | E24: =$C$17 | F24: 1 | G24: ='Model - Meta'!B12*C24*'Assumptions'!$B$22*$C$12*D24*E24*F24 | H24: =G24/200966.0*10000
A25: US states | B25: FL/UT/TN enforceable; many enjoined | C25: 0.04 | D25: =$C$15 | E25: =$C$18 | F25: 1 | G25: ='Model - Meta'!B12*C25*'Assumptions'!$B$22*$C$12*D25*E25*F25 | H25: =G25/200966.0*10000
A26: All baskets (broad-adoption scenario) | G26: =SUM(G22:G25) | H26: =G26/200966.0*10000
A28: 3. Google — exposure base = YouTube ads (only covered surface); FY2025 total revenue $402,836m
A29: Jurisdiction basket | B29: Status | C29: Rev share | D29: Cohort | E29: Enforce | F29: Covered | G29: At-risk ($M) | H29: bps of rev
A30: Australia | B30: In force (10 Dec 2025) | C30: 0.02 | D30: =$C$13 | E30: =$C$16 | F30: 1 | G30: ='Model - Google'!B16*C30*'Assumptions'!$E$11*$C$12*D30*E30*F30 | H30: =G30/402836.0*10000
A31: United Kingdom | B31: Consulting; target ~2027 | C31: 0.06 | D31: =$C$13 | E31: =$C$17 | F31: 1 | G31: ='Model - Google'!B16*C31*'Assumptions'!$E$11*$C$12*D31*E31*F31 | H31: =G31/402836.0*10000
A32: EU pipeline | B32: DK/FR/GR/PT passed; ES/NO/NL/IT advancing | C32: 0.06 | D32: =$C$14 | E32: =$C$17 | F32: 1 | G32: ='Model - Google'!B16*C32*'Assumptions'!$E$11*$C$12*D32*E32*F32 | H32: =G32/402836.0*10000
A33: US states | B33: FL/UT/TN enforceable; many enjoined | C33: 0.04 | D33: =$C$15 | E33: =$C$18 | F33: 1 | G33: ='Model - Google'!B16*C33*'Assumptions'!$E$11*$C$12*D33*E33*F33 | H33: =G33/402836.0*10000
A34: All baskets (broad-adoption scenario) | G34: =SUM(G30:G33) | H34: =G34/402836.0*10000
A36: 3. Snap — exposure base = total revenue; FY2025 total revenue $5,931m
A37: Jurisdiction basket | B37: Status | C37: Rev share | D37: Cohort | E37: Enforce | F37: Covered | G37: At-risk ($M) | H37: bps of rev
A38: Australia | B38: In force (10 Dec 2025) | C38: 0.025 | D38: =$C$13 | E38: =$C$16 | F38: 1 | G38: ='Model - Snap'!B11*C38*'Assumptions'!$E$14*$C$12*D38*E38*F38 | H38: =G38/5931.0*10000
A39: United Kingdom | B39: Consulting; target ~2027 | C39: 0.04 | D39: =$C$13 | E39: =$C$17 | F39: 1 | G39: ='Model - Snap'!B11*C39*'Assumptions'!$E$14*$C$12*D39*E39*F39 | H39: =G39/5931.0*10000
A40: EU pipeline | B40: DK/FR/GR/PT passed; ES/NO/NL/IT advancing | C40: 0.05 | D40: =$C$14 | E40: =$C$17 | F40: 1 | G40: ='Model - Snap'!B11*C40*'Assumptions'!$E$14*$C$12*D40*E40*F40 | H40: =G40/5931.0*10000
A41: US states | B41: FL/UT/TN enforceable; many enjoined | C41: 0.05 | D41: =$C$15 | E41: =$C$18 | F41: 1 | G41: ='Model - Snap'!B11*C41*'Assumptions'!$E$14*$C$12*D41*E41*F41 | H41: =G41/5931.0*10000
A42: All baskets (broad-adoption scenario) | G42: =SUM(G38:G41) | H42: =G42/5931.0*10000
A44: 3. Pinterest — exposure base = total revenue; FY2025 total revenue $4,222m
A45: Jurisdiction basket | B45: Status | C45: Rev share | D45: Cohort | E45: Enforce | F45: Covered | G45: At-risk ($M) | H45: bps of rev
A46: Australia | B46: In force (10 Dec 2025) | C46: 0.02 | D46: =$C$13 | E46: =$C$16 | F46: 0 | G46: ='Model - Pinterest'!B11*C46*'Assumptions'!$E$15*$C$12*D46*E46*F46 | H46: =G46/4222.0*10000
...

Sheet Sources
A1: SOURCES
A2: # | B2: Source | C2: URL / reference
A3: 1 | B3: Meta FY2025 results (10-K / Q4-25 press release, Jan 2026) | C3: sec.gov/Archives/edgar/data/1326801/000162828026003832/meta-12312025xexhibit991.htm
A4: 2 | B4: Meta FY2024 results (prior-year comparison) | C4: sec.gov/Archives/edgar/data/1326801/000132680125000014/meta-12312024xexhibit991.htm
A5: 3 | B5: Alphabet FY2025 results (segment & geography, Feb 2026) | C5: sec.gov/Archives/edgar/data/1652044/000165204426000018/
A6: 4 | B6: Snap FY2025 results (regional rev, DAU, ARPU, Feb 2026) | C6: investor.snap.com — Q4 & FY2025 press release
A7: 5 | B7: Pinterest FY2025 results (full-year regional revenue, MAU, Feb 2026) | C7: investor.pinterestinc.com — Q4 & FY2025 press release
A8: 6 | B8: Raffoul, Ward, Santoso, Kavanaugh, Austin (2023). Social media platforms generate billions from US youth. PLOS ONE 18(12): e0295337. | C8: journals.plos.org/plosone/article?id=10.1371/journal.pone.0295337
A9: 7 | B9: Harvard T.H. Chan School news release on the above study | C9: hsph.harvard.edu/news/social-media-platforms-generate-billions-in-annual-ad-revenue-from-u-s-youth/
A10: 8 | B10: Ofcom — Children and parents: media use and attitudes 2024 | C10: ofcom.org.uk — Children's Media Literacy Report 2024
A11: 9 | B11: eSafety Commissioner (AU) — Social Media Minimum Age: which platforms are age-restricted | C11: esafety.gov.au/.../social-media-age-restrictions/which-platforms-are-age-restricted
A12: 10 | B12: eSafety Commissioner (AU) — Social Media Minimum Age FAQ (penalties, excluded services) | C12: esafety.gov.au/.../social-media-age-restrictions/faqs
A13: 11 | B13: AVPA — EU countries / US state age-assurance trackers (2026) | C13: avpassociation.com — EU & US state age-assurance laws
A14: 12 | B14: TechCrunch / Wired-Parents — global under-16 social-media ban trackers (2026) | C14: techcrunch.com/2026/04/23/social-media-ban-children-countries-list/
A15: 13 | B15: DataReportal / Pinterest ad-audience age profile | C15: datareportal.com/essential-pinterest-stats
B17: All financial figures are as-reported FY2024/FY2025. All age-specific revenue and ban-headwind figures are MODELLED estimates (no issuer discloses revenue by user age or by jurisdiction at this granularity).
