Workbook

Sheet Read Me
A1: Optical Names x Semiconductor Supply Chain - Equity Model
A2: 30-company universe, live comps, driver-based TAM model, exposure & thematic scoring | Market data as of 2026-07-30 (Yahoo Finance)
A4: PURPOSE
B5: Maps the listed optics/photonics ecosystem to the semiconductor supply chain along two axes: (1) optics that move data BETWEEN semiconductors - AI/datacenter transceivers, optical DSPs, CPO - and (2) optics that MAKE semiconductors - lithography light/optics, mask blanks, optical inspection & metrology. Includes a driver-based market model (accelerator units x attach x speed mix x ASP), live comps, per-company revenue-exposure scenarios to 2028E, thematic scoring and sensitivities.
A7: TAB GUIDE
A8: Tab | B8: What it contains
A9: Universe | B9: 30 names in 6 segments: who they are, role in the semi chain, key products/customers, one-line thesis.
A10: Supply Chain Map | B10: Stage-by-stage value chain - AI datacenter interconnect chain, fab-equipment optics chain, cross-cutting enablers - with universe tickers and key private players per stage.
A11: Market Model | B11: 2023A-2028E driver model: AI accelerator units x optics attach x speed mix (400G/800G/1.6T) x ASPs -> datacom optics TAM; CPO displacement; telecom optics; WFE-derived litho & inspection optics TAM. Blue cells are yours to flex.
A12: Comps | B12: Live valuation/financial comps in USD with segment medians: growth, margins, EV/S, EV/EBITDA, P/E, FCF yield, 1-yr return.
A13: Company Exposure | B13: Estimated revenue split (AI/datacom, fab-optics, telecom, other) per name; grows each bucket at Market Model CAGRs (+/- share shift) to a 2028E revenue scenario; implied CAGR and EV/2028E sales.
A14: Thematic Scores | B14: 0-5 scores across 8 themes, weighted composite (weights adjustable) and rank.
A15: Sensitivity | B15: 2028E datacom optics market grids: attach ratio x 1.6T ASP, and accelerator units x 1.6T mix.
A17: CONVENTIONS
A18: Blue font | B18: Input / assumption - flex these; everything downstream recalculates.
A19: Black font | B19: Formula or hard market data (pulled from Yahoo Finance).
A20: $ figures | B20: USD millions unless marked $B; non-USD names converted at spot FX on the as-of date.
A21: Exposure %s | B21: Analyst estimates of revenue mix - directional, not company-reported segment data.
A22: NM / blank | B22: Not meaningful (negative denominator) or data unavailable.
A24: DISCLAIMER
B25: For research/educational use. Market data via Yahoo Finance and may contain errors; exposure estimates and forecasts are analyst assumptions, not investment advice. Verify before use.

Sheet Universe
A1: Ticker | B1: Company | C1: Country | D1: Segment | E1: Sub-segment / niche | F1: Role in the semiconductor supply chain | G1: Key products | H1: Key customers / end markets | I1: Thesis in one line
A2: Datacom Transceivers & Optical Components
A3: COHR | B3: Coherent Corp. | C3: US | D3: Transceivers | E3: Vertically integrated photonics (InP lasers -> transceivers) | F3: Makes 800G/1.6T datacom transceivers, EML/CW lasers for SiPh, and optics/lasers used in semi cap equipment; also SiC materials. | G3: 800G/1.6T transceivers, EML & CW lasers, VCSELs, optical circuit switches, fab lasers | H3: Nvidia ecosystem, hyperscalers (MSFT/META/GOOG/AWS), telecom OEMs, semi cap OEMs | I3: One of two western vertically-integrated AI optics plays; indium-phosphide capacity is the scarce asset.
A4: LITE | B4: Lumentum Holdings | C4: US | D4: Transceivers | E4: Lasers & photonics; datacom components -> modules pivot | F4: EMLs and CW lasers that power 800G+/1.6T modules (incl. merchant sales to Chinese module makers); expanding own module + CPO laser sources. | G4: EML/CW/DFB lasers, 800G/1.6T modules, ROADMs/WSS, 3D-sensing VCSELs | H4: Chinese transceiver makers, hyperscalers, Ciena/telecom OEMs, Apple (3D sensing) | I4: Laser-chip bottleneck owner: sells picks-and-shovels to every 1.6T module vendor; external laser source play for CPO.
A5: AAOI | B5: Applied Optoelectronics | C5: US | D5: Transceivers | E5: Datacenter transceivers (vertically integrated, US/TW/CN fabs) | F5: 400G/800G transceivers to hyperscalers; 100G lasers; CATV amplifiers. Re-shoring US capacity narrative. | G5: 400G/800G/1.6T transceivers, DFB/EML lasers, CATV/HFC gear | H5: Microsoft, Amazon (historical), CATV MSOs | I5: High-beta share-recovery story on 800G qualification at US hyperscalers; execution & dilution risk.
A6: FN | B6: Fabrinet | C6: Thailand | D6: Transceivers | E6: Precision optical EMS (manufactures others' optics) | F6: Contract manufacturer of optical transceivers/engines - notably Nvidia's 800G/1.6T OSFP modules and coherent modules for Ciena/others. | G6: Optical module assembly & test, optical engines, sensors, automotive optics | H6: Nvidia (largest), Cisco/Acacia, Lumentum, Ciena, Infinera/Nokia | I6: Cleanest 'volume' play on AI optics units with fab-lite risk; Nvidia concentration is the swing factor.
A7: 300308.SZ | B7: Zhongji Innolight | C7: China | D7: Transceivers | E7: #1 global datacom transceiver vendor by share | F7: Largest supplier of 800G (and first-wave 1.6T) modules to US hyperscalers and Nvidia ecosystem. | G7: 800G/1.6T optical modules, SiPh modules, coherent modules | H7: Nvidia, Google, Meta, Amazon, Microsoft | I7: Volume leader of the AI optics cycle; geopolitical/tariff risk against dominant share and cost position.
A8: 300502.SZ | B8: Eoptolink | C8: China | D8: Transceivers | E8: Fast-follower transceiver vendor | F8: 800G/1.6T modules incl. silicon photonics variants; gaining share at US and Chinese cloud customers. | G8: 800G/1.6T modules (EML & SiPh), 400G, AOCs | H8: Nvidia ecosystem, hyperscalers, Chinese cloud (Alibaba/Tencent/ByteDance) | I8: Fastest-growing of the Chinese module trio into the 1.6T generation; similar geopolitical overhang.
A9: 300394.SZ | B9: Suzhou TFC Optical | C9: China | D9: Transceivers | E9: Passive optical components & optical engines | F9: Fiber-array units (FAU), lenses, AWGs and passive assemblies that go inside transceivers and CPO/optical-engine designs. | G9: FAUs, MT/MPO assemblies, lenses, AWG, WDM components, optical engines | H9: Innolight/Eoptolink & global module makers, SiPh/CPO programs | I9: Content-per-port winner as SiPh and CPO raise passive/fiber-coupling content; supplier to everyone.
A10: 002281.SZ | B10: Accelink Technologies | C10: China | D10: Transceivers | E10: State-linked Chinese optics incumbent (telecom-heavy) | F10: China domestic optical components/modules champion across telecom + datacom; localization beneficiary. | G10: Telecom lasers/detectors, 400G/800G datacom modules, amplifiers | H10: Huawei, ZTE, China carriers, Chinese cloud | I10: Play on China network capex + domestic substitution; less exposed to US AI capex than the private-sector trio.
A11: Optical Semiconductors (DSP / PHY / TIA / PIC)
A12: MRVL | B12: Marvell Technology | C12: US | D12: Optical Semis | E12: PAM4 optical DSP leader + custom AI silicon | F12: Dominant merchant PAM4 DSP franchise (inherited from Inphi) inside 800G/1.6T modules; coherent DSPs (COLORZ/ZR); custom XPUs. | G12: PAM4 DSPs, 800ZR/coherent DSPs, TIAs/drivers, custom AI ASICs, switches | H12: All major module makers, hyperscalers (custom silicon) | I12: Every pluggable needs a DSP - Marvell taxes the whole module ecosystem; LPO/LRO and Broadcom are the share risks.
A13: AVGO | B13: Broadcom | C13: US | D13: Optical Semis | E13: Switch silicon + DSP + first-mover CPO | F13: Tomahawk switch ASICs set the port cadence that drives optics demand; sells optical DSPs, VCSELs/EMLs; shipping co-packaged optics (Bailly/TH6). | G13: Tomahawk/Jericho switch ASICs, PAM4 DSPs, CPO optical engines, custom XPUs | H13: Hyperscalers, Arista/OEMs, module makers | I13: Controls the switch roadmap that paces every optics upgrade; best-positioned if CPO displaces pluggables (small % of revenue today).
A14: CRDO | B14: Credo Technology | C14: US | D14: Optical Semis | E14: SerDes house: AECs, optical DSPs, LRO | F14: Active electrical cables (AEC) for in-rack + optical DSPs incl. low-power LRO variants that compete on power/cost in AI clusters. | G14: AECs, PAM4 optical DSPs, LRO/linear optics DSPs, retimers, chiplets | H14: Hyperscalers (MSFT/AMZN/xAI et al.), module partners | I14: Power-efficiency angle on AI interconnect; AECs cannibalize short optics but optical DSP line ties it to the module chain.
A15: MTSI | B15: MACOM Technology | C15: US | D15: Optical Semis | E15: Analog/photonic semis: TIAs, drivers, lasers | F15: High-performance analog front-ends (TIA/driver) and laser/photodiode chips for 800G+/1.6T and linear-drive (LPO) optics. | G15: TIAs, modulator drivers, CDRs, lasers/PDs, RF/microwave (defense) | H15: Module makers, telecom OEMs, defense primes | I15: Linear-drive optics needs better analog, not DSPs - MACOM wins either architecture; diversified by defense/industrial.
A16: SMTC | B16: Semtech | C16: US | D16: Optical Semis | E16: FiberEdge TIAs/drivers + CopperEdge | F16: TIA/driver content in 800G/1.6T modules (FiberEdge); CopperEdge linear redrivers for ACCs; LoRa/IoT rest of business. | G16: FiberEdge TIAs & drivers, CopperEdge, LoRa, protection ICs | H16: Module makers, hyperscaler cable programs, IoT | I16: Under-appreciated analog content per optical port; data-center now the growth engine after LoRa/IoT reset.
A17: ALAB | B17: Astera Labs | C17: US | D17: Optical Semis | E17: Connectivity silicon (PCIe/CXL/Ethernet retimers -> optical) | F17: Retimers/smart cables inside AI servers; scale-up fabric silicon (Scorpio) with a roadmap into optical interconnect (PCIe-over-optics). | G17: Aries retimers, Taurus AECs, Leo CXL, Scorpio fabric switches | H17: Nvidia-based server OEMs, hyperscalers, AMD platforms | I17: Adjacent today (mostly electrical), but the designated optical on-ramp is PCIe/scale-up over optics - watch Aries optical variants.
A18: POET | B18: POET Technologies | C18: Canada | D18: Optical Semis | E18: Optical interposer / optical engines (speculative) | F18: Wafer-level optical interposer platform for 800G/1.6T optical engines and external light sources; pre-scale revenue. | G18: Optical interposers, 800G/1.6T optical engines, light-source modules | H18: Module partners (Foxconn Interconnect, Mitsubishi et al.), design wins ramping | I18: Optionality bet on chiplet-style optics packaging; binary execution risk, watch dilution.
A19: Lithography & Light-Source Optics
A20: ASML | B20: ASML Holding | C20: Netherlands | D20: Litho Optics | E20: EUV/DUV lithography monopoly (optics from Zeiss SMT) | F20: The single most important optical system in semis: EUV scanners (13.5nm light, Zeiss mirrors, Cymer LPP source). High-NA ramping. | G20: EUV (NXE/EXE High-NA), DUV immersion, metrology/inspection (YieldStar) | H20: TSMC, Samsung, Intel, SK Hynix, Micron | I20: Effective monopoly on the optics that define leading-edge logic/DRAM; AI capex flows through to litho intensity.
A21: 7731.T | B21: Nikon | C21: Japan | D21: Litho Optics | E21: ArF/KrF immersion litho #2; in-house optics | F21: Only non-ASML immersion DUV supplier; precision optics/measurement; exposure tools for packaging/panel. | G21: ArF-i/KrF scanners, digital-litho for advanced packaging, optical components, cameras | H21: Intel (historic), memory fabs, OSATs, panel makers | I21: Deep value on DUV + advanced-packaging lithography optionality; imaging funds the semi business.
A22: 7751.T | B22: Canon | C22: Japan | D22: Litho Optics | E22: KrF/i-line litho + nanoimprint (NIL) challenger | F22: Volume KrF/i-line tools for mature nodes & packaging; nanoimprint litho as a disruptive (non-optical projection) alternative. | G22: KrF/i-line steppers, FPA packaging litho, nanoimprint systems, imaging/printing | H22: Mature-node fabs, memory (NIL pilot), OSATs | I22: Mature-node capex + NIL optionality inside a printing/imaging conglomerate - diluted but real semi-optics exposure.
A23: 6925.T | B23: Ushio | C23: Japan | D23: Litho Optics | E23: Industrial light sources; EUV mask-inspection source | F23: Excimer/UV lamps and lasers across litho/anneal/cure steps; light source for actinic EUV mask inspection (Lasertec ecosystem). | G23: Excimer lamps/lasers, UV cure/exposure sources, EPL/EUV-related sources | H23: Semi cap OEMs (incl. Lasertec), panel, life science | I23: Hidden light-source content across many fab steps; levered to EUV mask-inspection buildout.
A24: 7741.T | B24: Hoya | C24: Japan | D24: Litho Optics | E24: EUV mask blanks near-monopoly; photomasks | F24: Dominant supplier of EUV mask blanks (multilayer-coated low-defect substrates) and large-share DUV blanks/photomasks. | G24: EUV/DUV mask blanks, photomasks, glass substrates, healthcare optics | H24: TSMC/Samsung/Intel mask shops, merchant mask makers | I24: Every EUV layer starts on a Hoya blank; healthcare (~60%) stabilizes the cyclicality.
A25: Optical Inspection & Metrology
A26: KLAC | B26: KLA Corp. | C26: US | D26: Inspection | E26: Process control leader (optical inspection & metrology) | F26: Broadband-plasma & laser-scanning optical wafer inspection, overlay/film metrology, reticle inspection - yield gatekeeper for leading edge. | G26: BBP inspection (39xx), laser scanning, overlay, mask inspection, packaging inspection | H26: TSMC, Samsung, Intel, memory, OSATs | I26: Process-control intensity rises with EUV layers and advanced packaging (HBM) - KLA is the toll booth.
A27: 6920.T | B27: Lasertec | C27: Japan | D27: Inspection | E27: Actinic (EUV-light) mask inspection monopoly | F27: Only supplier of actinic patterned-mask inspection (ACTIS) using 13.5nm light; EUV blank inspection (ABICS). | G27: ACTIS A300+, ABICS, MATRICS, wafer/photomask inspection | H27: TSMC, Samsung, Intel, Hoya/mask shops | I27: Pure monopoly on EUV mask actinic inspection; order lumpiness + short-seller history = volatility around a real franchise.
A28: ONTO | B28: Onto Innovation | C28: US | D28: Inspection | E28: Metrology + advanced-packaging inspection | F28: Optical film/OCD metrology and the leading inspection franchise for advanced packaging/HBM (Dragonfly). | G28: Dragonfly G3 (packaging inspection), Atlas OCD, IMPULSE, lithography for panel-level packaging | H28: TSMC (CoWoS), HBM makers (SK Hynix/Micron/Samsung), OSATs | I28: The most direct optics play on CoWoS/HBM inspection intensity - AI packaging is its growth engine.
A29: CAMT | B29: Camtek | C29: Israel | D29: Inspection | E29: Advanced-packaging optical inspection & metrology | F29: 2D/3D optical inspection of HBM stacks, interposers, chiplets - direct beneficiary of AI packaging capacity adds. | G29: Eagle G5/Hawk inspection, metrology for bumps/TSVs/hybrid bonding | H29: HBM makers, OSATs (ASE/Amkor), CoWoS chain | I29: Small-cap pure play on the same HBM/CoWoS inspection theme as Onto; high growth, customer-concentrated.
A30: NVMI | B30: Nova Ltd. | C30: Israel | D30: Inspection | E30: Dimensional & materials metrology (optical + X-ray) | F30: Optical CD/film metrology embedded in process tools plus stand-alone; gains content with gate-all-around & advanced packaging. | G30: Nova Prism (OCD), Ancolt/Metrion, chemical & X-ray metrology | H30: TSMC, Samsung, Intel, memory | I30: Metrology intensity compounder at leading edge; consistently outgrows WFE.
A31: Substrates, Materials & Lasers
A32: AXTI | B32: AXT Inc. | C32: US | D32: Materials | E32: InP / GaAs / Ge compound-semi substrates | F32: Indium-phosphide substrates are the starting wafer for EML/CW lasers and photodetectors in every high-speed optical link. | G32: InP, GaAs, Ge substrates; raw materials JVs | H32: Laser/PD chip makers (Lumentum/Coherent/Landmark etc.), China photonics chain | I32: Upstream-most listed play on InP tightness from 1.6T lasers & CPO light sources; China-heavy footprint is the risk.
A33: GLW | B33: Corning | C33: US | D33: Materials | E33: Optical fiber/cable & specialty glass | F33: Fiber, cable and connectivity for hyperscale/AI datacenters (enterprise segment growing fast); EUV/optics glass; display. | G33: Optical fiber & cable, datacenter connectivity, Gorilla glass, life-science optics | H33: Hyperscalers, carriers, Apple, display makers | I33: AI datacenters need 2-5x the fiber of classic clouds; optical is now Corning's growth engine (Springboard plan).
A34: IPGP | B34: IPG Photonics | C34: US | D34: Materials | E34: Fiber lasers (industrial; semi-adjacent) | F34: Fiber lasers used in wafer/panel processing (anneal, dicing, drilling, marking) and micromachining for electronics & packaging. | G34: High-power fiber lasers, pulsed lasers for micro-processing, telecom components (legacy) | H34: Industrial/EV, electronics & semi-packaging toolmakers | I34: Peripheral but real: laser processing content in advanced packaging; mostly an industrial cycle play with net cash.
A35: Optical Systems & EMS
A36: CIEN | B36: Ciena | C36: US | D36: Systems/EMS | E36: Coherent optical networking systems & pluggables | F36: WaveLogic coherent DSP/modems interconnect datacenters (DCI/metro); 800ZR coherent pluggables carry AI traffic between sites. | G36: WaveLogic 6 (1.6T coherent), Waveserver DCI, RLS line systems, coherent pluggables | H36: Hyperscalers (>50% of orders), carriers (AT&T/Verizon), cable | I36: Inter-datacenter leg of AI networking: cloud now the majority customer; coherent-lite/800ZR expands the served market.
A37: CLS | B37: Celestica | C37: Canada | D37: Systems/EMS | E37: Hyperscaler networking hardware (ODM/EMS) | F37: Designs/builds 800G (and 1.6T-ready) Ethernet switches and AI server/storage systems for hyperscalers - each switch port pulls optics. | G37: 800G switches (HPS), AI compute/storage systems, industrial EMS | H37: Google, Meta, AWS + other hyperscalers | I37: Switch-box winner of AI networking: optics-adjacent volume compounding, re-rated from EMS to ODM multiple.

Sheet Supply Chain Map
A1: Optical value chains through the semiconductor ecosystem
A3: A. AI DATACENTER OPTICAL INTERCONNECT CHAIN (optics that move data between semiconductors)
A4: # | B4: Value-chain stage | C4: What it is / why it matters | D4: Universe names (tickers) | E4: Key private / non-universe players | F4: Bottlenecks & notes
A5: 1 | B5: III-V & SiPh substrates | C5: InP substrates are the starting wafer for EML/CW lasers & photodetectors; SOI wafers for silicon photonics. | D5: AXTI | E5: Sumitomo Electric, JX Metals, IQE, Soitec (SOI) | F5: InP 4"->6" transition is the gating capacity item for 1.6T lasers and CPO light sources.
A6: 2 | B6: Laser & modulator chips (EML / CW / VCSEL) | C6: The light engines: EMLs for 200G/lane pluggables, high-power CW lasers feeding silicon photonics and CPO. | D6: LITE, COHR, AVGO, MTSI | E6: Mitsubishi Electric, Sumitomo Electric, Landmark, SEDI | F6: 200G/lane EML yield is the industry-wide constraint; CW laser reliability governs CPO adoption.
A7: 3 | B7: Photonic ICs / silicon photonics | C7: Integrates modulators/detectors/waveguides on silicon; the platform for 1.6T DR/FR modules and optical engines. | D7: AVGO, MRVL, COHR, POET | E7: GlobalFoundries, Tower Semiconductor, TSMC (COUPE), imec | F7: Foundry SiPh PDK maturity determines who can play; laser attach/packaging is the yield battleground.
A8: 4 | B8: Analog front-end (TIA / driver / CDR) | C8: Amplifies photodiode current and drives modulators; linear-drive (LPO/LRO) architectures raise analog content. | D8: SMTC, MTSI | E8: Analog Devices, in-house at Broadcom/Marvell | F8: LPO shifts BOM value from DSP to analog - watch architecture wins at 1.6T.
A9: 5 | B9: PAM4 DSP / optical PHY | C9: Retimes and equalizes the electrical-optical interface; the highest-value chip inside a pluggable module. | D9: MRVL, AVGO, CRDO | E9: In-house hyperscaler efforts | F9: Duopoly-plus-one (MRVL/AVGO/CRDO); 3nm DSP tapeouts pace the 1.6T ramp.
A10: 6 | B10: Passive optics & fiber coupling | C10: FAUs, lenses, AWG mux/demux, MPO connectors - content per port rises sharply with SiPh and CPO. | D10: 300394.SZ, FN, GLW | E10: Browave, Senko, US Conec | F10: Fiber-array alignment capacity is a quiet bottleneck for CPO scale-up.
A11: 7 | B11: Transceiver module design & assembly | C11: Turns chips+optics into 800G/1.6T pluggables; the most visible P&L beneficiary of AI optics capex. | D11: 300308.SZ, 300502.SZ, COHR, LITE, AAOI, 002281.SZ | E11: Hisense Broadband, HG Genuine, Source Photonics | F11: Chinese trio holds ~60% share of hyperscaler pluggables; tariffs/export rules are the key swing factor.
A12: 8 | B12: Optical EMS / contract manufacturing | C12: Precision optical assembly & test at scale for chip vendors and systems OEMs (incl. Nvidia optics). | D12: FN, CLS | E12: Venture Corp, Benchmark | F12: Fabrinet is the de-facto standard for high-mix optical assembly; capacity additions track AI demand.
A13: 9 | B13: Switching, DCI & coherent systems | C13: Switch boxes whose port counts pull optics demand; coherent systems/pluggables link datacenters together. | D13: CLS, CIEN | E13: Arista, Nvidia (Spectrum-X/Quantum), Cisco, Nokia(Infinera) | F13: Switch ASIC cadence (51.2T->102.4T) sets the optics upgrade clock; 800ZR blurs telecom/datacom.
A14: 10 | B14: End demand: AI accelerators & hyperscalers | C14: GPU/XPU cluster architectures determine attach ratios (scale-out, and now scale-up going optical). | D14: - | E14: Nvidia, AMD, Google TPU, AWS Trainium, Microsoft, Meta | F14: Scale-up networks moving from copper to optics is the biggest upside optionality in the model.
A16: B. SEMICONDUCTOR FAB OPTICS CHAIN (optics that make semiconductors)
A17: # | B17: Value-chain stage | C17: What it is / why it matters | D17: Universe names (tickers) | E17: Key private / non-universe players | F17: Bottlenecks & notes
A18: 1 | B18: Lithography light sources | C18: DUV excimer lasers (KrF/ArF) and EUV LPP sources (CO2 laser + tin plasma) that generate the exposure light. | D18: ASML (Cymer), 6925.T | E18: Gigaphoton (Komatsu) | F18: EUV source power (>500W) gates High-NA throughput; excimer duopoly Cymer/Gigaphoton.
A19: 2 | B19: Projection & illumination optics | C19: The most precise optics made: EUV mirror sets (sub-nm figure error) and ArF immersion lens columns. | D19: 7731.T, 7751.T (in-house) | E19: Zeiss SMT (ASML's optics partner, private) | F19: Zeiss SMT is a sole-source choke point for EUV mirrors - unlisted, accessed via ASML.
A20: 3 | B20: Photomask blanks, pellicles & photomasks | C20: EUV blanks (40+ multilayer coatings, near-zero defects), DUV blanks, pellicles protecting masks in the scanner. | D20: 7741.T | E20: AGC, Mitsui Chemicals (pellicles), Toppan/DNP (masks) | F20: Hoya ~near-monopoly in EUV blanks; blank defectivity feeds straight into Lasertec/KLA inspection demand.
A21: 4 | B21: Lithography systems | C21: Scanner/stepper integration - the optical system that prints every transistor. | D21: ASML, 7731.T, 7751.T | E21: SMEE (China, embargoed at leading edge) | F21: ASML monopoly at EUV; DUV export controls reshape China demand for Nikon/Canon mature tools.
A22: 5 | B22: Mask & blank inspection (actinic) | C22: Inspecting EUV masks with EUV light itself - the only way to see printable phase defects. | D22: 6920.T, KLAC | E22: - | F22: Lasertec ACTIS is sole-source actinic patterned-mask inspection; KLA competes at DUV/e-beam.
A23: 6 | B23: Wafer inspection & optical metrology | C23: Broadband-plasma/laser inspection, OCD & overlay metrology - yield control for EUV nodes, GAA and HBM. | D23: KLAC, ONTO, NVMI, CAMT | E23: Applied Materials (PDC), Hitachi High-Tech (e-beam) | F23: Process-control intensity rises with EUV layer count and advanced packaging - structural share of WFE grows.
A24: 7 | B24: Laser processing in fab & packaging | C24: Annealing, wafer dicing/grooving, via drilling, marking - laser steps throughout front & back end. | D24: IPGP, COHR | E24: DISCO, Hamamatsu, Amada/Via Mechanics | F24: Advanced packaging (CoWoS/HBM) adds laser drilling/dicing content per wafer.
A26: C. CROSS-CUTTING ENABLERS
A27: # | B27: Value-chain stage | C27: What it is / why it matters | D27: Universe names (tickers) | E27: Key private / non-universe players | F27: Bottlenecks & notes
A28: 1 | B28: Optical fiber, cable & connectivity | C28: Intra/inter-datacenter fiber plant; AI clusters need 2-5x the fiber of classic cloud halls. | D28: GLW | E28: Prysmian, CommScope, Amphenol (connectivity) | F28: Pre-terminated high-density fiber (MPO trunks) is a hidden AI capex line-item.
A29: 2 | B29: Co-packaged optics (CPO) ecosystem | C29: Optical engines mounted beside the switch/XPU die; replaces pluggables at highest speeds. | D29: AVGO, MRVL, COHR, LITE, 300394.SZ, POET | E29: Nvidia (Quantum-X/Spectrum-X photonics), TSMC COUPE | F29: CPO shifts value: less pluggable assembly, more laser sources (external light), fiber coupling and foundry SiPh.
A30: 3 | B30: Optical test & measurement | C30: Module/link test at 200G-per-lane; test intensity per port rises with speed. | D30: - | E30: EXFO, Viavi, Keysight, Yokogawa | F30: Test capacity often gates module shipment ramps in tight quarters.

Sheet Market Model
A1: AI / Datacom + Fab-Equipment Optics: Driver-Based Market Model
A2: Blue = input assumption (flex freely). All $ in millions unless marked $B.
A4: Driver / line item | B4: Units | C4: 2023A | D4: 2024A | E4: 2025E | F4: 2026E | G4: 2027E | H4: 2028E | I4: YoY assump. | J4: Notes
A5: 1. AI / DATACOM OPTICAL TRANSCEIVER DEMAND
A6: AI accelerator shipments (GPU + custom XPU) | B6: M units | C6: 3.9 | D6: 6.5 | E6: 9.5 | F6: 12.5 | G6: 15.5 | H6: 18 | J6: Nvidia + AMD + hyperscaler ASICs; the primary demand driver.
A7: YoY growth | B7: % | D7: =IFERROR(D6/C6-1,"") | E7: =IFERROR(E6/D6-1,"") | F7: =IFERROR(F6/E6-1,"") | G7: =IFERROR(G6/F6-1,"") | H7: =IFERROR(H6/G6-1,"")
A8: Optical ports per accelerator (attach ratio) | B8: ports/unit | C8: 2 | D8: 2.4 | E8: 2.8 | F8: 3 | G8: 3.3 | H8: 3.5 | J8: Scale-out today; rises as scale-up fabrics go optical. Key swing input.
A9: AI-driven optical ports | B9: M units | C9: =(C6*C8) | D9: =(D6*D8) | E9: =(E6*E8) | F9: =(F6*F8) | G9: =(G6*G8) | H9: =(H6*H8) | J9: Formula: accelerators x attach ratio
A10: Non-AI datacom ports (classic cloud/enterprise) | B10: M units | C10: 10 | D10: =C10*(1+$I$10) | E10: =D10*(1+$I$10) | F10: =E10*(1+$I$10) | G10: =F10*(1+$I$10) | H10: =G10*(1+$I$10) | I10: 0.08 | J10: 2023 base is input; grows at rate in col I.
A11: Total datacom optical ports | B11: M units | C11: =C9+C10 | D11: =D9+D10 | E11: =E9+E10 | F11: =F9+F10 | G11: =G9+G10 | H11: =H9+H10
A13: 2. PORT SPEED MIX (% of total ports)
A14: <= 400G | B14: % mix | C14: 0.7 | D14: 0.45 | E14: 0.3 | F14: 0.2 | G14: 0.12 | H14: 0.08 | J14: Legacy speeds fade but never fully disappear.
A15: 800G | B15: % mix | C15: 0.3 | D15: 0.55 | E15: 0.6 | F15: 0.55 | G15: 0.48 | H15: 0.4 | J15: Workhorse speed of the 2024-2027 build.
A16: 1.6T | B16: % mix | C16: 0 | D16: 0 | E16: 0.1 | F16: 0.25 | G16: 0.4 | H16: 0.52 | J16: Ramps with GB300/Rubin-class systems and 102.4T switching.
A17: Mix check (must = 100%) | B17: % | C17: =SUM(C14:C16) | D17: =SUM(D14:D16) | E17: =SUM(E14:E16) | F17: =SUM(F14:F16) | G17: =SUM(G14:G16) | H17: =SUM(H14:H16)
A19: 3. ASPs ($ per port; first year input, then declines at rate in col I)
A20: <= 400G ASP | B20: $/port | C20: 350 | D20: =C20*(1+$I$20) | E20: =D20*(1+$I$20) | F20: =E20*(1+$I$20) | G20: =F20*(1+$I$20) | H20: =G20*(1+$I$20) | I20: -0.15 | J20: Mature product; steady price erosion.
A21: 800G ASP | B21: $/port | C21: 950 | D21: =C21*(1+$I$21) | E21: =D21*(1+$I$21) | F21: =E21*(1+$I$21) | G21: =F21*(1+$I$21) | H21: =G21*(1+$I$21) | I21: -0.12 | J21: EML-based OSFP; SiPh variants cheaper.
A22: 1.6T ASP | B22: $/port | E22: 1700 | F22: =E22*(1+$I$22) | G22: =F22*(1+$I$22) | H22: =G22*(1+$I$22) | I22: -0.18 | J22: Enters 2025; fastest erosion as SiPh scales.
A24: 4. DATACOM OPTICAL TRANSCEIVER MARKET ($M)
A25: <= 400G revenue | B25: $M | C25: =C11*C14*N(C20) | D25: =D11*D14*N(D20) | E25: =E11*E14*N(E20) | F25: =F11*F14*N(F20) | G25: =G11*G14*N(G20) | H25: =H11*H14*N(H20) | J25: Formula: total ports x mix x ASP (M units x $ = $M)
A26: 800G revenue | B26: $M | C26: =C11*C15*N(C21) | D26: =D11*D15*N(D21) | E26: =E11*E15*N(E21) | F26: =F11*F15*N(F21) | G26: =G11*G15*N(G21) | H26: =H11*H15*N(H21) | J26: Formula: total ports x mix x ASP (M units x $ = $M)
A27: 1.6T revenue | B27: $M | C27: =C11*C16*N(C22) | D27: =D11*D16*N(D22) | E27: =E11*E16*N(E22) | F27: =F11*F16*N(F22) | G27: =G11*G16*N(G22) | H27: =H11*H16*N(H22) | J27: Formula: total ports x mix x ASP (M units x $ = $M)
A28: Total datacom transceiver market | B28: $M | C28: =SUM(C25:C27) | D28: =SUM(D25:D27) | E28: =SUM(E25:E27) | F28: =SUM(F25:F27) | G28: =SUM(G25:G27) | H28: =SUM(H25:H27)
A29: YoY growth | B29: % | D29: =IFERROR(D28/C28-1,"") | E29: =IFERROR(E28/D28-1,"") | F29: =IFERROR(F28/E28-1,"") | G29: =IFERROR(G28/F28-1,"") | H29: =IFERROR(H28/G28-1,"")
A31: 5. CO-PACKAGED OPTICS (CPO) DISPLACEMENT
A32: CPO share of 1.6T ports | B32: % of 1.6T | C32: 0 | D32: 0 | E32: 0 | F32: 0.02 | G32: 0.06 | H32: 0.12 | J32: Nvidia Quantum-X/Spectrum-X photonics + Broadcom Bailly ramp.
A33: Pluggable revenue displaced by CPO | B33: $M | C33: =C27*C32 | D33: =D27*D32 | E33: =E27*E32 | F33: =F27*F32 | G33: =G27*G32 | H33: =H27*H32 | J33: Formula: 1.6T revenue x CPO share
A34: Net pluggable transceiver market | B34: $M | C34: =C28-C33 | D34: =D28-D33 | E34: =E28-E33 | F34: =F28-F33 | G34: =G28-G33 | H34: =H28-H33 | J34: What the module makers (Comps: Transceivers segment) actually ship.
A36: 6. TELECOM OPTICS (components + modules)
A37: Telecom optics growth | B37: % YoY | D37: -0.08 | E37: 0.04 | F37: 0.07 | G37: 0.06 | H37: 0.05 | J37: 2024 inventory digestion, then 400ZR/800ZR-led recovery.
A38: Telecom optics market | B38: $M | C38: 14000 | D38: =C38*(1+D37) | E38: =D38*(1+E37) | F38: =E38*(1+F37) | G38: =F38*(1+G37) | H38: =G38*(1+H37) | J38: 2023 base input.
A40: 7. SEMICONDUCTOR FAB OPTICS (equipment chain, $B)
A41: Wafer fab equipment (WFE) spend | B41: $B | C41: 95 | D41: 105 | E41: 118 | F41: 130 | G41: 140 | H41: 150 | J41: AI/leading-edge logic + HBM led cycle.
A42: Lithography share of WFE | B42: % | C42: 0.22 | D42: 0.23 | E42: 0.23 | F42: 0.24 | G42: 0.24 | H42: 0.24 | J42: EUV mix pushes litho share up over time.
A43: Lithography systems market | B43: $B | C43: =C41*C42 | D43: =D41*D42 | E43: =E41*E42 | F43: =F41*F42 | G43: =G41*G42 | H43: =H41*H42
A44: Optics + light-source content of litho tools | B44: % | C44: 0.33 | D44: 0.34 | E44: 0.34 | F44: 0.35 | G44: 0.35 | H44: 0.35 | J44: Zeiss optics + Cymer source ~1/3 of an EUV tool's value.
A45: Litho optics & source content | B45: $B | C45: =C43*C44 | D45: =D43*D44 | E45: =E43*E44 | F45: =F43*F44 | G45: =G43*G44 | H45: =H43*H44
A46: Process control share of WFE | B46: % | C46: 0.105 | D46: 0.11 | E46: 0.11 | F46: 0.115 | G46: 0.115 | H46: 0.12 | J46: Rises with EUV layers & advanced packaging.
A47: Process control market | B47: $B | C47: =C41*C46 | D47: =D41*D46 | E47: =E41*E46 | F47: =F41*F46 | G47: =G41*G46 | H47: =H41*H46
...

Sheet Comps
A1: Valuation & Financial Comps (USD, converted at spot FX)
A2: Values pulled from Yahoo Finance; EV, multiples, yields and medians are live formulas.
A4: Ticker | B4: Company | C4: Segment | D4: Ccy | E4: Price (local) | F4: Mkt Cap $M | G4: Net Debt $M | H4: EV $M | I4: Rev TTM $M | J4: Rev Grw YoY | K4: Gross Mgn | L4: EBITDA Mgn | M4: Op Mgn | N4: EBITDA $M | O4: EV / Sales | P4: EV / EBITDA | Q4: P/E (fwd) | R4: FCF $M | S4: FCF Yield | T4: 1Y Return | U4: % off 52w High | V4: Beta
A5: Datacom Transceivers & Optical Components
A6: COHR | B6: Coherent Corp. | C6: Transceivers | D6: USD | E6: 246.29 | F6: 48142.926 | G6: 1001.385 | H6: =IF(F6="","",F6+N(G6)) | I6: 6602.0838 | J6: 0.205 | K6: 0.36990002 | L6: 0.19899 | M6: 0.13572 | N6: 1313.732 | O6: =IFERROR(IF(I6>0,H6/I6,"NM"),"NM") | P6: =IFERROR(IF(N6>0,H6/N6,"NM"),"NM") | Q6: 29.683062 | R6: -197.63174 | S6: =IFERROR(IF(AND(R6<>"",F6>0),R6/F6,""),"") | T6: 1.2948801 | U6: -0.44025 | V6: 2.037
A7: LITE | B7: Lumentum Holdings | C7: Transceivers | D7: USD | E7: 682 | F7: 53059.6 | G7: 141.40006 | H7: =IF(F7="","",F7+N(G7)) | I7: 2488.3999 | J7: 0.901 | K7: 0.40837002 | L7: 0.20447001 | M7: 0.21771 | N7: 508.8 | O7: =IFERROR(IF(I7>0,H7/I7,"NM"),"NM") | P7: =IFERROR(IF(N7>0,H7/N7,"NM"),"NM") | Q7: 37.156635 | R7: 93.35 | S7: =IFERROR(IF(AND(R7<>"",F7>0),R7/F7,""),"") | T7: 5.2082384 | U7: -0.37182227 | V7: 1.482
A8: AAOI | B8: Applied Optoelectronics | C8: Transceivers | D8: USD | E8: 89.52 | F8: 7183.3324 | G8: -159.28298 | H8: =IF(F8="","",F8+N(G8)) | I8: 507 | J8: 0.514 | K8: 0.29642 | L8: -0.05415 | M8: -0.08595 | N8: -27.456 | O8: =IFERROR(IF(I8>0,H8/I8,"NM"),"NM") | P8: =IFERROR(IF(N8>0,H8/N8,"NM"),"NM") | Q8: 18.75943 | R8: -445.58326 | S8: =IFERROR(IF(AND(R8<>"",F8>0),R8/F8,""),"") | T8: 2.8820468 | U8: -0.61689562 | V8: 3.687
A9: FN | B9: Fabrinet | C9: Transceivers | D9: USD | E9: 437.08 | F9: 15660.462 | G9: -940.81097 | H9: =IF(F9="","",F9+N(G9)) | I9: 4235.0011 | J9: 0.393 | K9: 0.12037 | L9: 0.11327 | M9: 0.098859996 | N9: 479.712 | O9: =IFERROR(IF(I9>0,H9/I9,"NM"),"NM") | P9: =IFERROR(IF(N9>0,H9/N9,"NM"),"NM") | Q9: 25.234793 | R9: -79.178376 | S9: =IFERROR(IF(AND(R9<>"",F9>0),R9/F9,""),"") | T9: 0.36306362 | U9: -0.41636288 | V9: 1.198
A10: 300308.SZ | B10: Zhongji Innolight | C10: Transceivers | D10: CNY | E10: 864 | F10: 142654.94 | G10: -1554.5831 | H10: =IF(F10="","",F10+N(G10)) | I10: 7559.7243 | J10: 1.921 | K10: 0.44032001 | L10: 0.39240003 | M10: 0.39813 | N10: 2966.4033 | O10: =IFERROR(IF(I10>0,H10/I10,"NM"),"NM") | P10: =IFERROR(IF(N10>0,H10/N10,"NM"),"NM") | Q10: 13.819136 | R10: 616.21564 | S10: =IFERROR(IF(AND(R10<>"",F10>0),R10/F10,""),"") | T10: 3.5256546 | U10: -0.39020947 | V10: 1.38
A11: 300502.SZ | B11: Eoptolink | C11: Transceivers | D11: CNY | E11: 371.1 | F11: 76602.067 | G11: -1170.07 | H11: =IF(F11="","",F11+N(G11)) | I11: 4312.3103 | J11: 1.058 | K11: 0.47421002 | L11: 0.44657 | M11: 0.46001 | N11: 1925.7672 | O11: =IFERROR(IF(I11>0,H11/I11,"NM"),"NM") | P11: =IFERROR(IF(N11>0,H11/N11,"NM"),"NM") | Q11: 8.861243 | R11: 481.6949 | S11: =IFERROR(IF(AND(R11<>"",F11>0),R11/F11,""),"") | T11: 2.1034968 | U11: -0.40035872 | V11: 0.811
A12: 300394.SZ | B12: Suzhou TFC Optical | C12: Transceivers | D12: CNY | E12: 160.1 | F12: 25855.519 | G12: -477.26435 | H12: =IF(F12="","",F12+N(G12)) | I12: 821.53697 | J12: 0.408 | K12: 0.54168 | L12: 0.48042 | M12: 0.45503 | N12: 394.6839 | O12: =IFERROR(IF(I12>0,H12/I12,"NM"),"NM") | P12: =IFERROR(IF(N12>0,H12/N12,"NM"),"NM") | Q12: 22.774021 | R12: 131.75644 | S12: =IFERROR(IF(AND(R12<>"",F12>0),R12/F12,""),"") | T12: 1.5198707 | U12: -0.57306667 | V12: 0.954
A13: 002281.SZ | B13: Accelink Technologies | C13: Transceivers | D13: CNY | E13: 152.33 | F13: 18669.956 | G13: -575.72269 | H13: =IF(F13="","",F13+N(G13)) | I13: 1847.6159 | J13: 0.248 | K13: 0.21248 | L13: 0.12464 | M13: 0.13071999 | N13: 230.29426 | O13: =IFERROR(IF(I13>0,H13/I13,"NM"),"NM") | P13: =IFERROR(IF(N13>0,H13/N13,"NM"),"NM") | Q13: 49.944263 | R13: 172.70851 | S13: =IFERROR(IF(AND(R13<>"",F13>0),R13/F13,""),"") | T13: 2.2738877 | U13: -0.45401434 | V13: 1.003
B14: Median - Transceivers | J14: =IFERROR(MEDIAN(J6:J13),"") | K14: =IFERROR(MEDIAN(K6:K13),"") | L14: =IFERROR(MEDIAN(L6:L13),"") | M14: =IFERROR(MEDIAN(M6:M13),"") | O14: =IFERROR(MEDIAN(O6:O13),"") | P14: =IFERROR(MEDIAN(P6:P13),"") | Q14: =IFERROR(MEDIAN(Q6:Q13),"") | S14: =IFERROR(MEDIAN(S6:S13),"") | T14: =IFERROR(MEDIAN(T6:T13),"")
A15: Optical Semiconductors (DSP / PHY / TIA / PIC)
A16: MRVL | B16: Marvell Technology | C16: Optical Semis | D16: USD | E16: 180.945 | F16: 162406.19 | G16: 1433.6 | H16: =IF(F16="","",F16+N(G16)) | I16: 8717.1 | J16: 0.276 | K16: 0.51502997 | L16: 0.31111 | M16: 0.14479999 | N16: 2712 | O16: =IFERROR(IF(I16>0,H16/I16,"NM"),"NM") | P16: =IFERROR(IF(N16>0,H16/N16,"NM"),"NM") | Q16: 28.993229 | R16: 2269.7001 | S16: =IFERROR(IF(AND(R16<>"",F16>0),R16/F16,""),"") | T16: 1.2183818 | U16: -0.45148236 | V16: 2.197
A17: AVGO | B17: Broadcom | C17: Optical Semis | D17: USD | E17: 385.22 | F17: 1832715 | G17: 45279.003 | H17: =IF(F17="","",F17+N(G17)) | I17: 75464.999 | J17: 0.479 | K17: 0.76284 | L17: 0.55766 | M17: 0.48988 | N17: 42084 | O17: =IFERROR(IF(I17>0,H17/I17,"NM"),"NM") | P17: =IFERROR(IF(N17>0,H17/N17,"NM"),"NM") | Q17: 19.7317 | R17: 27212.249 | S17: =IFERROR(IF(AND(R17<>"",F17>0),R17/F17,""),"") | T17: 0.28227664 | U17: -0.22177778 | V17: 1.462
A18: CRDO | B18: Credo Technology | C18: Optical Semis | D18: USD | E18: 197.7 | F18: 36866.683 | G18: -1417.838 | H18: =IF(F18="","",F18+N(G18)) | I18: 1335.116 | J18: 1.57 | K18: 0.68035007 | L18: 0.35924998 | M18: 0.35661998 | N18: 479.64198 | O18: =IFERROR(IF(I18>0,H18/I18,"NM"),"NM") | P18: =IFERROR(IF(N18>0,H18/N18,"NM"),"NM") | Q18: 21.783037 | R18: 250.81013 | S18: =IFERROR(IF(AND(R18<>"",F18>0),R18/F18,""),"") | T18: 0.70416338 | U18: -0.35951016 | V18: 3.202
A19: MTSI | B19: MACOM Technology | C19: Optical Semis | D19: USD | E19: 250.405 | F19: 19104.844 | G19: -250.83398 | H19: =IF(F19="","",F19+N(G19)) | I19: 1073.8161 | J19: 0.225 | K19: 0.55684 | L19: 0.21884 | M19: 0.17591 | N19: 234.99501 | O19: =IFERROR(IF(I19>0,H19/I19,"NM"),"NM") | P19: =IFERROR(IF(N19>0,H19/N19,"NM"),"NM") | Q19: 36.114246 | R19: 81.527872 | S19: =IFERROR(IF(AND(R19<>"",F19>0),R19/F19,""),"") | T19: 0.7883516 | U19: -0.40223204 | V19: 1.655
A20: SMTC | B20: Semtech | C20: Optical Semis | D20: USD | E20: 115.5025 | F20: 10759.193 | G20: 354.30699 | H20: =IF(F20="","",F20+N(G20)) | I20: 1089.9331 | J20: 0.159 | K20: 0.52394 | L20: 0.13919 | M20: 0.09267 | N20: 151.71101 | O20: =IFERROR(IF(I20>0,H20/I20,"NM"),"NM") | P20: =IFERROR(IF(N20>0,H20/N20,"NM"),"NM") | Q20: 29.4517 | R20: 132.51138 | S20: =IFERROR(IF(AND(R20<>"",F20>0),R20/F20,""),"") | T20: 1.1504842 | U20: -0.34873132 | V20: 2.31
A21: ALAB | B21: Astera Labs | C21: Optical Semis | D21: USD | E21: 290.89 | F21: 49860.858 | G21: -1142.624 | H21: =IF(F21="","",F21+N(G21)) | I21: 1001.444 | J21: 0.934 | K21: 0.75988996 | L21: 0.23305 | M21: 0.20052 | N21: 233.38499 | O21: =IFERROR(IF(I21>0,H21/I21,"NM"),"NM") | P21: =IFERROR(IF(N21>0,H21/N21,"NM"),"NM") | Q21: 63.741066 | R21: 240.00488 | S21: =IFERROR(IF(AND(R21<>"",F21>0),R21/F21,""),"") | T21: 1.2572362 | U21: -0.41760965 | V21: 3.671
A22: POET | B22: POET Technologies | C22: Optical Semis | D22: USD | E22: 7.1074 | F22: 1226.6661 | G22: -422.11585 | H22: =IF(F22="","",F22+N(G22)) | I22: 1.411494 | J22: 2.019 | K22: 1 | L22: 0 | M22: -35.4997 | N22: -47.118212 | O22: =IFERROR(IF(I22>0,H22/I22,"NM"),"NM") | P22: =IFERROR(IF(N22>0,H22/N22,"NM"),"NM") | Q22: NM | R22: -42.376272 | S22: =IFERROR(IF(AND(R22<>"",F22>0),R22/F22,""),"") | T22: 0.23606955 | U22: -0.65846228 | V22: 0.764
B23: Median - Optical Semis | J23: =IFERROR(MEDIAN(J16:J22),"") | K23: =IFERROR(MEDIAN(K16:K22),"") | L23: =IFERROR(MEDIAN(L16:L22),"") | M23: =IFERROR(MEDIAN(M16:M22),"") | O23: =IFERROR(MEDIAN(O16:O22),"") | P23: =IFERROR(MEDIAN(P16:P22),"") | Q23: =IFERROR(MEDIAN(Q16:Q22),"") | S23: =IFERROR(MEDIAN(S16:S22),"") | T23: =IFERROR(MEDIAN(T16:T22),"")
A24: Lithography & Light-Source Optics
A25: ASML | B25: ASML Holding | C25: Litho Optics | D25: USD | E25: 1651.24 | F25: 634241.29 | G25: -6453.4762 | H25: =IF(F25="","",F25+N(G25)) | I25: 40732.734 | J25: 0.213 | K25: 0.52733004 | L25: 0.38181 | M25: 0.37057 | N25: 15552.174 | O25: =IFERROR(IF(I25>0,H25/I25,"NM"),"NM") | P25: =IFERROR(IF(N25>0,H25/N25,"NM"),"NM") | Q25: 28.387125 | R25: 9728.6694 | S25: =IFERROR(IF(AND(R25<>"",F25>0),R25/F25,""),"") | T25: 1.3038731 | U25: -0.17436349 | V25: 1.394
A26: 7731.T | B26: Nikon | C26: Litho Optics | D26: JPY | E26: 1840 | F26: 3810.2735 | G26: 389.25177 | H26: =IF(F26="","",F26+N(G26)) | I26: 4256.8253 | J26: -0.046 | K26: 0.40944 | L26: 0.04097 | M26: -0.00773 | N26: 174.40611 | O26: =IFERROR(IF(I26>0,H26/I26,"NM"),"NM") | P26: =IFERROR(IF(N26>0,H26/N26,"NM"),"NM") | Q26: 17.376522 | R26: -376.15433 | S26: =IFERROR(IF(AND(R26<>"",F26>0),R26/F26,""),"") | T26: 0.36156006 | U26: -0.23012552 | V26: 0.153
A27: 7751.T | B27: Canon | C27: Litho Optics | D27: JPY | E27: 4554 | F27: 24314.569 | G27: 3305.8646 | H27: =IF(F27="","",F27+N(G27)) | I27: 29549.856 | J27: 0.036 | K27: 0.47847998 | L27: 0.1545 | M27: 0.13483 | N27: 4565.3994 | O27: =IFERROR(IF(I27>0,H27/I27,"NM"),"NM") | P27: =IFERROR(IF(N27>0,H27/N27,"NM"),"NM") | Q27: 12.563106 | R27: 1055.437 | S27: =IFERROR(IF(AND(R27<>"",F27>0),R27/F27,""),"") | T27: 0.12015074 | U27: -0.095171866 | V27: 0.248
A28: 6925.T | B28: Ushio | C28: Litho Optics | D28: JPY | E28: 3604 | F28: 1797.6844 | G28: -21.20356 | H28: =IF(F28="","",F28+N(G28)) | I28: 1126.5676 | J28: 0.055 | K28: 0.36558998 | L28: 0.11561 | M28: 0.080819994 | N28: 130.2451 | O28: =IFERROR(IF(I28>0,H28/I28,"NM"),"NM") | P28: =IFERROR(IF(N28>0,H28/N28,"NM"),"NM") | Q28: 33.192116 | R28: -0.10608071 | S28: =IFERROR(IF(AND(R28<>"",F28>0),R28/F28,""),"") | T28: 1.0059 | U28: -0.3020914 | V28: 0.792
A29: 7741.T | B29: Hoya | C29: Litho Optics | D29: JPY | E29: 23840 | F29: 50132.46 | G29: -3343.3559 | H29: =IF(F29="","",F29+N(G29)) | I29: 5957.8004 | J29: 0.151 | K29: 0.54973 | L29: 0.38562 | M29: 0.27271 | N29: 2297.4409 | O29: =IFERROR(IF(I29>0,H29/I29,"NM"),"NM") | P29: =IFERROR(IF(N29>0,H29/N29,"NM"),"NM") | Q29: 34.895123 | R29: 1070.2247 | S29: =IFERROR(IF(AND(R29<>"",F29>0),R29/F29,""),"") | T29: 0.27107546 | U29: -0.21578947 | V29: 0.603
B30: Median - Litho Optics | J30: =IFERROR(MEDIAN(J25:J29),"") | K30: =IFERROR(MEDIAN(K25:K29),"") | L30: =IFERROR(MEDIAN(L25:L29),"") | M30: =IFERROR(MEDIAN(M25:M29),"") | O30: =IFERROR(MEDIAN(O25:O29),"") | P30: =IFERROR(MEDIAN(P25:P29),"") | Q30: =IFERROR(MEDIAN(Q25:Q29),"") | S30: =IFERROR(MEDIAN(S25:S29),"") | T30: =IFERROR(MEDIAN(T25:T29),"")
A31: Optical Inspection & Metrology
A32: KLAC | B32: KLA Corp. | C32: Inspection | D32: USD | E32: 181.265 | F32: 236781.98 | G32: 985.00659 | H32: =IF(F32="","",F32+N(G32)) | I32: 13579.476 | J32: 0.152 | K32: 0.61301 | L32: 0.44586 | M32: 0.42486 | N32: 6054.6094 | O32: =IFERROR(IF(I32>0,H32/I32,"NM"),"NM") | P32: =IFERROR(IF(N32>0,H32/N32,"NM"),"NM") | Q32: 27.577126 | S32: =IFERROR(IF(AND(R32<>"",F32>0),R32/F32,""),"") | T32: 0.97227302 | U32: -0.41027101
A33: 6920.T | B33: Lasertec | C33: Inspection | D33: JPY | E33: 33620 | F33: 18942.923 | G33: -503.07086 | H33: =IF(F33="","",F33+N(G33)) | I33: 1585.2764 | J33: 0.035 | K33: 0.59827 | L33: 0.50181997 | M33: 0.36821 | N33: 795.52043 | O33: =IFERROR(IF(I33>0,H33/I33,"NM"),"NM") | P33: =IFERROR(IF(N33>0,H33/N33,"NM"),"NM") | Q33: 30.782753 | R33: 348.02643 | S33: =IFERROR(IF(AND(R33<>"",F33>0),R33/F33,""),"") | T33: 1.315593 | U33: -0.42608399 | V33: 1.714
A34: ONTO | B34: Onto Innovation | C34: Inspection | D34: USD | E34: 248.7875 | F34: 12375.579 | G34: -654.16397 | H34: =IF(F34="","",F34+N(G34)) | I34: 1030.605 | J34: 0.095 | K34: 0.54186 | L34: 0.25899 | M34: 0.16753 | N34: 266.91699 | O34: =IFERROR(IF(I34>0,H34/I34,"NM"),"NM") | P34: =IFERROR(IF(N34>0,H34/N34,"NM"),"NM") | Q34: 25.015762 | R34: 197.24226 | S34: =IFERROR(IF(AND(R34<>"",F34>0),R34/F34,""),"") | T34: 1.4317028 | U34: -0.35623997 | V34: 1.545
A35: CAMT | B35: Camtek | C35: Inspection | D35: USD | E35: 137.155 | F35: 6399.1752 | G35: -182.44998 | H35: =IF(F35="","",F35+N(G35)) | I35: 499.09299 | J35: 0.025 | K35: 0.50969005 | L35: 0.27756 | M35: 0.22412 | N35: 138.52925 | O35: =IFERROR(IF(I35>0,H35/I35,"NM"),"NM") | P35: =IFERROR(IF(N35>0,H35/N35,"NM"),"NM") | Q35: 30.311636 | S35: =IFERROR(IF(AND(R35<>"",F35>0),R35/F35,""),"") | T35: 0.39456025 | U35: -0.36499375 | V35: 1.567
A36: NVMI | B36: Nova Ltd. | C36: Inspection | D36: USD | E36: 395.04 | F36: 12564.705 | G36: -298.37299 | H36: =IF(F36="","",F36+N(G36)) | I36: 902.52902 | J36: 0.103 | K36: 0.57310003 | L36: 0.31451 | M36: 0.30104 | N36: 283.85798 | O36: =IFERROR(IF(I36>0,H36/I36,"NM"),"NM") | P36: =IFERROR(IF(N36>0,H36/N36,"NM"),"NM") | Q36: 30.468763 | R36: 122.41587 | S36: =IFERROR(IF(AND(R36<>"",F36>0),R36/F36,""),"") | T36: 0.44259427 | U36: -0.35869089 | V36: 1.735
B37: Median - Inspection | J37: =IFERROR(MEDIAN(J32:J36),"") | K37: =IFERROR(MEDIAN(K32:K36),"") | L37: =IFERROR(MEDIAN(L32:L36),"") | M37: =IFERROR(MEDIAN(M32:M36),"") | O37: =IFERROR(MEDIAN(O32:O36),"") | P37: =IFERROR(MEDIAN(P32:P36),"") | Q37: =IFERROR(MEDIAN(Q32:Q36),"") | S37: =IFERROR(MEDIAN(S32:S36),"") | T37: =IFERROR(MEDIAN(T32:T36),"")
A38: Substrates, Materials & Lasers
A39: AXTI | B39: AXT Inc. | C39: Materials | D39: USD | E39: 47.335 | F39: 3096.8064 | G39: -29.571 | H39: =IF(F39="","",F39+N(G39)) | I39: 95.894 | J39: 0.391 | K39: 0.21337 | L39: -0.041360002 | M39: -0.058870003 | N39: -3.966 | O39: =IFERROR(IF(I39>0,H39/I39,"NM"),"NM") | P39: =IFERROR(IF(N39>0,H39/N39,"NM"),"NM") | Q39: 60.8419 | R39: -25.25325 | S39: =IFERROR(IF(AND(R39<>"",F39>0),R39/F39,""),"") | T39: 21.327831 | U39: -0.66935597 | V39: 1.867
A40: GLW | B40: Corning | C40: Materials | D40: USD | E40: 133.42 | F40: 114692.87 | G40: 5920 | H40: =IF(F40="","",F40+N(G40)) | I40: 16964 | J40: 0.166 | K40: 0.36707002 | L40: 0.24622999 | M40: 0.16382 | N40: 4176.9999 | O40: =IFERROR(IF(I40>0,H40/I40,"NM"),"NM") | P40: =IFERROR(IF(N40>0,H40/N40,"NM"),"NM") | Q40: 30.992876 | R40: 882 | S40: =IFERROR(IF(AND(R40<>"",F40>0),R40/F40,""),"") | T40: 1.1542638 | U40: -0.50908823 | V40: 1.086
A41: IPGP | B41: IPG Photonics | C41: Materials | D41: USD | E41: 83.62 | F41: 3549.1354 | G41: -796.59302 | H41: =IF(F41="","",F41+N(G41)) | I41: 1041.481 | J41: 0.166 | K41: 0.37557 | L41: 0.08813 | M41: 0.02096 | N41: 91.79 | O41: =IFERROR(IF(I41>0,H41/I41,"NM"),"NM") | P41: =IFERROR(IF(N41>0,H41/N41,"NM"),"NM") | Q41: 36.17674 | R41: 0.603625 | S41: =IFERROR(IF(AND(R41<>"",F41>0),R41/F41,""),"") | T41: 0.085410199 | U41: -0.46335515 | V41: 0.941
...

Sheet Company Exposure
A1: Revenue Exposure Model - who actually monetizes each optical TAM
A2: Exposure %s are analyst estimates (blue - flex them). Each bucket grows at the Market Model '25-'28 CAGR, +/- a company share-shift adjustment, compounded over the horizon below.
A3: Years TTM -> CY2028E: | B3: 2.5 | D3: Other-bucket growth: | F3: 0.03
A5: Ticker | B5: Company | C5: Segment | D5: Rev TTM $M | E5: % AI/ DC opt | F5: % Fab optics | G5: % Telecom | H5: % Other | I5: AI/DC Rev $M | J5: Fab Rev $M | K5: Telecom Rev $M | L5: Other Rev $M | M5: Share adj (pts) | N5: 2028E Rev $M | O5: Implied CAGR | P5: EV $M | Q5: EV / 28E Rev
A6: COHR | B6: Coherent Corp. | C6: Transceivers | D6: =Comps!I6 | E6: 0.45 | F6: 0.05 | G6: 0.15 | H6: =1-E6-F6-G6 | I6: =IFERROR($D6*E6,"") | J6: =IFERROR($D6*F6,"") | K6: =IFERROR($D6*G6,"") | L6: =IFERROR($D6*H6,"") | M6: 0 | N6: =IFERROR(I6*(1+'Market Model'!$C$57+M6)^$B$3+J6*(1+'Market Model'!$C$58)^$B$3+K6*(1+'Market Model'!$C$59)^$B$3+L6*(1+$F$3)^$B$3,"") | O6: =IFERROR((N6/D6)^(1/$B$3)-1,"") | P6: =Comps!H6 | Q6: =IFERROR(IF(N6>0,P6/N6,"NM"),"NM")
A7: LITE | B7: Lumentum Holdings | C7: Transceivers | D7: =Comps!I7 | E7: 0.55 | F7: 0.05 | G7: 0.25 | H7: =1-E7-F7-G7 | I7: =IFERROR($D7*E7,"") | J7: =IFERROR($D7*F7,"") | K7: =IFERROR($D7*G7,"") | L7: =IFERROR($D7*H7,"") | M7: 0.01 | N7: =IFERROR(I7*(1+'Market Model'!$C$57+M7)^$B$3+J7*(1+'Market Model'!$C$58)^$B$3+K7*(1+'Market Model'!$C$59)^$B$3+L7*(1+$F$3)^$B$3,"") | O7: =IFERROR((N7/D7)^(1/$B$3)-1,"") | P7: =Comps!H7 | Q7: =IFERROR(IF(N7>0,P7/N7,"NM"),"NM")
A8: AAOI | B8: Applied Optoelectronics | C8: Transceivers | D8: =Comps!I8 | E8: 0.85 | F8: 0 | G8: 0.05 | H8: =1-E8-F8-G8 | I8: =IFERROR($D8*E8,"") | J8: =IFERROR($D8*F8,"") | K8: =IFERROR($D8*G8,"") | L8: =IFERROR($D8*H8,"") | M8: -0.02 | N8: =IFERROR(I8*(1+'Market Model'!$C$57+M8)^$B$3+J8*(1+'Market Model'!$C$58)^$B$3+K8*(1+'Market Model'!$C$59)^$B$3+L8*(1+$F$3)^$B$3,"") | O8: =IFERROR((N8/D8)^(1/$B$3)-1,"") | P8: =Comps!H8 | Q8: =IFERROR(IF(N8>0,P8/N8,"NM"),"NM")
A9: FN | B9: Fabrinet | C9: Transceivers | D9: =Comps!I9 | E9: 0.65 | F9: 0 | G9: 0.25 | H9: =1-E9-F9-G9 | I9: =IFERROR($D9*E9,"") | J9: =IFERROR($D9*F9,"") | K9: =IFERROR($D9*G9,"") | L9: =IFERROR($D9*H9,"") | M9: 0 | N9: =IFERROR(I9*(1+'Market Model'!$C$57+M9)^$B$3+J9*(1+'Market Model'!$C$58)^$B$3+K9*(1+'Market Model'!$C$59)^$B$3+L9*(1+$F$3)^$B$3,"") | O9: =IFERROR((N9/D9)^(1/$B$3)-1,"") | P9: =Comps!H9 | Q9: =IFERROR(IF(N9>0,P9/N9,"NM"),"NM")
A10: 300308.SZ | B10: Zhongji Innolight | C10: Transceivers | D10: =Comps!I10 | E10: 0.9 | F10: 0 | G10: 0.05 | H10: =1-E10-F10-G10 | I10: =IFERROR($D10*E10,"") | J10: =IFERROR($D10*F10,"") | K10: =IFERROR($D10*G10,"") | L10: =IFERROR($D10*H10,"") | M10: 0.01 | N10: =IFERROR(I10*(1+'Market Model'!$C$57+M10)^$B$3+J10*(1+'Market Model'!$C$58)^$B$3+K10*(1+'Market Model'!$C$59)^$B$3+L10*(1+$F$3)^$B$3,"") | O10: =IFERROR((N10/D10)^(1/$B$3)-1,"") | P10: =Comps!H10 | Q10: =IFERROR(IF(N10>0,P10/N10,"NM"),"NM")
A11: 300502.SZ | B11: Eoptolink | C11: Transceivers | D11: =Comps!I11 | E11: 0.92 | F11: 0 | G11: 0.04 | H11: =1-E11-F11-G11 | I11: =IFERROR($D11*E11,"") | J11: =IFERROR($D11*F11,"") | K11: =IFERROR($D11*G11,"") | L11: =IFERROR($D11*H11,"") | M11: 0.02 | N11: =IFERROR(I11*(1+'Market Model'!$C$57+M11)^$B$3+J11*(1+'Market Model'!$C$58)^$B$3+K11*(1+'Market Model'!$C$59)^$B$3+L11*(1+$F$3)^$B$3,"") | O11: =IFERROR((N11/D11)^(1/$B$3)-1,"") | P11: =Comps!H11 | Q11: =IFERROR(IF(N11>0,P11/N11,"NM"),"NM")
A12: 300394.SZ | B12: Suzhou TFC Optical | C12: Transceivers | D12: =Comps!I12 | E12: 0.8 | F12: 0 | G12: 0.12 | H12: =1-E12-F12-G12 | I12: =IFERROR($D12*E12,"") | J12: =IFERROR($D12*F12,"") | K12: =IFERROR($D12*G12,"") | L12: =IFERROR($D12*H12,"") | M12: 0.01 | N12: =IFERROR(I12*(1+'Market Model'!$C$57+M12)^$B$3+J12*(1+'Market Model'!$C$58)^$B$3+K12*(1+'Market Model'!$C$59)^$B$3+L12*(1+$F$3)^$B$3,"") | O12: =IFERROR((N12/D12)^(1/$B$3)-1,"") | P12: =Comps!H12 | Q12: =IFERROR(IF(N12>0,P12/N12,"NM"),"NM")
A13: 002281.SZ | B13: Accelink Technologies | C13: Transceivers | D13: =Comps!I13 | E13: 0.45 | F13: 0 | G13: 0.45 | H13: =1-E13-F13-G13 | I13: =IFERROR($D13*E13,"") | J13: =IFERROR($D13*F13,"") | K13: =IFERROR($D13*G13,"") | L13: =IFERROR($D13*H13,"") | M13: -0.01 | N13: =IFERROR(I13*(1+'Market Model'!$C$57+M13)^$B$3+J13*(1+'Market Model'!$C$58)^$B$3+K13*(1+'Market Model'!$C$59)^$B$3+L13*(1+$F$3)^$B$3,"") | O13: =IFERROR((N13/D13)^(1/$B$3)-1,"") | P13: =Comps!H13 | Q13: =IFERROR(IF(N13>0,P13/N13,"NM"),"NM")
A14: MRVL | B14: Marvell Technology | C14: Optical Semis | D14: =Comps!I16 | E14: 0.2 | F14: 0 | G14: 0.05 | H14: =1-E14-F14-G14 | I14: =IFERROR($D14*E14,"") | J14: =IFERROR($D14*F14,"") | K14: =IFERROR($D14*G14,"") | L14: =IFERROR($D14*H14,"") | M14: 0 | N14: =IFERROR(I14*(1+'Market Model'!$C$57+M14)^$B$3+J14*(1+'Market Model'!$C$58)^$B$3+K14*(1+'Market Model'!$C$59)^$B$3+L14*(1+$F$3)^$B$3,"") | O14: =IFERROR((N14/D14)^(1/$B$3)-1,"") | P14: =Comps!H16 | Q14: =IFERROR(IF(N14>0,P14/N14,"NM"),"NM")
A15: AVGO | B15: Broadcom | C15: Optical Semis | D15: =Comps!I17 | E15: 0.05 | F15: 0 | G15: 0.01 | H15: =1-E15-F15-G15 | I15: =IFERROR($D15*E15,"") | J15: =IFERROR($D15*F15,"") | K15: =IFERROR($D15*G15,"") | L15: =IFERROR($D15*H15,"") | M15: 0 | N15: =IFERROR(I15*(1+'Market Model'!$C$57+M15)^$B$3+J15*(1+'Market Model'!$C$58)^$B$3+K15*(1+'Market Model'!$C$59)^$B$3+L15*(1+$F$3)^$B$3,"") | O15: =IFERROR((N15/D15)^(1/$B$3)-1,"") | P15: =Comps!H17 | Q15: =IFERROR(IF(N15>0,P15/N15,"NM"),"NM")
A16: CRDO | B16: Credo Technology | C16: Optical Semis | D16: =Comps!I18 | E16: 0.25 | F16: 0 | G16: 0 | H16: =1-E16-F16-G16 | I16: =IFERROR($D16*E16,"") | J16: =IFERROR($D16*F16,"") | K16: =IFERROR($D16*G16,"") | L16: =IFERROR($D16*H16,"") | M16: 0.02 | N16: =IFERROR(I16*(1+'Market Model'!$C$57+M16)^$B$3+J16*(1+'Market Model'!$C$58)^$B$3+K16*(1+'Market Model'!$C$59)^$B$3+L16*(1+$F$3)^$B$3,"") | O16: =IFERROR((N16/D16)^(1/$B$3)-1,"") | P16: =Comps!H18 | Q16: =IFERROR(IF(N16>0,P16/N16,"NM"),"NM")
A17: MTSI | B17: MACOM Technology | C17: Optical Semis | D17: =Comps!I19 | E17: 0.35 | F17: 0.05 | G17: 0.1 | H17: =1-E17-F17-G17 | I17: =IFERROR($D17*E17,"") | J17: =IFERROR($D17*F17,"") | K17: =IFERROR($D17*G17,"") | L17: =IFERROR($D17*H17,"") | M17: 0.005 | N17: =IFERROR(I17*(1+'Market Model'!$C$57+M17)^$B$3+J17*(1+'Market Model'!$C$58)^$B$3+K17*(1+'Market Model'!$C$59)^$B$3+L17*(1+$F$3)^$B$3,"") | O17: =IFERROR((N17/D17)^(1/$B$3)-1,"") | P17: =Comps!H19 | Q17: =IFERROR(IF(N17>0,P17/N17,"NM"),"NM")
A18: SMTC | B18: Semtech | C18: Optical Semis | D18: =Comps!I20 | E18: 0.25 | F18: 0 | G18: 0.05 | H18: =1-E18-F18-G18 | I18: =IFERROR($D18*E18,"") | J18: =IFERROR($D18*F18,"") | K18: =IFERROR($D18*G18,"") | L18: =IFERROR($D18*H18,"") | M18: 0.005 | N18: =IFERROR(I18*(1+'Market Model'!$C$57+M18)^$B$3+J18*(1+'Market Model'!$C$58)^$B$3+K18*(1+'Market Model'!$C$59)^$B$3+L18*(1+$F$3)^$B$3,"") | O18: =IFERROR((N18/D18)^(1/$B$3)-1,"") | P18: =Comps!H20 | Q18: =IFERROR(IF(N18>0,P18/N18,"NM"),"NM")
A19: ALAB | B19: Astera Labs | C19: Optical Semis | D19: =Comps!I21 | E19: 0.05 | F19: 0 | G19: 0 | H19: =1-E19-F19-G19 | I19: =IFERROR($D19*E19,"") | J19: =IFERROR($D19*F19,"") | K19: =IFERROR($D19*G19,"") | L19: =IFERROR($D19*H19,"") | M19: 0.03 | N19: =IFERROR(I19*(1+'Market Model'!$C$57+M19)^$B$3+J19*(1+'Market Model'!$C$58)^$B$3+K19*(1+'Market Model'!$C$59)^$B$3+L19*(1+$F$3)^$B$3,"") | O19: =IFERROR((N19/D19)^(1/$B$3)-1,"") | P19: =Comps!H21 | Q19: =IFERROR(IF(N19>0,P19/N19,"NM"),"NM")
A20: POET | B20: POET Technologies | C20: Optical Semis | D20: =Comps!I22 | E20: 0.9 | F20: 0 | G20: 0.05 | H20: =1-E20-F20-G20 | I20: =IFERROR($D20*E20,"") | J20: =IFERROR($D20*F20,"") | K20: =IFERROR($D20*G20,"") | L20: =IFERROR($D20*H20,"") | M20: 0.05 | N20: =IFERROR(I20*(1+'Market Model'!$C$57+M20)^$B$3+J20*(1+'Market Model'!$C$58)^$B$3+K20*(1+'Market Model'!$C$59)^$B$3+L20*(1+$F$3)^$B$3,"") | O20: =IFERROR((N20/D20)^(1/$B$3)-1,"") | P20: =Comps!H22 | Q20: =IFERROR(IF(N20>0,P20/N20,"NM"),"NM")
A21: ASML | B21: ASML Holding | C21: Litho Optics | D21: =Comps!I25 | E21: 0 | F21: 1 | G21: 0 | H21: =1-E21-F21-G21 | I21: =IFERROR($D21*E21,"") | J21: =IFERROR($D21*F21,"") | K21: =IFERROR($D21*G21,"") | L21: =IFERROR($D21*H21,"") | M21: 0 | N21: =IFERROR(I21*(1+'Market Model'!$C$57+M21)^$B$3+J21*(1+'Market Model'!$C$58)^$B$3+K21*(1+'Market Model'!$C$59)^$B$3+L21*(1+$F$3)^$B$3,"") | O21: =IFERROR((N21/D21)^(1/$B$3)-1,"") | P21: =Comps!H25 | Q21: =IFERROR(IF(N21>0,P21/N21,"NM"),"NM")
A22: 7731.T | B22: Nikon | C22: Litho Optics | D22: =Comps!I26 | E22: 0 | F22: 0.3 | G22: 0 | H22: =1-E22-F22-G22 | I22: =IFERROR($D22*E22,"") | J22: =IFERROR($D22*F22,"") | K22: =IFERROR($D22*G22,"") | L22: =IFERROR($D22*H22,"") | M22: 0 | N22: =IFERROR(I22*(1+'Market Model'!$C$57+M22)^$B$3+J22*(1+'Market Model'!$C$58)^$B$3+K22*(1+'Market Model'!$C$59)^$B$3+L22*(1+$F$3)^$B$3,"") | O22: =IFERROR((N22/D22)^(1/$B$3)-1,"") | P22: =Comps!H26 | Q22: =IFERROR(IF(N22>0,P22/N22,"NM"),"NM")
A23: 7751.T | B23: Canon | C23: Litho Optics | D23: =Comps!I27 | E23: 0 | F23: 0.15 | G23: 0 | H23: =1-E23-F23-G23 | I23: =IFERROR($D23*E23,"") | J23: =IFERROR($D23*F23,"") | K23: =IFERROR($D23*G23,"") | L23: =IFERROR($D23*H23,"") | M23: 0 | N23: =IFERROR(I23*(1+'Market Model'!$C$57+M23)^$B$3+J23*(1+'Market Model'!$C$58)^$B$3+K23*(1+'Market Model'!$C$59)^$B$3+L23*(1+$F$3)^$B$3,"") | O23: =IFERROR((N23/D23)^(1/$B$3)-1,"") | P23: =Comps!H27 | Q23: =IFERROR(IF(N23>0,P23/N23,"NM"),"NM")
A24: 6925.T | B24: Ushio | C24: Litho Optics | D24: =Comps!I28 | E24: 0 | F24: 0.4 | G24: 0 | H24: =1-E24-F24-G24 | I24: =IFERROR($D24*E24,"") | J24: =IFERROR($D24*F24,"") | K24: =IFERROR($D24*G24,"") | L24: =IFERROR($D24*H24,"") | M24: 0 | N24: =IFERROR(I24*(1+'Market Model'!$C$57+M24)^$B$3+J24*(1+'Market Model'!$C$58)^$B$3+K24*(1+'Market Model'!$C$59)^$B$3+L24*(1+$F$3)^$B$3,"") | O24: =IFERROR((N24/D24)^(1/$B$3)-1,"") | P24: =Comps!H28 | Q24: =IFERROR(IF(N24>0,P24/N24,"NM"),"NM")
A25: 7741.T | B25: Hoya | C25: Litho Optics | D25: =Comps!I29 | E25: 0 | F25: 0.3 | G25: 0 | H25: =1-E25-F25-G25 | I25: =IFERROR($D25*E25,"") | J25: =IFERROR($D25*F25,"") | K25: =IFERROR($D25*G25,"") | L25: =IFERROR($D25*H25,"") | M25: 0 | N25: =IFERROR(I25*(1+'Market Model'!$C$57+M25)^$B$3+J25*(1+'Market Model'!$C$58)^$B$3+K25*(1+'Market Model'!$C$59)^$B$3+L25*(1+$F$3)^$B$3,"") | O25: =IFERROR((N25/D25)^(1/$B$3)-1,"") | P25: =Comps!H29 | Q25: =IFERROR(IF(N25>0,P25/N25,"NM"),"NM")
A26: KLAC | B26: KLA Corp. | C26: Inspection | D26: =Comps!I32 | E26: 0 | F26: 0.95 | G26: 0 | H26: =1-E26-F26-G26 | I26: =IFERROR($D26*E26,"") | J26: =IFERROR($D26*F26,"") | K26: =IFERROR($D26*G26,"") | L26: =IFERROR($D26*H26,"") | M26: 0 | N26: =IFERROR(I26*(1+'Market Model'!$C$57+M26)^$B$3+J26*(1+'Market Model'!$C$58)^$B$3+K26*(1+'Market Model'!$C$59)^$B$3+L26*(1+$F$3)^$B$3,"") | O26: =IFERROR((N26/D26)^(1/$B$3)-1,"") | P26: =Comps!H32 | Q26: =IFERROR(IF(N26>0,P26/N26,"NM"),"NM")
A27: 6920.T | B27: Lasertec | C27: Inspection | D27: =Comps!I33 | E27: 0 | F27: 1 | G27: 0 | H27: =1-E27-F27-G27 | I27: =IFERROR($D27*E27,"") | J27: =IFERROR($D27*F27,"") | K27: =IFERROR($D27*G27,"") | L27: =IFERROR($D27*H27,"") | M27: 0 | N27: =IFERROR(I27*(1+'Market Model'!$C$57+M27)^$B$3+J27*(1+'Market Model'!$C$58)^$B$3+K27*(1+'Market Model'!$C$59)^$B$3+L27*(1+$F$3)^$B$3,"") | O27: =IFERROR((N27/D27)^(1/$B$3)-1,"") | P27: =Comps!H33 | Q27: =IFERROR(IF(N27>0,P27/N27,"NM"),"NM")
A28: ONTO | B28: Onto Innovation | C28: Inspection | D28: =Comps!I34 | E28: 0 | F28: 0.95 | G28: 0 | H28: =1-E28-F28-G28 | I28: =IFERROR($D28*E28,"") | J28: =IFERROR($D28*F28,"") | K28: =IFERROR($D28*G28,"") | L28: =IFERROR($D28*H28,"") | M28: 0.01 | N28: =IFERROR(I28*(1+'Market Model'!$C$57+M28)^$B$3+J28*(1+'Market Model'!$C$58)^$B$3+K28*(1+'Market Model'!$C$59)^$B$3+L28*(1+$F$3)^$B$3,"") | O28: =IFERROR((N28/D28)^(1/$B$3)-1,"") | P28: =Comps!H34 | Q28: =IFERROR(IF(N28>0,P28/N28,"NM"),"NM")
A29: CAMT | B29: Camtek | C29: Inspection | D29: =Comps!I35 | E29: 0 | F29: 1 | G29: 0 | H29: =1-E29-F29-G29 | I29: =IFERROR($D29*E29,"") | J29: =IFERROR($D29*F29,"") | K29: =IFERROR($D29*G29,"") | L29: =IFERROR($D29*H29,"") | M29: 0.01 | N29: =IFERROR(I29*(1+'Market Model'!$C$57+M29)^$B$3+J29*(1+'Market Model'!$C$58)^$B$3+K29*(1+'Market Model'!$C$59)^$B$3+L29*(1+$F$3)^$B$3,"") | O29: =IFERROR((N29/D29)^(1/$B$3)-1,"") | P29: =Comps!H35 | Q29: =IFERROR(IF(N29>0,P29/N29,"NM"),"NM")
A30: NVMI | B30: Nova Ltd. | C30: Inspection | D30: =Comps!I36 | E30: 0 | F30: 1 | G30: 0 | H30: =1-E30-F30-G30 | I30: =IFERROR($D30*E30,"") | J30: =IFERROR($D30*F30,"") | K30: =IFERROR($D30*G30,"") | L30: =IFERROR($D30*H30,"") | M30: 0 | N30: =IFERROR(I30*(1+'Market Model'!$C$57+M30)^$B$3+J30*(1+'Market Model'!$C$58)^$B$3+K30*(1+'Market Model'!$C$59)^$B$3+L30*(1+$F$3)^$B$3,"") | O30: =IFERROR((N30/D30)^(1/$B$3)-1,"") | P30: =Comps!H36 | Q30: =IFERROR(IF(N30>0,P30/N30,"NM"),"NM")
A31: AXTI | B31: AXT Inc. | C31: Materials | D31: =Comps!I39 | E31: 0.45 | F31: 0.1 | G31: 0.15 | H31: =1-E31-F31-G31 | I31: =IFERROR($D31*E31,"") | J31: =IFERROR($D31*F31,"") | K31: =IFERROR($D31*G31,"") | L31: =IFERROR($D31*H31,"") | M31: 0.01 | N31: =IFERROR(I31*(1+'Market Model'!$C$57+M31)^$B$3+J31*(1+'Market Model'!$C$58)^$B$3+K31*(1+'Market Model'!$C$59)^$B$3+L31*(1+$F$3)^$B$3,"") | O31: =IFERROR((N31/D31)^(1/$B$3)-1,"") | P31: =Comps!H39 | Q31: =IFERROR(IF(N31>0,P31/N31,"NM"),"NM")
A32: GLW | B32: Corning | C32: Materials | D32: =Comps!I40 | E32: 0.35 | F32: 0.05 | G32: 0.15 | H32: =1-E32-F32-G32 | I32: =IFERROR($D32*E32,"") | J32: =IFERROR($D32*F32,"") | K32: =IFERROR($D32*G32,"") | L32: =IFERROR($D32*H32,"") | M32: 0 | N32: =IFERROR(I32*(1+'Market Model'!$C$57+M32)^$B$3+J32*(1+'Market Model'!$C$58)^$B$3+K32*(1+'Market Model'!$C$59)^$B$3+L32*(1+$F$3)^$B$3,"") | O32: =IFERROR((N32/D32)^(1/$B$3)-1,"") | P32: =Comps!H40 | Q32: =IFERROR(IF(N32>0,P32/N32,"NM"),"NM")
