Workbook

Sheet README
A1: Neocloud contract duration & spot-GPU price exposure
A2: Prepared 16 Oct 2026. Latest financial data: quarter ended 30 Jun 2026 (CoreWeave 10-Q, Nebius Q2'26 letter, IREN FY26 results). Prices: Oct-2026 indices.
A4: Purpose | B4: Quantify how long the revenue of GPU 'neoclouds' is locked up under take-or-pay / committed contracts, and how much of each company's revenue is exposed to the spot / on-demand GPU rental market (either directly, or indirectly via near-term re-contracting).
A5: Duration metric 1 | B5: Backlog coverage (years) = contracted backlog / annualized revenue run-rate. Naive but comparable; overstated while capacity is still ramping (backlog includes undelivered capacity).
A6: Duration metric 2 | B6: RPO-schedule-weighted remaining duration (CoreWeave only): the 10-Q discloses % of RPO recognized in months 0-24 / 25-48 / 49-78. Weighted average of bucket midpoints = average remaining life of a contracted dollar.
A7: Duration metric 3 | B7: TCV-weighted contract term: bottom-up from individually disclosed contracts (term from first revenue to expiry). Remaining duration = TCV-weighted years from the as-of date to expiry.
A8: Spot exposure | B8: Share of run-rate revenue that is (a) on-demand / pay-as-you-go today, plus (b) contracted capacity whose initial term expires within 12 / 24 months and must be re-priced at market. Sensitivity = exposed revenue x spot price shock.
A9: Colour code | B9: Yellow = editable assumption / input. Green = formula output. White = disclosed data point (source in column notes and on the 'Sources' sheet).
A10: Caveats | B10: Backlog, RPO and 'customer commitments' are not like-for-like across companies (CoreWeave RPO is net of variable consideration; Nebius 'commitments' and private-company TCV figures are gross and may include optional capacity). Private-company figures are from press / IPO-filing coverage, not audited statements. Analyst assumptions are labelled as such; replace them with your own view.
A12: Sheet guide
A13: Summary | B13: One row per company: backlog, run-rate, coverage, duration, spot-exposed share, exposure rating.
A14: CRWV_Duration | B14: CoreWeave: quarterly backlog series, RPO recognition schedule -> weighted duration and revenue cliff, disclosed contracts.
A15: NBIS_Duration | B15: Nebius: ARR series, contract-by-contract TCV-weighted term and remaining duration, deal taxonomy.
A16: Peer_Contracts | B16: IREN, Lambda, Nscale, Crusoe, Fluidstack and GPU-hosting landlords (APLD, CIFR, WULF, HUT, CORZ, GLXY): contract list and TCV-weighted terms.
A17: GPU_Spot_Prices | B17: H100 spot/contract price history (SemiAnalysis), current cross-provider spot/on-demand/reserved (Bargo, flatkey), term ladder (CCIR).
A18: Spot_Exposure | B18: Scenario model: revenue at risk under spot price shocks; mark-to-market of legacy contract rates vs today's spot.
A19: Sources | B19: Every source URL with retrieval date.

Sheet Summary
A1: Summary - contract duration & spot GPU-price exposure by neocloud
A2: As of 16-Oct-2026; financials as of quarter ended 30-Jun-2026 unless noted. Green = linked formulas; see component sheets for sources.
A4: Company | B4: Ticker / status | C4: Model | D4: Backlog / commitments ($B) | E4: Run-rate basis ($B) | F4: Run-rate definition | G4: Backlog coverage (yrs) | H4: Wtd remaining duration (yrs) | I4: TCV-wtd original term (yrs) | J4: Longest tenor (yrs) | K4: On-demand / spot share | L4: Spot-exposed share (24 mo) | M4: Exposure rating | N4: Key counterparties / notes
A5: CoreWeave | B5: CRWV (Nasdaq) | C5: GPU cloud | D5: =CRWV_Duration!E10 -> 104.2 | E5: =CRWV_Duration!E13 -> 19 | F5: YE26 exit ARR guide mid | G5: =CRWV_Duration!E15 -> 5.4842105 | H5: =CRWV_Duration!$E$25 -> 2.63 | I5: =CRWV_Duration!$E$41 -> 6.0012961 | J5: =CRWV_Duration!C23/12 -> 6.5 | K5: =Spot_Exposure!D6 -> 0.02 | L5: =Spot_Exposure!H6 -> 0.14 | M5: =Spot_Exposure!K6 -> Low | N5: Microsoft (~36%), OpenAI (~26%), Meta (~10%), NVIDIA backstop, Jane Street. 98% committed/take-or-pay. RPO: 41% <24 mo, 39% 25-48 mo, 20% 49-78 mo. Shift toward 2-3 yr enterprise deals via DTL 5.5.
A6: Nebius Group | B6: NBIS (Nasdaq) | C6: GPU cloud | D6: =NBIS_Duration!F8 -> 40 | E6: =NBIS_Duration!E11 -> 8 | F6: YE26 ARR guide mid | G6: =NBIS_Duration!E12 -> 5 | H6: =NBIS_Duration!$G$25 -> 4.4053114 | I6: =NBIS_Duration!$D$25 -> 4.43 | J6: =MAX(NBIS_Duration!D17:D24) -> 5 | K6: =Spot_Exposure!D7 -> 0.12 | L6: =Spot_Exposure!H7 -> 0.32 | M6: =Spot_Exposure!K7 -> Medium | N6: Microsoft $17.4B (to 2031), Meta $3B + $12B firm (+$15B option) - ~80% IG. Four >$1B 1-3 yr AI-lab deals in Q2'26. Deliberately holds capacity for <=6-mo premium deals / auctions.
A7: IREN | B7: IREN (Nasdaq) | C7: GPU cloud (ex-BTC miner) | D7: =Peer_Contracts!$H$47 -> 14.85 | E7: =Spot_Exposure!B8 -> 4 | F7: Contracted ARR for 2026 capacity (implied TCV = ARR x term) | G7: =Peer_Contracts!$H$48 -> 3.7125 | H7: =Peer_Contracts!$G$47 -> 3.7099932 | I7: =Peer_Contracts!$D$47 -> 3.7125 | J7: =Peer_Contracts!F31 -> 5 | K7: =Spot_Exposure!D8 -> 0.02 | L7: =Spot_Exposure!H8 -> 0.32 | M7: =Spot_Exposure!K8 -> Medium | N7: Microsoft $9.7B / 5-yr avg (20% prepay) = ~$1.9B ARR; frontier lab + Together, Fluidstack, Fireworks, Poolside, Cohere on 1-3 yr terms. RPO $5.1B (Jun-26). Recent 3-yr deals >$20M/MW.
A8: Lambda | B8: Private | C8: GPU cloud | D8: 50 | F8: n/d | I8: =Peer_Contracts!E32 -> 6 | J8: =Peer_Contracts!F32 -> 6 | M8: Medium | N8: Anthropic $35B / 6 yr (~70% of backlog); Microsoft multi-year; public on-demand cloud is spot-priced.
A9: Nscale | B9: IPO filing (NYSE) | C9: GPU cloud / AI factory | D9: 103 | F9: n/d | I9: =Peer_Contracts!E33 -> 6.4954751 | J9: =Peer_Contracts!F33 -> 7 | M9: Low | N9: Microsoft $43.8B through 2033; Anthropic $44.6B / 6 yr (contingent on financing). ~85% of TCV in two names.
A10: Crusoe | B10: Private | C10: GPU cloud + AI DCs | D10: 140 | F10: n/d | M10: Low-Medium | N10: >$140B TCV, ~4.9 GW contracted; term mix not disclosed (Abilene lease to Oracle/OpenAI ~15 yr).
A11: Fluidstack | B11: Private | C11: GPU cloud + marketplace | F11: n/d | I11: =Peer_Contracts!E35 | M11: Medium-High | N11: Private cloud 2-3 yr; marketplace spot; 10-25 yr fixed hosting leases at WULF/CIFR/HUT with Google backstop.
A12: Applied Digital | B12: APLD (Nasdaq) | C12: Hosting landlord | D12: =Peer_Contracts!C36 -> 36.2 | F12: n/a | I12: =Peer_Contracts!E36 -> 15 | J12: =Peer_Contracts!F36 -> 15 | K12: 0 | L12: 0 | M12: None | N12: 1,410 MW on 15-yr take-or-pay leases; CoreWeave 400 MW; ~$86B incl. renewal options.
A13: Cipher Digital | B13: CIFR (Nasdaq) | C13: Hosting landlord | D13: =Peer_Contracts!C37 -> 14.5 | F13: n/a | I13: =Peer_Contracts!E37 -> 11.896552 | J13: =Peer_Contracts!F37 -> 15 | K13: 0 | L13: 0 | M13: None | N13: AWS 15 yr; Fluidstack 10 yr + AI-lab 10-yr follow-on (20 yr site life).
A14: TeraWulf | B14: WULF (Nasdaq) | C14: Hosting landlord | D14: =Peer_Contracts!C38 -> 25.7 | F14: n/a | I14: =Peer_Contracts!E38 -> 17.392996 | J14: =Peer_Contracts!F38 -> 20 | K14: 0 | L14: 0 | M14: None | N14: Fluidstack 10 yr (Google backstop); Anthropic $19B / 20 yr.
A15: Hut 8 | B15: HUT (Nasdaq) | C15: Hosting landlord | D15: =Peer_Contracts!C39 -> 7 | F15: n/a | I15: =Peer_Contracts!E39 -> 15 | J15: =Peer_Contracts!F39 -> 15 | K15: 0 | L15: 0 | M15: None | N15: Fluidstack-for-Anthropic $7B / 15 yr; Google backstop.
A16: Core Scientific | B16: CORZ (Nasdaq) | C16: Hosting landlord | D16: =Peer_Contracts!C40 -> 10.2 | F16: n/a | I16: =Peer_Contracts!E40 -> 12 | J16: =Peer_Contracts!F40 -> 12 | K16: 0 | L16: 0 | M16: None | N16: CoreWeave ~$10.2B / 12 yr.
A17: Galaxy Digital | B17: GLXY (Nasdaq) | C17: Hosting landlord | D17: =Peer_Contracts!C41 -> 18 | F17: n/a | I17: =Peer_Contracts!E41 -> 15 | J17: =Peer_Contracts!F41 -> 15 | K17: 0 | L17: 0 | M17: None | N17: CoreWeave Helios 15 yr; >$1.2B avg annual revenue.
A19: Key takeaways
A20: - CoreWeave: the average contracted dollar has ~2.6 years of remaining life (RPO-weighted), down from ~2.9 at Q1'26 as 2-3 yr enterprise deals are layered in; but the book still carries 5.5 years of YE26 run-rate and the longest tenors run to Dec-2032. Only 2% of revenue is on-demand. The real spot exposure is the yr-5+ cliff: contracted run-rate falls ~59% from yrs 3-4 to yrs 5-6.5 absent new bookings or re-contracting.
A21: - Nebius: ~80% of the $40B book is 5-yr investment-grade (Microsoft, Meta), giving a TCV-weighted term of ~4.4 yrs and ~5 yrs of YE26 ARR coverage. But management is explicitly running a barbell - 1-3 yr 'mid-term' AI-lab deals plus <=6-month premium/auction capacity - so a larger share of revenue re-prices at market than at CoreWeave. Prepayments (70% of deals, >$9B in 2026) mitigate credit, not price, risk.
A22: - IREN: Microsoft 5-yr (20% prepaid, IG-financed at 6%) anchors ~half of contracted ARR; the rest is 1-3 yr AI-lab paper that re-prices from 2027. Little on-demand; exposure is medium and skewed to renewal pricing.
A23: - Private peers are longer-dated on paper (Nscale 6-7 yr, Lambda 6 yr Anthropic) but concentrated in one or two AI-lab counterparties whose contracts are contingent on financing - credit/delivery risk rather than spot-price risk.
A24: - Spot today is ABOVE legacy contract rates: H100 spot ~$2.6 and on-demand ~$3.5 vs. 2024-25 vintage multi-year contracts at ~$1.4-2.1. 1-yr contract rates rose ~40% from the Oct-25 trough and on-demand sold out Feb-Apr 2026; CoreWeave lifted list prices ~25% in Jul-26. Near-term, re-pricing is an upside; the downside case is a repeat of the 2H23-2025 drawdown (-58%) landing on the 2028-29 renewal wave.
A25: - Hosting landlords (APLD, CIFR, WULF, HUT, CORZ, GLXY) have 10-20 yr fixed $/MW leases and zero direct GPU-price exposure; their risk is tenant credit - which loops back to CoreWeave's and Fluidstack's own re-contracting exposure.

Sheet CRWV_Duration
A1: CoreWeave (CRWV) - contract duration from disclosed backlog & RPO schedule
A2: Sources: 10-Q for quarter ended 30-Jun-2026; Q2'26 earnings presentation & call (12-Aug-2026); prior quarterly press releases.
A4: A. Revenue backlog vs. revenue run-rate
A5: Quarter | B5: Period end | C5: Revenue ($M) | D5: Annualized revenue ($B) | E5: Revenue backlog ($B) | F5: Backlog coverage (yrs) = E / D | G5: QoQ backlog growth | H5: Note
A6: Q2'25 | B6: 45838 | C6: 1212 | D6: =C6*4/1000 -> 4.848 | E6: 30.1 | F6: =E6/D6 -> 6.2087459 | H6: Backlog = RPO ($30.1B); no 'other' amounts
A7: Q3'25 | B7: 45930 | C7: 1365 | D7: =C7*4/1000 -> 5.46 | E7: 55.6 | F7: =E7/D7 -> 10.18315 | G7: =E7/E6-1 -> 0.84717608 | H7: OpenAI +$6.5B (Sep-25), Meta $14.2B (Sep-25), NVIDIA $6.3B backstop
A8: Q4'25 | B8: 46022 | C8: 1572 | D8: =C8*4/1000 -> 6.288 | E8: 66.8 | F8: =E8/D8 -> 10.62341 | G8: =E8/E7-1 -> 0.20143885 | H8: FY25 revenue $5.1B
A9: Q1'26 | B9: 46112 | C9: 2078 | D9: =C9*4/1000 -> 8.312 | E9: 99.4 | F9: =E9/D9 -> 11.958614 | G9: =E9/E8-1 -> 0.48802395 | H9: Meta $21B order form (Mar-26); RPO $98.8B
A10: Q2'26 | B10: 46203 | C10: 2575 | D10: =C10*4/1000 -> 10.3 | E10: 104.2 | F10: =E10/D10 -> 10.116505 | G10: =E10/E9-1 -> 0.048289738 | H10: RPO $103.7B + $0.5B other; excludes >$25B net new commitments added early Q3'26
A12: FY2026 revenue guidance ($B, low / high / mid) | C12: 12.4 | D12: 13.2 | E12: =AVERAGE(C12,D12) -> 12.8 | H12: Raised on Q2'26 call (from $11.7-12.5B)
A13: YE2026 exit annualized run-rate revenue guidance ($B) | C13: 18.5 | D13: 19.5 | E13: =AVERAGE(C13,D13) -> 19 | H13: Q2'26 call
A14: Net new commitments added early Q3'26 ($B, not in Q2 backlog) | E14: 25 | H14: 'More than $25 billion' - Q2'26 release footnote
A15: Backlog coverage vs. YE26 exit ARR (yrs) | E15: =E10/E13 -> 5.4842105 | H15: Less flattering than vs. trailing revenue because run-rate is ramping fast
A16: Pro-forma coverage incl. early-Q3 adds vs. YE26 exit ARR (yrs) | E16: =(E10+E14)/E13 -> 6.8
A18: B. RPO recognition schedule -> weighted-average remaining contract duration
A19: Total unsatisfied RPO, 30-Jun-2026 ($B) | C19: 103.7 | E19: Total unsatisfied RPO, 31-Mar-2026 ($B) | G19: 98.8
A20: Bucket (months after period end) | B20: Start month | C20: End month | D20: Midpoint (yrs) | E20: % of RPO - Q2'26 | F20: RPO $B - Q2'26 | G20: Annualized recognition $B/yr - Q2'26 | H20: % of RPO - Q1'26 (bucket 3 = months 49-84)
A21: Months 1-24 | B21: 0 | C21: 24 | D21: =AVERAGE(B21,C21)/12 -> 1 | E21: 0.41 | F21: =E21*$C$19 -> 42.517 | G21: =F21/((C21-B21)/12) -> 21.2585 | H21: 0.36
A22: Months 25-48 | B22: 24 | C22: 48 | D22: =AVERAGE(B22,C22)/12 -> 3 | E22: 0.39 | F22: =E22*$C$19 -> 40.443 | G22: =F22/((C22-B22)/12) -> 20.2215 | H22: 0.39
A23: Months 49-78 (Q1'26: 49-84) | B23: 48 | C23: 78 | D23: =AVERAGE(B23,C23)/12 -> 5.25 | E23: 0.2 | F23: =E23*$C$19 -> 20.74 | G23: =F23/((C23-B23)/12) -> 8.296 | H23: 0.25
A24: Check: % sums to 100% | E24: =SUM(E21:E23) -> 1 | H24: =SUM(H21:H23) -> 1
A25: Weighted-avg remaining duration, Q2'26 (yrs) | E25: =SUMPRODUCT(D21:D23,E21:E23) -> 2.63 | H25: SUMPRODUCT(bucket midpoint in yrs, % of RPO) - the average remaining life of a contracted dollar.
A26: Weighted-avg remaining duration, Q1'26 (yrs) | E26: =D21*H21+D22*H22+(AVERAGE(48,84)/12)*H23 -> 2.905 | H26: Q1'26 third bucket ran to month 84 (midpoint 66 mo). Duration shortened QoQ as 2-3 yr enterprise deals were added.
A27: Maximum remaining tenor, Q2'26 (yrs) | E27: =C23/12 -> 6.5 | H27: Longest-dated contract runs to ~Dec-2032 (Meta order form, Mar-2026)
A28: Contracted revenue 'cliff': yr 5-6.5 run-rate vs yr 3-4 run-rate | E28: =G23/G22-1 -> -0.58974359 | H28: Share of yr-3/4 contracted run-rate that must be re-contracted (at market) to hold revenue flat beyond yr 4, absent new bookings.
A29: Yr 1-2 contracted run-rate vs FY26 revenue guidance midpoint | E29: =G21/E12 -> 1.6608203 | H29: Backlog implies ~1.7x FY26 revenue per year over the next 24 months - consistent with YE26 exit ARR guide of $18.5-19.5B.
A31: C. Individually disclosed committed contracts (TCV-weighted term)
A32: Customer | B32: Signed / announced | C32: TCV ($B) | D32: Stated expiry | E32: Term from signing (yrs) | F32: Remaining from 30-Jun-26 (yrs) | G32: Credit tier | H32: Notes / source
A33: OpenAI (initial MSA order) | B33: 45726 | C33: 11.9 | D33: 47573 | E33: =IF(AND(ISNUMBER(B33),ISNUMBER(D33)),(D33-B33)/365.25,0) -> 5.0568104 | F33: =IF(ISNUMBER(D33),MAX(0,(D33-DATE(2026,6,30))/365.25),0) -> 3.7508556 | G33: AI lab (VC-funded) | H33: 5-year agreement announced Mar-2025; expiry approximated as 5 yrs from signing
A34: OpenAI (expansion) | B34: 45792 | C34: 4 | D34: 47238 | E34: =IF(AND(ISNUMBER(B34),ISNUMBER(D34)),(D34-B34)/365.25,0) -> 3.9589322 | F34: =IF(ISNUMBER(D34),MAX(0,(D34-DATE(2026,6,30))/365.25),0) -> 2.8336756 | G34: AI lab (VC-funded) | H34: Expansion announced May-2025, runs through Apr-2029
A35: OpenAI (Sep-25 order form) | B35: 45925 | C35: 6.5 | D35: 47999 | E35: =IF(AND(ISNUMBER(B35),ISNUMBER(D35)),(D35-B35)/365.25,0) -> 5.6783025 | F35: =IF(ISNUMBER(D35),MAX(0,(D35-DATE(2026,6,30))/365.25),0) -> 4.91718 | G35: AI lab (VC-funded) | H35: 10-Q: 'committed to pay us up to approximately $6.5 billion through May 31, 2031'
A36: Meta (Sep-25 order form) | B36: 45930 | C36: 14.2 | D36: 48196 | E36: =IF(AND(ISNUMBER(B36),ISNUMBER(D36)),(D36-B36)/365.25,0) -> 6.2039699 | F36: =IF(ISNUMBER(D36),MAX(0,(D36-DATE(2026,6,30))/365.25),0) -> 5.4565366 | G36: Investment grade | H36: 8-K Sep-2025: through 14-Dec-2031
A37: Meta (Mar-26 order form) | B37: 46112 | C37: 21 | D37: 48568 | E37: =IF(AND(ISNUMBER(B37),ISNUMBER(D37)),(D37-B37)/365.25,0) -> 6.7241615 | F37: =IF(ISNUMBER(D37),MAX(0,(D37-DATE(2026,6,30))/365.25),0) -> 6.4750171 | G37: Investment grade | H37: 10-Q: 'up to approximately $21.0 billion' incl. new capacity through 20-Dec-2032 and option exercise through 10-Apr-2032
A38: NVIDIA (unsold-capacity backstop) | B38: 45925 | C38: 6.3 | D38: 48317 | E38: =IF(AND(ISNUMBER(B38),ISNUMBER(D38)),(D38-B38)/365.25,0) -> 6.5489391 | F38: =IF(ISNUMBER(D38),MAX(0,(D38-DATE(2026,6,30))/365.25),0) -> 5.7878166 | G38: Investment grade | H38: Commitment to purchase residual unsold capacity through 13-Apr-2032
A39: Jane Street | B39: 46127 | C39: 6 | E39: =IF(AND(ISNUMBER(B39),ISNUMBER(D39)),(D39-B39)/365.25,0) -> 0 | F39: =IF(ISNUMBER(D39),MAX(0,(D39-DATE(2026,6,30))/365.25),0) -> 0 | G39: Private financial (unrated) | H39: 10-Q: 'committed approximately $6.0 billion'; term not disclosed - excluded from weighted term
A40: Microsoft | E40: =IF(AND(ISNUMBER(B40),ISNUMBER(D40)),(D40-B40)/365.25,0) -> 0 | F40: =IF(ISNUMBER(D40),MAX(0,(D40-DATE(2026,6,30))/365.25),0) -> 0 | G40: Investment grade | H40: Largest customer (Customer A: 71% of Q2'25 and ~36% of Q2'26 revenue); contract values and expiries not disclosed
A41: Disclosed TCV with known expiry ($B) / TCV-weighted | C41: =SUMPRODUCT(--(F33:F40>0),C33:C40) -> 63.9 | E41: =SUMPRODUCT(C33:C40,E33:E40)/C41 -> 6.0012961 | F41: =SUMPRODUCT(C33:C40,F33:F40)/C41 -> 5.287214 | H41: TCV-weighted original term (col E) and remaining duration (col F) of the individually disclosed book (~2/3 of RPO). Contracts without a disclosed expiry are excluded. Longer than the RPO-weighted figure because the disclosed mega-deals are the newest, longest-dated contracts; the undisclosed third (Microsoft 2023-24 vintage, enterprise) is shorter.
A42: Share of 30-Jun-26 RPO individually disclosed above | C42: =SUM(C33:C40)/$C$19 -> 0.67405979
A44: D. Revenue mix: committed vs on-demand; customer concentration (10-Q)
A45: Metric | B45: Q2'26 | C45: Q2'25 | D45: 6M'26 | E45: 6M'25 | H45: Note
...

Sheet NBIS_Duration
A1: Nebius Group (NBIS) - contract duration from disclosed customer commitments
A2: Sources: Q2'26 shareholder letter & press release (12-Aug-2026), Q2'26 earnings call, Q1'26 letter, company press releases on Microsoft / Meta agreements.
A4: A. Customer commitments vs. revenue run-rate
A5: Quarter | B5: Period end | C5: Revenue ($M) | D5: Annualized revenue ($B) | E5: ARR ($B, company-defined) | F5: Customer commitments ($B) | G5: Coverage vs ARR (yrs) | H5: Note
A6: Q4'25 | B6: 46022 | C6: 228 | D6: =C6*4/1000 -> 0.912 | E6: 1.25 | G6: =IF(ISNUMBER(F6),F6/E6,"") | H6: Q4'25 revenue implied from Q1'26 +75% QoQ; ARR $1.25B
A7: Q1'26 | B7: 46112 | C7: 399 | D7: =C7*4/1000 -> 1.596 | E7: 1.92 | G7: =IF(ISNUMBER(F7),F7/E7,"") | H7: Meta $27B framework ($12B firm + up to $15B) signed Mar-26
A8: Q2'26 | B8: 46203 | C8: 582.3 | D8: =C8*4/1000 -> 2.3292 | E8: 3 | F8: 40 | G8: =IF(ISNUMBER(F8),F8/E8,"") -> 13.333333 | H8: 'More than $40 billion of customer commitments'; AI cloud revenue $574.9M (98% of group)
A10: FY2026 guidance: revenue ($B) low / high / mid | C10: 3 | D10: 3.4 | E10: =AVERAGE(C10,D10) -> 3.2 | H10: Reaffirmed on Q2'26 call
A11: FY2026 guidance: year-end ARR ($B) low / high / mid | C11: 7 | D11: 9 | E11: =AVERAGE(C11,D11) -> 8
A12: Coverage: commitments / YE26 ARR guidance midpoint (yrs) | E12: =F8/E11 -> 5 | H12: Comparable basis to CoreWeave 'coverage vs exit ARR'
A13: Expected 2026 customer prepayments ($B) | E13: 9 | H13: 'Over $9 billion'; 70% of Q2 deals included prepayment covering 50-60% of associated capex
A15: B. Contract-by-contract: TCV-weighted term and remaining duration (as of 30-Jun-2026)
A16: Counterparty | B16: Announced | C16: TCV ($B, firm) | D16: Stated term (yrs) | E16: Est. revenue start | F16: Est. expiry = start + term | G16: Remaining from 30-Jun-26 (yrs) | H16: Credit tier | I16: Notes / source
A17: Microsoft (Vineland, NJ) | B17: 45908 | C17: 17.4 | D17: 5 | E17: 46023 | F17: =EDATE(E17,ROUND(D17*12,0)) -> 47849 | G17: =MAX(0,(F17-DATE(2026,6,30))/365.25) -> 4.5065024 | H17: Investment grade | I17: $17.4B 'through 2031', expandable to $19.4B; all tranches delivered by Aug-2026. Start set to mid-point of tranche deliveries (Q4'25-Q3'26).
A18: Meta - agreement #1 | B18: 45962 | C18: 3 | D18: 5 | E18: 46023 | F18: =EDATE(E18,ROUND(D18*12,0)) -> 47849 | G18: =MAX(0,(F18-DATE(2026,6,30))/365.25) -> 4.5065024 | H18: Investment grade | I18: 'Approximately $3B over five years' (Nov-2025)
A19: Meta - agreement #2 (dedicated capacity) | B19: 46096 | C19: 12 | D19: 5 | E19: 46447 | F19: =EDATE(E19,ROUND(D19*12,0)) -> 48274 | G19: =MAX(0,(F19-DATE(2026,6,30))/365.25) -> 5.670089 | H19: Investment grade | I19: $12B dedicated 5-yr capacity coming online early 2027; up to a further $15B of optional capacity NOT included here
A20: Reflection AI (mid-term) | B20: 46157 | C20: 1 | D20: 2 | E20: 46296 | F20: =EDATE(E20,ROUND(D20*12,0)) -> 47027 | G20: =MAX(0,(F20-DATE(2026,6,30))/365.25) -> 2.255989 | H20: AI lab (VC-funded) | I20: One of four Q2'26 landmark deals, '>$1B average' each; mgmt: core AI-cloud contracts are 1-3 yrs -> 2 yrs assumed (yellow)
A21: Cohere (mid-term) | B21: 46157 | C21: 1 | D21: 2 | E21: 46296 | F21: =EDATE(E21,ROUND(D21*12,0)) -> 47027 | G21: =MAX(0,(F21-DATE(2026,6,30))/365.25) -> 2.255989 | H21: AI lab (VC-funded) | I21: As above
A22: Unnamed US frontier lab (mid-term) | B22: 46157 | C22: 1 | D22: 2 | E22: 46296 | F22: =EDATE(E22,ROUND(D22*12,0)) -> 47027 | G22: =MAX(0,(F22-DATE(2026,6,30))/365.25) -> 2.255989 | H22: AI lab (VC-funded) | I22: As above
A23: Unnamed US quant trading firm (mid-term) | B23: 46157 | C23: 1 | D23: 2 | E23: 46296 | F23: =EDATE(E23,ROUND(D23*12,0)) -> 47027 | G23: =MAX(0,(F23-DATE(2026,6,30))/365.25) -> 2.255989 | H23: Private financial (unrated) | I23: As above
A24: Other / undisclosed (plug to $40B) | C24: =F8-SUM(C17:C23) -> 3.6 | D24: 2 | E24: 46204 | F24: =EDATE(E24,ROUND(D24*12,0)) -> 46935 | G24: =MAX(0,(F24-DATE(2026,6,30))/365.25) -> 2.0041068 | H24: Mixed | I24: Residual of the '>$40B' headline not individually disclosed; 2-yr term assumed (yellow)
A25: Total / TCV-weighted | C25: =SUM(C17:C24) -> 40 | D25: =SUMPRODUCT(C17:C24,D17:D24)/C25 -> 4.43 | G25: =SUMPRODUCT(C17:C24,G17:G24)/C25 -> 4.4053114 | I25: TCV-weighted original term (col D) and remaining duration (col G) of the $40B book
A26: Share of commitments from investment-grade counterparties | C26: =SUMIF(H17:H24,"Investment grade",C17:C24)/C25 -> 0.81
A27: Share of commitments with term <= 3 yrs (re-prices at market by 2028-29) | C27: =SUMIF(D17:D24,"<=3",C17:C24)/C25 -> 0.19
A28: Implied straight-line annual revenue from long-term IG book ($B/yr) = IG TCV / 5 | C28: =SUMIF(H17:H24,"Investment grade",C17:C24)/5 -> 6.48 | I28: ~$6.5B/yr once Meta #2 is live (2027) - i.e. most of the 2026 exit-ARR guide of $7-9B is IG long-term; remainder is 1-3 yr / short-term
A30: C. Management's three deal types (Q2'26 call) - the basis for spot-exposure assumptions
A31: Deal type | B31: Typical term | C31: Customer type | D31: Pricing | E31: Prepayment | F31: Role | I31: Spot-price exposure
A32: 1. Long-term strategic | B32: 5 yrs | C32: Investment-grade hyperscalers (Microsoft, Meta) | D32: Fixed; $17-27B TCV | E32: Yes - basis for asset-backed debt ($775M at SOFR+250) | F32: Finance build-out; collateral | I32: None during term; re-price at expiry (2031-32)
A33: 2. Mid-term 'core AI cloud' | B33: 1-3 yrs | C33: AI labs, enterprises, quant funds (Reflection, Cohere, etc.) | D33: $20-25M ACV per MW; payback 1y10m | E33: 70% of Q2 deals; 50-60% of capex | F33: Core margin engine | I33: Re-prices at market every 1-3 yrs -> medium exposure
A34: 3. Short-term / capacity auctions | B34: <= 6 months | C34: Time-bounded, high-urgency needs | D34: 'Significant premium' to mid-term; first capacity auction Q2'26 | E34: Varies | F34: Monetize unallocated capacity; mgmt deliberately withholds some 2027 capacity for this | I34: Direct spot exposure - priced off current market
A36: D. Other duration-relevant disclosures
A37: - Server & network equipment depreciated over 5 years from 2026 (was 4) - 'based on usage patterns and current utilization commitments'.
A38: - Contracted power 5 GW by YE26; 'almost all of that power will come online over the next 3 to 3.5 years' - i.e. 2027-29 capacity is largely not yet contracted to customers.
A39: - 'We could sell today our entire 2027 capacity on these [mid-term] terms if we wanted to. But we are not doing this' - management is choosing to keep spot/short-term optionality.
A40: - 'We have tactically shortened how far in advance we sell capacity... selling closer to deployment' - improves price, lowers forward visibility.

Sheet Peer_Contracts
A1: Other neoclouds & GPU-hosting landlords - disclosed contracts and TCV-weighted terms
A2: GPU clouds sell compute ($/GPU-hr); hosting landlords lease powered shells ($/MW-yr) and carry no direct GPU-price exposure. Private-company figures from IPO filings / press.
A4: Company | B4: Ticker / status | C4: Business model | D4: Counterparty | E4: Announced | F4: TCV ($B) | G4: Term (yrs) | H4: MW (IT) | I4: $M per MW-yr | J4: Prepay / credit support | K4: Notes / source
A5: IREN | B5: IREN (Nasdaq) | C5: GPU cloud | D5: Microsoft (GB300, Childress TX) | E5: 45963 | F5: 9.7 | G5: 5 | H5: 200 | I5: =IF(AND(ISNUMBER(F5),ISNUMBER(G5),ISNUMBER(H5)),F5*1000/G5/H5,"") -> 9.7 | J5: 20% prepayment; $3.6B IG GPU financing at 6.0% | K5: 'Average term of five years'; ~$1.94B ARR when fully commissioned; Horizon 1 delivered Aug-26, H2-4 by Q4'26
A6: IREN | B6: IREN (Nasdaq) | C6: GPU cloud | D6: Leading frontier AI lab (unnamed) | E6: 46254 | G6: 3 | I6: =IF(AND(ISNUMBER(F6),ISNUMBER(G6),ISNUMBER(H6)),F6*1000/G6/H6,"") | J6: Prepayments 45-55% of GPU capex | K6: FY26 results: 'recent 3-year contracts >$20M revenue per MW (IT), ~2 year payback'; TCV n/d
A7: IREN | B7: IREN (Nasdaq) | C7: GPU cloud | D7: Together AI, Fluidstack, Fireworks, Poolside, Cohere, Perplexity, Figure, Fal, Higgsfield | E7: 45901 | G7: 2 | I7: =IF(AND(ISNUMBER(F7),ISNUMBER(G7),ISNUMBER(H7)),F7*1000/G7/H7,"") | J7: Prepayments on newer deals | K7: Multi-year (1-3 yr) contracts; $4B contracted ARR for 2026 capacity, $1B operating ARR (Aug-26); RPO $5.1B at 30-Jun-26
A8: Lambda | B8: Private (IPO filed/expected) | C8: GPU cloud | D8: Anthropic | E8: 46235 | F8: 35 | G8: 6 | I8: =IF(AND(ISNUMBER(F8),ISNUMBER(G8),ISNUMBER(H8)),F8*1000/G8/H8,"") | J8: Asset-backed financing | K8: Reported $35B six-year deal; ~70% of ~$50B backlog
A9: Lambda | B9: Private (IPO filed/expected) | C9: GPU cloud | D9: Microsoft (GB300 NVL72) | E9: 45964 | I9: =IF(AND(ISNUMBER(F9),ISNUMBER(G9),ISNUMBER(H9)),F9*1000/G9/H9,"") | J9: n/d | K9: 'Multibillion-dollar', 'multi-year'; term not disclosed
A10: Nscale | B10: IPO filing (NYSE) | C10: GPU cloud / AI factory | D10: Microsoft | E10: 45945 | F10: 43.8 | G10: 7 | I10: =IF(AND(ISNUMBER(F10),ISNUMBER(G10),ISNUMBER(H10)),F10*1000/G10/H10,"") | J10: n/d | K10: S-1: $43.8B 'through 2033'; ~7-yr term assumed from 2026 start (yellow)
A11: Nscale | B11: IPO filing (NYSE) | C11: GPU cloud / AI factory | D11: Anthropic (West Virginia) | E11: 46174 | F11: 44.6 | G11: 6 | I11: =IF(AND(ISNUMBER(F11),ISNUMBER(G11),ISNUMBER(H11)),F11*1000/G11/H11,"") | J11: Contingent on Nscale securing financing; cancellable on missed milestones | K11: Six-year supply agreement; together with Microsoft = ~85% of $103B TCV
A12: Nscale | B12: IPO filing (NYSE) | C12: GPU cloud / AI factory | D12: Other (plug to $103B) | F12: =103-F10-F11 -> 14.6 | I12: =IF(AND(ISNUMBER(F12),ISNUMBER(G12),ISNUMBER(H12)),F12*1000/G12/H12,"") | J12: n/d | K12: Residual of disclosed $103B total contract value
A13: Crusoe | B13: Private ($30.9B valuation, Sep-26) | C13: GPU cloud + AI data centers | D13: Portfolio (OpenAI/Oracle Abilene et al.) | E13: 46266 | F13: 140 | H13: 4900 | I13: =IF(AND(ISNUMBER(F13),ISNUMBER(G13),ISNUMBER(H13)),F13*1000/G13/H13,"") | J13: n/d | K13: 'More than $140B total contracted value', ~4.9 GW contracted; customer-level terms not disclosed (Abilene lease to Oracle widely reported at 15 yrs)
A14: Fluidstack | B14: Private | C14: GPU cloud (private cloud + marketplace) | D14: Meta, sovereigns, AI labs (private cloud) | G14: 2.5 | I14: =IF(AND(ISNUMBER(F14),ISNUMBER(G14),ISNUMBER(H14)),F14*1000/G14/H14,"") | J14: 25-50% upfront | K14: Private-cloud contracts typically 2-3 yrs; marketplace / brokerage side is spot-priced
A15: Applied Digital | B15: APLD (Nasdaq) | C15: Hosting landlord | D15: CoreWeave (Polaris Forge 1) | E15: 45805 | F15: 11 | G15: 15 | H15: 400 | I15: =IF(AND(ISNUMBER(F15),ISNUMBER(G15),ISNUMBER(H15)),F15*1000/G15/H15,"") -> 1.8333333 | J15: Take-or-pay, non-cancellable | K15: 10-K FY26: 400 MW, ~$11.0B, 15 yrs
A16: Applied Digital | B16: APLD (Nasdaq) | C16: Hosting landlord | D16: IG hyperscaler (Polaris Forge 2) | E16: 45952 | F16: 5 | G16: 15 | H16: 200 | I16: =IF(AND(ISNUMBER(F16),ISNUMBER(G16),ISNUMBER(H16)),F16*1000/G16/H16,"") -> 1.6666667 | J16: Take-or-pay | K16: 10-K FY26
A17: Applied Digital | B17: APLD (Nasdaq) | C17: Hosting landlord | D17: High-IG hyperscaler (Polaris Forge 3) | E17: 46162 | F17: 7.5 | G17: 15 | H17: 300 | I17: =IF(AND(ISNUMBER(F17),ISNUMBER(G17),ISNUMBER(H17)),F17*1000/G17/H17,"") -> 1.6666667 | J17: Take-or-pay | K17: 10-K FY26
A18: Applied Digital | B18: APLD (Nasdaq) | C18: Hosting landlord | D18: High-IG hyperscaler (Delta Forge 1) | E18: 46135 | F18: 7.5 | G18: 15 | H18: 300 | I18: =IF(AND(ISNUMBER(F18),ISNUMBER(G18),ISNUMBER(H18)),F18*1000/G18/H18,"") -> 1.6666667 | J18: Take-or-pay | K18: 10-K FY26
A19: Applied Digital | B19: APLD (Nasdaq) | C19: Hosting landlord | D19: High-IG hyperscaler (Delta Forge 2) | E19: 46181 | F19: 5.2 | G19: 15 | H19: 210 | I19: =IF(AND(ISNUMBER(F19),ISNUMBER(G19),ISNUMBER(H19)),F19*1000/G19/H19,"") -> 1.6507937 | J19: Take-or-pay | K19: 10-K FY26; portfolio ~$86B if all renewal options exercised
A20: Cipher Digital | B20: CIFR (Nasdaq) | C20: Hosting landlord | D20: AWS (Black Pearl TX) | E20: 45964 | F20: 5.5 | G20: 15 | H20: 300 | I20: =IF(AND(ISNUMBER(F20),ISNUMBER(G20),ISNUMBER(H20)),F20*1000/G20/H20,"") -> 1.2222222 | J20: IG tenant | K20: DCD / company release
A21: Cipher Digital | B21: CIFR (Nasdaq) | C21: Hosting landlord | D21: Fluidstack (Barber Lake TX) | E21: 45925 | F21: 3.8 | G21: 10 | H21: 207 | I21: =IF(AND(ISNUMBER(F21),ISNUMBER(G21),ISNUMBER(H21)),F21*1000/G21/H21,"") -> 1.8357488 | J21: Google backstops $1.4B of Fluidstack obligations; warrants | K21: Initial 168 MW ($3.0B) + 39 MW expansion
A22: Cipher Digital | B22: CIFR (Nasdaq) | C22: Hosting landlord | D22: Unnamed AI lab (Barber Lake, follow-on) | E22: 46290 | F22: 5.2 | G22: 10 | H22: 207 | I22: =IF(AND(ISNUMBER(F22),ISNUMBER(G22),ISNUMBER(H22)),F22*1000/G22/H22,"") -> 2.5120773 | J22: Binding commitment | K22: Ten-year lease starting when Fluidstack term ends -> site contracted life 20 yrs, >$9B
A23: TeraWulf | B23: WULF (Nasdaq) | C23: Hosting landlord | D23: Fluidstack (Lake Mariner NY, 2 deals) | E23: 45883 | F23: 6.7 | G23: 10 | H23: 360 | I23: =IF(AND(ISNUMBER(F23),ISNUMBER(G23),ISNUMBER(H23)),F23*1000/G23/H23,"") -> 1.8611111 | J23: Google backstops $3.2B total | K23: $3.7B + $3.0B, 10-yr initial terms
A24: TeraWulf | B24: WULF (Nasdaq) | C24: Hosting landlord | D24: Anthropic (Hawesville KY) | E24: 46209 | F24: 19 | G24: 20 | H24: 401 | I24: =IF(AND(ISNUMBER(F24),ISNUMBER(G24),ISNUMBER(H24)),F24*1000/G24/H24,"") -> 2.3690773 | J24: Expected IG credit support | K24: 20-yr lease
A25: Hut 8 | B25: HUT (Nasdaq) | C25: Hosting landlord | D25: Fluidstack for Anthropic | E25: 46008 | F25: 7 | G25: 15 | H25: 245 | I25: =IF(AND(ISNUMBER(F25),ISNUMBER(G25),ISNUMBER(H25)),F25*1000/G25/H25,"") -> 1.9047619 | J25: Google backstops lease payments for 15-yr base term | K25: DCD
A26: Core Scientific | B26: CORZ (Nasdaq) | C26: Hosting landlord | D26: CoreWeave (series of contracts) | E26: 45689 | F26: 10.2 | G26: 12 | H26: 590 | I26: =IF(AND(ISNUMBER(F26),ISNUMBER(G26),ISNUMBER(H26)),F26*1000/G26/H26,"") -> 1.440678 | J26: n/d | K26: ~$10.2B over 12 yrs (2024-Feb 2025 series)
A27: Galaxy Digital | B27: GLXY (Nasdaq) | C27: Hosting landlord | D27: CoreWeave (Helios TX) | E27: 45744 | F27: 18 | G27: 15 | H27: 800 | I27: =IF(AND(ISNUMBER(F27),ISNUMBER(G27),ISNUMBER(H27)),F27*1000/G27/H27,"") -> 1.5 | J27: n/d | K27: 15-yr lease; Galaxy guides >$1.2B average annual revenue -> ~$18B TCV (yellow estimate)
A29: Roll-up by company (TCV-weighted term over contracts with both TCV and term disclosed)
A30: Company | B30: Model | C30: Disclosed TCV ($B) | D30: TCV with term ($B) | E30: TCV-weighted term (yrs) | F30: Longest term (yrs) | G30: Direct GPU spot exposure | K30: Comment
A31: IREN | B31: GPU cloud | C31: =SUMIF($A$5:$A$27,A31,$F$5:$F$27) -> 9.7 | D31: =SUMPRODUCT(($A$5:$A$27=A31)*ISNUMBER($G$5:$G$27)*ISNUMBER($F$5:$F$27),$F$5:$F$27) -> 9.7 | E31: =IFERROR(SUMPRODUCT(($A$5:$A$27=A31)*ISNUMBER($G$5:$G$27),$F$5:$F$27,$G$5:$G$27)/D31,"") -> 5 | F31: =_xlfn.MAXIFS($G$5:$G$27,$A$5:$A$27,A31) -> 5 | G31: Low-Medium | K31: Microsoft 5-yr = ~48% of $4B contracted ARR; balance is 1-3 yr AI-lab deals that re-price 2027-29; no meaningful on-demand book
A32: Lambda | B32: GPU cloud | C32: =SUMIF($A$5:$A$27,A32,$F$5:$F$27) -> 35 | D32: =SUMPRODUCT(($A$5:$A$27=A32)*ISNUMBER($G$5:$G$27)*ISNUMBER($F$5:$F$27),$F$5:$F$27) -> 35 | E32: =IFERROR(SUMPRODUCT(($A$5:$A$27=A32)*ISNUMBER($G$5:$G$27),$F$5:$F$27,$G$5:$G$27)/D32,"") -> 6 | F32: =_xlfn.MAXIFS($G$5:$G$27,$A$5:$A$27,A32) -> 6 | G32: Medium | K32: Anthropic 6-yr dominates backlog, but Lambda also runs a public on-demand cloud (1-Click Clusters) - spot-priced
A33: Nscale | B33: GPU cloud / AI factory | C33: =SUMIF($A$5:$A$27,A33,$F$5:$F$27) -> 103 | D33: =SUMPRODUCT(($A$5:$A$27=A33)*ISNUMBER($G$5:$G$27)*ISNUMBER($F$5:$F$27),$F$5:$F$27) -> 88.4 | E33: =IFERROR(SUMPRODUCT(($A$5:$A$27=A33)*ISNUMBER($G$5:$G$27),$F$5:$F$27,$G$5:$G$27)/D33,"") -> 6.4954751 | F33: =_xlfn.MAXIFS($G$5:$G$27,$A$5:$A$27,A33) -> 7 | G33: Low | K33: ~85% of TCV in 6-7 yr Microsoft/Anthropic deals; Anthropic deal contingent on financing
A34: Crusoe | B34: GPU cloud + AI data centers | C34: =SUMIF($A$5:$A$27,A34,$F$5:$F$27) -> 140 | D34: =SUMPRODUCT(($A$5:$A$27=A34)*ISNUMBER($G$5:$G$27)*ISNUMBER($F$5:$F$27),$F$5:$F$27) -> 0 | E34: =IFERROR(SUMPRODUCT(($A$5:$A$27=A34)*ISNUMBER($G$5:$G$27),$F$5:$F$27,$G$5:$G$27)/D34,"") | F34: =_xlfn.MAXIFS($G$5:$G$27,$A$5:$A$27,A34) -> 0 | G34: Low-Medium | K34: Portfolio TCV only; mix of long-dated DC leases (Abilene) and cloud contracts; on-demand cloud is small
A35: Fluidstack | B35: GPU cloud (private cloud + marketplace) | C35: =SUMIF($A$5:$A$27,A35,$F$5:$F$27) -> 0 | D35: =SUMPRODUCT(($A$5:$A$27=A35)*ISNUMBER($G$5:$G$27)*ISNUMBER($F$5:$F$27),$F$5:$F$27) -> 0 | E35: =IFERROR(SUMPRODUCT(($A$5:$A$27=A35)*ISNUMBER($G$5:$G$27),$F$5:$F$27,$G$5:$G$27)/D35,"") | F35: =_xlfn.MAXIFS($G$5:$G$27,$A$5:$A$27,A35) -> 2.5 | G35: Medium-High | K35: Marketplace brokerage is spot-priced; private cloud 2-3 yr; its own 10-25 yr hosting leases are fixed obligations (negative carry if GPU prices fall)
A36: Applied Digital | B36: Hosting landlord | C36: =SUMIF($A$5:$A$27,A36,$F$5:$F$27) -> 36.2 | D36: =SUMPRODUCT(($A$5:$A$27=A36)*ISNUMBER($G$5:$G$27)*ISNUMBER($F$5:$F$27),$F$5:$F$27) -> 36.2 | E36: =IFERROR(SUMPRODUCT(($A$5:$A$27=A36)*ISNUMBER($G$5:$G$27),$F$5:$F$27,$G$5:$G$27)/D36,"") -> 15 | F36: =_xlfn.MAXIFS($G$5:$G$27,$A$5:$A$27,A36) -> 15 | G36: None | K36: Fixed $/MW-yr take-or-pay leases; exposure is tenant credit (CoreWeave) not GPU price
A37: Cipher Digital | B37: Hosting landlord | C37: =SUMIF($A$5:$A$27,A37,$F$5:$F$27) -> 14.5 | D37: =SUMPRODUCT(($A$5:$A$27=A37)*ISNUMBER($G$5:$G$27)*ISNUMBER($F$5:$F$27),$F$5:$F$27) -> 14.5 | E37: =IFERROR(SUMPRODUCT(($A$5:$A$27=A37)*ISNUMBER($G$5:$G$27),$F$5:$F$27,$G$5:$G$27)/D37,"") -> 11.896552 | F37: =_xlfn.MAXIFS($G$5:$G$27,$A$5:$A$27,A37) -> 15 | G37: None | K37: As above; Google backstop on Fluidstack lease
A38: TeraWulf | B38: Hosting landlord | C38: =SUMIF($A$5:$A$27,A38,$F$5:$F$27) -> 25.7 | D38: =SUMPRODUCT(($A$5:$A$27=A38)*ISNUMBER($G$5:$G$27)*ISNUMBER($F$5:$F$27),$F$5:$F$27) -> 25.7 | E38: =IFERROR(SUMPRODUCT(($A$5:$A$27=A38)*ISNUMBER($G$5:$G$27),$F$5:$F$27,$G$5:$G$27)/D38,"") -> 17.392996 | F38: =_xlfn.MAXIFS($G$5:$G$27,$A$5:$A$27,A38) -> 20 | G38: None | K38: As above; 20-yr Anthropic lease
A39: Hut 8 | B39: Hosting landlord | C39: =SUMIF($A$5:$A$27,A39,$F$5:$F$27) -> 7 | D39: =SUMPRODUCT(($A$5:$A$27=A39)*ISNUMBER($G$5:$G$27)*ISNUMBER($F$5:$F$27),$F$5:$F$27) -> 7 | E39: =IFERROR(SUMPRODUCT(($A$5:$A$27=A39)*ISNUMBER($G$5:$G$27),$F$5:$F$27,$G$5:$G$27)/D39,"") -> 15 | F39: =_xlfn.MAXIFS($G$5:$G$27,$A$5:$A$27,A39) -> 15 | G39: None | K39: As above
A40: Core Scientific | B40: Hosting landlord | C40: =SUMIF($A$5:$A$27,A40,$F$5:$F$27) -> 10.2 | D40: =SUMPRODUCT(($A$5:$A$27=A40)*ISNUMBER($G$5:$G$27)*ISNUMBER($F$5:$F$27),$F$5:$F$27) -> 10.2 | E40: =IFERROR(SUMPRODUCT(($A$5:$A$27=A40)*ISNUMBER($G$5:$G$27),$F$5:$F$27,$G$5:$G$27)/D40,"") -> 12 | F40: =_xlfn.MAXIFS($G$5:$G$27,$A$5:$A$27,A40) -> 12 | G40: None | K40: CoreWeave is the tenant
A41: Galaxy Digital | B41: Hosting landlord | C41: =SUMIF($A$5:$A$27,A41,$F$5:$F$27) -> 18 | D41: =SUMPRODUCT(($A$5:$A$27=A41)*ISNUMBER($G$5:$G$27)*ISNUMBER($F$5:$F$27),$F$5:$F$27) -> 18 | E41: =IFERROR(SUMPRODUCT(($A$5:$A$27=A41)*ISNUMBER($G$5:$G$27),$F$5:$F$27,$G$5:$G$27)/D41,"") -> 15 | F41: =_xlfn.MAXIFS($G$5:$G$27,$A$5:$A$27,A41) -> 15 | G41: None | K41: CoreWeave is the tenant
A43: IREN - contracted-ARR build: ARR-weighted term, remaining duration and implied backlog coverage
...

Sheet GPU_Spot_Prices
A1: GPU rental price benchmarks - spot, on-demand, reserved and term contracts ($/GPU-hour)
A2: Sources: SemiAnalysis GPU Spot-Contract Composite Index (H100, Bloomberg SAH100SC); Bargo cross-provider tracker (15-Oct-2026); CCIR term ladder (Oct-2026); flatkey.ai index (12-Oct-2026).
A4: A. H100 price history - SemiAnalysis composite index and 1-yr contract range (25th-75th pct)
A5: Period | B5: Composite index ($/hr) | C5: On-demand low | D5: On-demand high | E5: 1-yr contract low | F5: 1-yr contract high | G5: 1-yr contract mid | H5: Index change vs 2H23 peak | I5: Note
A6: 1H 2023 | E6: 2.7 | F6: 3.4 | G6: =AVERAGE(E6,F6) -> 3.05 | H6: =IF(ISNUMBER(B6),B6/$B$7-1,"") | I6: Pre-index; contract range only
A7: 2H 2023 | B7: 6.62 | E7: 2.65 | F7: 3.3 | G7: =AVERAGE(E7,F7) -> 2.975 | H7: =IF(ISNUMBER(B7),B7/$B$7-1,"") -> 0 | I7: Peak scarcity pricing
A8: 1Q 2024 | B8: 5.78 | E8: 2.5 | F8: 3.1 | G8: =AVERAGE(E8,F8) -> 2.8 | H8: =IF(ISNUMBER(B8),B8/$B$7-1,"") -> -0.12688822
A9: 2Q 2024 | B9: 4.77 | C9: 3.9 | D9: 3.9 | E9: 2.2 | F9: 2.5 | G9: =AVERAGE(E9,F9) -> 2.35 | H9: =IF(ISNUMBER(B9),B9/$B$7-1,"") -> -0.27945619
A10: 3Q 2024 | B10: 4.44 | C10: 3.45 | D10: 3.45 | E10: 2.15 | F10: 2.45 | G10: =AVERAGE(E10,F10) -> 2.3 | H10: =IF(ISNUMBER(B10),B10/$B$7-1,"") -> -0.32930514
A11: 4Q 2024 | B11: 3.91 | C11: 2.85 | D11: 3.15 | E11: 1.9 | F11: 2.1 | G11: =AVERAGE(E11,F11) -> 2 | H11: =IF(ISNUMBER(B11),B11/$B$7-1,"") -> -0.40936556
A12: 1Q 2025 | B12: 3.6 | C12: 2.7 | D12: 3 | E12: 1.8 | F12: 2.1 | G12: =AVERAGE(E12,F12) -> 1.95 | H12: =IF(ISNUMBER(B12),B12/$B$7-1,"") -> -0.45619335
A13: 2Q 2025 | B13: 3.34 | C13: 2.5 | D13: 3 | E13: 1.8 | F13: 2.1 | G13: =AVERAGE(E13,F13) -> 1.95 | H13: =IF(ISNUMBER(B13),B13/$B$7-1,"") -> -0.49546828
A14: Jul 2025 | B14: 2.79 | C14: 2.25 | D14: 3 | E14: 1.7 | F14: 2 | G14: =AVERAGE(E14,F14) -> 1.85 | H14: =IF(ISNUMBER(B14),B14/$B$7-1,"") -> -0.57854985
A15: Aug 2025 | B15: 2.9 | C15: 2 | D15: 3 | E15: 1.5 | F15: 2 | G15: =AVERAGE(E15,F15) -> 1.75 | H15: =IF(ISNUMBER(B15),B15/$B$7-1,"") -> -0.56193353
A16: Sep 2025 | B16: 2.9 | C16: 2 | D16: 3 | E16: 1.5 | F16: 2 | G16: =AVERAGE(E16,F16) -> 1.75 | H16: =IF(ISNUMBER(B16),B16/$B$7-1,"") -> -0.56193353
A17: Oct 2025 | B17: 2.84 | C17: 2.2 | D17: 3 | E17: 1.45 | F17: 1.95 | G17: =AVERAGE(E17,F17) -> 1.7 | H17: =IF(ISNUMBER(B17),B17/$B$7-1,"") -> -0.57099698 | I17: Trough in 1-yr contract pricing
A18: Nov 2025 | B18: 2.8 | C18: 2.2 | D18: 3 | E18: 1.45 | F18: 2 | G18: =AVERAGE(E18,F18) -> 1.725 | H18: =IF(ISNUMBER(B18),B18/$B$7-1,"") -> -0.57703927
A19: Dec 2025 | B19: 2.81 | C19: 2.2 | D19: 3 | E19: 1.45 | F19: 2 | G19: =AVERAGE(E19,F19) -> 1.725 | H19: =IF(ISNUMBER(B19),B19/$B$7-1,"") -> -0.5755287
A20: Jan 2026 | B20: 2.82 | C20: 2.2 | D20: 3 | E20: 1.5 | F20: 2.05 | G20: =AVERAGE(E20,F20) -> 1.775 | H20: =IF(ISNUMBER(B20),B20/$B$7-1,"") -> -0.57401813
A21: Feb 2026 | B21: 2.83 | E21: 1.8 | F21: 2.35 | G21: =AVERAGE(E21,F21) -> 2.075 | H21: =IF(ISNUMBER(B21),B21/$B$7-1,"") -> -0.57250755 | I21: On-demand 'sold out' Feb-Apr 2026
A22: Mar 2026 | B22: 2.8 | E22: 2 | F22: 2.7 | G22: =AVERAGE(E22,F22) -> 2.35 | H22: =IF(ISNUMBER(B22),B22/$B$7-1,"") -> -0.57703927
A23: Apr 2026 | E23: 2.1 | F23: 2.7 | G23: =AVERAGE(E23,F23) -> 2.4 | H23: =IF(ISNUMBER(B23),B23/$B$7-1,"") | I23: Latest SemiAnalysis public print; index ~$2.82 (Oct-2026 page)
A25: H100 composite: peak (2H23) -> Mar-2026 | B25: =$B$22/$B$7-1 -> -0.57703927 | I25: Spot/blended H100 price fell ~58% from peak over ~2.5 years
A26: H100 1-yr contract mid: 2H23 -> Oct-2025 trough | B26: =$G$17/$G$7-1 -> -0.42857143
A27: H100 1-yr contract mid: Oct-2025 trough -> Apr-2026 | B27: =$G$23/$G$17-1 -> 0.41176471 | I27: Contract pricing re-tightened +40% in 6 months as on-demand sold out - consistent with CoreWeave's ~25% list price hike (Jul-26)
A29: B. Current cross-provider averages (Bargo, updated 15-Oct-2026)
A30: GPU | B30: On-demand ($/hr) | C30: Spot ($/hr) | D30: Reserved ($/hr) | E30: Spot discount to on-demand | F30: Reserved discount to on-demand | G30: # providers | H30: On-demand YoY | I30: Note
A31: B200 | B31: 7.94 | C31: 4.26 | D31: 5.62 | E31: =C31/B31-1 -> -0.46347607 | F31: =D31/B31-1 -> -0.29219144 | G31: 37 | H31: 0.04 | I31: GB200 rack = B200 compute building block
A32: H200 | B32: 4.72 | C32: 3.72 | D32: 3.84 | E32: =C32/B32-1 -> -0.21186441 | F32: =D32/B32-1 -> -0.18644068 | G32: 49 | H32: 0.03
A33: H100 | B33: 3.49 | C33: 2.62 | D33: 3.31 | E33: =C33/B33-1 -> -0.24928367 | F33: =D33/B33-1 -> -0.051575931 | G33: 57 | I33: YoY n/d
A34: MI300X | B34: 2.99 | C34: 1.76 | D34: 2.8 | E34: =C34/B34-1 -> -0.41137124 | F34: =D34/B34-1 -> -0.063545151 | G34: 11 | H34: 0.23
A36: C. Term ladder - posted vs. contracted rates by tenor (CCIR, Oct-2026)
A37: GPU / layer | B37: On-demand | C37: 3M | D37: 6M | E37: 1Y | F37: 2Y | G37: 3Y | H37: 5Y | I37: Note
A38: B300 - posted | B38: 8.39 | E38: 6.61 | F38: 6.5
A39: B300 - contracted (filed deals) | F39: 4.1 | G39: 4.1 | H39: 3.74 | I39: 'b' = bundled deal
A40: B200 - posted | B40: 6.59 | C40: 6.39 | D40: 5.96 | E40: 6.33
A41: B200 - contracted (filed deals) | F41: 3.29 | G41: 3.07
A42: H200 - posted | B42: 4.5 | C42: 4.32 | D42: 4.15 | E42: 4.11 | F42: 3.68 | G42: 3.1
A43: H200 - contracted (filed deals) | E43: 1.67 | I43: -59% vs posted 1Y
A44: H100 - posted | B44: 3.52 | C44: 3.36 | D44: 3.18 | E44: 3.11 | F44: 2.64 | G44: 1.83
...

Sheet Spot_Exposure
A1: Spot GPU-price exposure - scenario model (public neoclouds)
A2: Exposed revenue = run-rate x (on-demand share + share of contracts re-pricing within the horizon). Yellow cells are analyst assumptions - edit them.
A4: A. Inputs
A5: Company | B5: Run-rate revenue basis ($B) | C5: Basis | D5: On-demand / spot share of revenue today | E5: Share re-pricing within 12 mo | F5: Share re-pricing within 24 mo | G5: Spot-exposed share (12 mo) | H5: Spot-exposed share (24 mo) | I5: Backlog coverage vs exit ARR (yrs) | J5: Wtd remaining contract duration (yrs) | K5: Exposure rating (24 mo) | L5: Basis for assumptions
A6: CoreWeave (CRWV) | B6: =CRWV_Duration!E13 -> 19 | C6: YE26 exit ARR guide midpoint | D6: =CRWV_Duration!$B$47 -> 0.02 | E6: 0.05 | F6: 0.12 | G6: =D6+E6 -> 0.07 | H6: =D6+F6 -> 0.14 | I6: =CRWV_Duration!E15 -> 5.4842105 | J6: =CRWV_Duration!$E$25 -> 2.63 | K6: =IF(H6<0.15,"Low",IF(H6<0.35,"Medium","High")) -> Low | L6: On-demand = 2% (10-Q). Re-pricing: 2023-24 vintage H100/A100 fleet on 3-4 yr terms (FY23 rev $0.2B, FY24 $1.9B) rolls off 2026-28; mgmt: 'limited fleet expires soon'. 5% / 12% of a ~$19B exit run-rate = ~$1B / $2.3B of annual revenue re-pricing - analyst assumption.
A7: Nebius (NBIS) | B7: =NBIS_Duration!E11 -> 8 | C7: YE26 ARR guide midpoint | D7: 0.12 | E7: 0.1 | F7: 0.2 | G7: =D7+E7 -> 0.22 | H7: =D7+F7 -> 0.32 | I7: =NBIS_Duration!E12 -> 5 | J7: =NBIS_Duration!$G$25 -> 4.4053114 | K7: =IF(H7<0.15,"Low",IF(H7<0.35,"Medium","High")) -> Medium | L7: Not disclosed. IG long-term book = ~$6.5B/yr at full run, but Meta #2 ($12B) only starts 2027, so in 2026 IG contributes ~$4B/yr = ~50% of the $8B exit ARR. The other ~50% is 1-3 yr mid-term AI-lab paper (~38%) plus self-serve / <=6-month premium deals / capacity auctions (~12%, treated as spot). Roughly half of the mid-term book (avg 2-yr term) re-prices within 24 mo -> ~20%. Analyst assumptions.
A8: IREN (IREN) | B8: =Peer_Contracts!B47 -> 4 | C8: Contracted ARR for 2026 capacity (Aug-26) | D8: 0.02 | E8: 0.1 | F8: 0.3 | G8: =D8+E8 -> 0.12 | H8: =D8+F8 -> 0.32 | I8: =Peer_Contracts!$H$48 -> 3.7125 | J8: =Peer_Contracts!$G$47 -> 3.7099932 | K8: =IF(H8<0.15,"Low",IF(H8<0.35,"Medium","High")) -> Medium | L8: Microsoft $9.7B / 5 yr = ~$1.9B ARR (48% of $4B). Balance is 1-3 yr contracts with AI labs signed 2025-26 (Poolside, Together, Fluidstack, Fireworks, Cohere...), ~30% of which re-price within 24 mo. Dedicated clusters -> negligible on-demand. Analyst assumptions.
A10: Rating thresholds (24-mo spot-exposed share): Low < 15%, Medium 15-35%, High > 35%
A12: B. Revenue sensitivity to a spot-price shock applied to the exposed share (12-month horizon)
A13: Spot price shock -> | B13: -0.4 | C13: -0.25 | D13: -0.1 | E13: 0 | F13: 0.15 | G13: 0.25 | I13: Shocks are vs. today's spot; +25% = CoreWeave's Jul-26 list increase; -40% approximates the 2024-25 H100 drawdown (see GPU_Spot_Prices)
A14: Revenue impact, $B (12-mo exposed share) | B14: Scenario 1 | C14: Scenario 2 | D14: Scenario 3 | E14: Scenario 4 | F14: Scenario 5 | G14: Scenario 6
A15: =A6 -> CoreWeave (CRWV) | B15: =$B6*$G6*B$13 -> -0.532 | C15: =$B6*$G6*C$13 -> -0.3325 | D15: =$B6*$G6*D$13 -> -0.133 | E15: =$B6*$G6*E$13 -> 0 | F15: =$B6*$G6*F$13 -> 0.1995 | G15: =$B6*$G6*G$13 -> 0.3325
A16: =A7 -> Nebius (NBIS) | B16: =$B7*$G7*B$13 -> -0.704 | C16: =$B7*$G7*C$13 -> -0.44 | D16: =$B7*$G7*D$13 -> -0.176 | E16: =$B7*$G7*E$13 -> 0 | F16: =$B7*$G7*F$13 -> 0.264 | G16: =$B7*$G7*G$13 -> 0.44
A17: =A8 -> IREN (IREN) | B17: =$B8*$G8*B$13 -> -0.192 | C17: =$B8*$G8*C$13 -> -0.12 | D17: =$B8*$G8*D$13 -> -0.048 | E17: =$B8*$G8*E$13 -> 0 | F17: =$B8*$G8*F$13 -> 0.072 | G17: =$B8*$G8*G$13 -> 0.12
A18: Revenue impact, % of run-rate (12-mo) | B18: Scenario 1 | C18: Scenario 2 | D18: Scenario 3 | E18: Scenario 4 | F18: Scenario 5 | G18: Scenario 6
A19: =A6 -> CoreWeave (CRWV) | B19: =$G6*B$13 -> -0.028 | C19: =$G6*C$13 -> -0.0175 | D19: =$G6*D$13 -> -0.007 | E19: =$G6*E$13 -> 0 | F19: =$G6*F$13 -> 0.0105 | G19: =$G6*G$13 -> 0.0175
A20: =A7 -> Nebius (NBIS) | B20: =$G7*B$13 -> -0.088 | C20: =$G7*C$13 -> -0.055 | D20: =$G7*D$13 -> -0.022 | E20: =$G7*E$13 -> 0 | F20: =$G7*F$13 -> 0.033 | G20: =$G7*G$13 -> 0.055
A21: =A8 -> IREN (IREN) | B21: =$G8*B$13 -> -0.048 | C21: =$G8*C$13 -> -0.03 | D21: =$G8*D$13 -> -0.012 | E21: =$G8*E$13 -> 0 | F21: =$G8*F$13 -> 0.018 | G21: =$G8*G$13 -> 0.03
A22: Revenue impact, % of run-rate (24-mo exposed share) | B22: Scenario 1 | C22: Scenario 2 | D22: Scenario 3 | E22: Scenario 4 | F22: Scenario 5 | G22: Scenario 6
A23: =A6 -> CoreWeave (CRWV) | B23: =$H6*B$13 -> -0.056 | C23: =$H6*C$13 -> -0.035 | D23: =$H6*D$13 -> -0.014 | E23: =$H6*E$13 -> 0 | F23: =$H6*F$13 -> 0.021 | G23: =$H6*G$13 -> 0.035
A24: =A7 -> Nebius (NBIS) | B24: =$H7*B$13 -> -0.128 | C24: =$H7*C$13 -> -0.08 | D24: =$H7*D$13 -> -0.032 | E24: =$H7*E$13 -> 0 | F24: =$H7*F$13 -> 0.048 | G24: =$H7*G$13 -> 0.08
A25: =A8 -> IREN (IREN) | B25: =$H8*B$13 -> -0.128 | C25: =$H8*C$13 -> -0.08 | D25: =$H8*D$13 -> -0.032 | E25: =$H8*E$13 -> 0 | F25: =$H8*F$13 -> 0.048 | G25: =$H8*G$13 -> 0.08
A27: C. Mark-to-market: legacy contracted H100 rate vs. today's market (renewal upside / downside buffer)
A28: Metric | B28: Value | L28: Note
A29: Legacy multi-year contracted H100 rate ($/hr) - 2024-25 vintage | B29: 1.75 | L29: Midpoint of CCIR contracted 2Y ($1.40) and SemiAnalysis H2'25 1-yr range ($1.45-2.10); edit for your own book
A30: Current H100 spot ($/hr, Bargo) | B30: =GPU_Spot_Prices!$C$33 -> 2.62
A31: Current H100 on-demand ($/hr, Bargo) | B31: =GPU_Spot_Prices!$B$33 -> 3.49
A32: Current H100 posted 3-yr rate ($/hr, CCIR) | B32: =GPU_Spot_Prices!$G$44 -> 1.83
A33: Spot premium / (discount) to legacy contract rate | B33: =B30/B29-1 -> 0.49714286 | L33: Positive = expiring contracts can be re-let above their old rate (spot exposure is currently an upside)
A34: Spot decline that would make renewals dilutive (buffer) | B34: =1-B29/B30 -> 0.33206107 | L34: Spot would need to fall this much before a legacy-rate renewal loses revenue
A35: 3-yr re-contract today vs legacy rate | B35: =B32/B29-1 -> 0.045714286 | L35: Locking a new 3-yr term today is roughly flat to legacy economics - the duration discount offsets the spot premium
A36: Peak-to-trough H100 drawdown 2H23 -> Mar-26 (reference downside) | B36: =GPU_Spot_Prices!$B$22/GPU_Spot_Prices!$B$7-1 -> -0.57703927 | L36: The worst historical realized spot move for a GPU generation - use as a stress case for the shock grid
A38: D. Qualitative exposure - private neoclouds and landlords
A39: Company | B39: Direct spot exposure | C39: Indirect (re-contracting) exposure | D39: Comment
A40: Lambda (private) | B40: Medium | C40: Low-Medium | D40: Public on-demand cloud and 1-Click Clusters are spot-priced; Anthropic 6-yr ($35B) and Microsoft multi-year deals now ~70%+ of ~$50B backlog.
A41: Nscale (IPO) | B41: Low | C41: Low | D41: ~85% of $103B TCV in 6-7 yr Microsoft/Anthropic contracts; risk is delivery/financing, not spot price.
A42: Crusoe (private) | B42: Low-Medium | C42: Low | D42: >$140B TCV, ~4.9 GW; largely long-dated AI-factory leases; cloud on-demand is a small share.
A43: Fluidstack (private) | B43: High (marketplace) | C43: Medium (2-3 yr private cloud) | D43: Brokerage resells third-party capacity at spot; carries 10-25 yr fixed hosting leases (WULF, CIFR, HUT) - negative carry if GPU rents fall; Google backstops rent.
A44: Hosting landlords (APLD, CIFR, WULF, HUT, CORZ, GLXY) | B44: None | C44: None (10-20 yr fixed $/MW leases) | D44: Exposure is tenant credit (CoreWeave / Fluidstack) rather than GPU price; renewal options extend to 25-30 yrs.

Sheet Sources
A1: Sources (retrieved 16-Oct-2026)
A3: # | B3: Company / topic | C3: Document | D3: URL | E3: Used for
A4: 1 | B4: CoreWeave | C4: Form 10-Q, quarter ended 30-Jun-2026 (filed Aug-2026) | D4: https://www.sec.gov/Archives/edgar/data/1769628/000176962826000366/crwv-20260630.htm | E4: RPO $103.7B and 41/39/20 schedule; 98% committed revenue; customer concentration; OpenAI/Meta/Jane Street contract terms
A5: 2 | B5: CoreWeave | C5: Form 10-Q, quarter ended 31-Mar-2026 | D5: https://www.sec.gov/Archives/edgar/data/1769628/000176962826000222/crwv-20260331.htm | E5: RPO $98.8B and 36/39/25 schedule (49-84 mo)
A6: 3 | B6: CoreWeave | C6: Q2'26 earnings presentation (12-Aug-2026) | D6: https://static.seekingalpha.com/uploads/sa_presentations/36/134036/original.pdf | E6: Revenue backlog $104.2B reconciliation; >$25B early-Q3 commitments; contracted power
A7: 4 | B7: CoreWeave | C7: Q2'26 earnings call transcript | D7: https://gloom.sh/stocks/crwv/transcripts/q2-2026 | E7: FY26 guidance ($12.4-13.2B rev; $18.5-19.5B exit ARR); DTL 5.5 / 2-3 yr enterprise contracts; A100 re-contract to 2029; ~25% July price increase
A8: 5 | B8: CoreWeave | C8: Q3'25, Q4'25, Q1'26, Q2'26 results press releases | D8: https://investors.coreweave.com/news/ | E8: Quarterly revenue and backlog series ($55.6B / $66.8B / $99.4B / ~$104B)
A9: 6 | B9: Nebius | C9: Q2'26 shareholder letter (12-Aug-2026) | D9: https://assets.nebius.com/assets/4462517b-ce83-41f2-96ed-f2ac1bc06a05/SHLQ226%20%281%29.pdf-0 | E9: >$40B customer commitments; ARR $3.0B; prepayments; payback 1y10m; 5-yr depreciation; 5 GW contracted power
A10: 7 | B10: Nebius | C10: Q2'26 results press release / 6-K | D10: https://www.sec.gov/Archives/edgar/data/1513845/000110465926094568/tm2622968d1_ex99-2.htm | E10: Revenue $582.3M; AI cloud $574.9M
A11: 8 | B11: Nebius | C11: Q2'26 earnings call transcript | D11: https://www.fool.com/earnings/call-transcripts/2026/08/19/nebius-nbis-q2-2026-earnings-call-transcript/ | E11: Three deal types (5-yr IG / 1-3 yr mid-term / <=6-mo short-term); FY26 guidance ($3.0-3.4B rev, $7-9B ARR, $20-25B capex); $775M ABS at SOFR+250
A12: 9 | B12: Nebius | C12: Q1'26 shareholder letter | D12: https://assets.nebius.com/assets/aa1bc2e6-df83-40cd-a6a2-95e7cda3d16c/Nebius%20SHL%5FQ1%202026.pdf | E12: Meta $27B framework ($12B firm + $15B); ARR $1.92B / $1.25B
A13: 10 | B13: Nebius | C13: NBIS Tracker - customer commitments | D13: https://nbistracker.com/demand | E13: Contract-level list (Microsoft $17.4B, Meta $12B + $3B, four ~$1B mid-term deals); 89% IG of disclosed
A14: 11 | B14: IREN | C14: FY26 results release (27-Aug-2026) | D14: https://www.sec.gov/Archives/edgar/data/1878848/000187884826000051/irenreportsfy26results.htm | E14: $4B contracted ARR / $1B operating ARR; 3-yr contracts >$20M/MW; prepayments 45-55%; GPU financings
A15: 12 | B15: IREN | C15: Q1 FY26 results release (6-Nov-2025) and Microsoft agreement blog | D15: https://iren.com/resources/blog/iren-signs97-billion-agreement-with-microsoft-to-deploy-ai-cloud-infrastructure | E15: Microsoft $9.7B, 5-yr average term, 20% prepayment, ~$1.94B ARR
... A29: 26 | B29: GPU prices | C29: flatkey.ai GPU price index (12-Oct-2026) | D29: https://flatkey.ai/compute/prices | E29: Marketplace realtime / spot asks and term multipliers
